Workbook

Sheet #summury
A2: Base 테이블
A3: DATA | B3: Type | C3: Desc
A4: Id | B4: int | C4: id
A5: Name | B5: string | C5: 이름
C6: - Localization 테이블의 키 값을 입력한다.
A7: Spine | B7: string | C7: 스파인 리소스 파일명.
C8: - 스파인 리소스는 Front와 Back 2개의 세트로 구성된다.
C9: - 스파인 리소스 파일명 규칙 확정 필요. (ex. Spine_Eve_Front)
A10: Illust | B10: string | C10: 일러스트 리소스 파일명.
A11: Icon | B11: string | C11: 캐릭터 아이콘 파일명
A15: Child 테이블
A16: DATA | B16: Type | C16: Desc
A17: Id | B17: int | C17: id
A18: BaseId | B18: int | C18: 사용할 캐릭터의 Base 테이블의 id를 입력한다.
A19: Name | B19: string | C19: 이름
C20: - Localization 테이블의 키 값을 입력한다.
A21: Grade | B21: Enum.Grade | C21: 캐릭터의 등급을 지정한다.
C22: 0: NONE
C23: 1: 1성
C24: 2: 2성
C25: 3: 3성
A26: Element | B26: Enum.Element | C26: 캐릭터의 속성을 지정한다.
C27: 0: NONE
C28: 1: 수속성
C29: 2: 화속성
C30: 3: 목속성
C31: 4: 광속성
C32: 5: 암속성
A33: Role | B33: Enum.Role | C33: 캐릭터의 직업을 지정한다.
C34: 0: NONE
C35: 1: 공격형
C36: 2: 방어형
C37: 3: 마법형
C38: 4: 보조형
A39: StatParam | B39: Enum.StatParam | C39: 스탯 종류
C40: - 스탯 종류를 설정한다.
A41: StatValue | B41: int | C41: 스탯 초기 값
C42: - 캐릭터의 1레벨의 성장되지 않은 초기 값이다.
C43: - 확장 가능
A44: SkillId | B44: int | C44: 스킬 id
...

Sheet Detail<Child>
A1: Id | B1: #이름 | C1: Skin | D1: #DefaultSoul | E1: Name | F1: Profile | G1: MonsterType | H1: Size | I1: Scale | J1: UseHud | K1: StatusOffset | L1: StarGrade | M1: Element | N1: Role | O1: LevelUpGroup | P1: MaxSp | Q1: UseSp | R1: TurnSp | S1: AtkSp | T1: HitSp | U1: StatParam | V1: StatValue | W1: StatParam | X1: StatValue | Y1: StatParam | Z1: StatValue | AA1: StatParam | AB1: StatValue | AC1: StatParam | AD1: StatValue | AE1: StatParam | AF1: StatValue | AG1: StatParam | AH1: StatValue | AI1: StatParam | AJ1: StatValue | AK1: StatParam | AL1: StatValue | AM1: SkillId | AN1: DefaultCheck | AO1: SkillId | AP1: DefaultCheck | AQ1: SkillId | AR1: DefaultCheck | AS1: SkillId | AT1: DefaultCheck
G3: 몬스터 타입 | H3: 크기 | L3: 등급 | M3: 속성 | N3: 직업 | AM3: Normal | AO3: Active | AQ3: Ultimate | AS3: Passive
A4: 10000064 | B4: 메두사 | C4: 106401 | D4: c064 | E4: character_name_10000064 | F4: =D4&"_profile" -> c064_profile | G4: None | H4: Normal | I4: 0.95,0.95,0.95 | J4: TRUE | K4: 0,0,0 | L4: 1 | M4: Dark | N4: Attacker | O4: =100+L4 -> 101 | P4: 6 | Q4: 6 | R4: 1 | S4: 0 | T4: 0 | U4: Spd | V4: 80 | W4: Hp | X4: 5100 | Y4: Atk | Z4: 420 | AA4: Def | AB4: 120 | AC4: Penetration | AD4: 120 | AE4: Hit | AF4: 100 | AG4: Dodge | AH4: 100 | AI4: CriRatio | AJ4: 5000 | AK4: CriDmgRatio | AL4: 150000 | AM4: =INT(1&L4&TEXT(RIGHT(A4,3),"0000")&"01") -> 11006401 | AN4: TRUE | AO4: =INT(2&$L4&TEXT(RIGHT($A4,3),"0000")&"01") -> 21006401 | AP4: TRUE | AQ4: =INT(3&$L4&TEXT(RIGHT($A4,3),"0000")&"01") -> 31006401 | AR4: TRUE | AS4: =INT(4&$L4&TEXT(RIGHT($A4,3),"0000")&"01") -> 41006401 | AT4: TRUE
A5: 10000156 | B5: 에르제베트 | C5: 115601 | D5: c156 | E5: ="character_name_"&A5 -> character_name_10000156 | F5: =D5&"_profile" -> c156_profile | G5: None | H5: Normal | I5: 0.95,0.95,0.95 | J5: TRUE | K5: 0,0,0 | L5: 2 | M5: Dark | N5: Attacker | O5: =100+L5 -> 102 | P5: {=_xlfn.IFS($N5="Attacker",6,$N5="Healer",3,$N5="Magician",4,$N5="Defender",3,$N5="Supporter",4)} -> 6 | Q5: {=_xlfn.IFS($N5="Attacker",6,$N5="Healer",3,$N5="Magician",4,$N5="Defender",3,$N5="Supporter",4)} -> 6 | R5: 1 | S5: 0 | T5: 0 | U5: Spd | V5: {=_xlfn.IFS(N5="Attacker",80,N5="Healer",90,N5="Magician",100,N5="Defender",110,N5="Supporter",120)} -> 80 | W5: Hp | X5: 5100 | Y5: Atk | Z5: 420 | AA5: Def | AB5: 120 | AC5: Penetration | AD5: 187 | AE5: Hit | AF5: 100 | AG5: Dodge | AH5: 100 | AI5: CriRatio | AJ5: 5000 | AK5: CriDmgRatio | AL5: 150000 | AM5: =INT(1&L5&TEXT(RIGHT(A5,3),"0000")&"01") -> 12015601 | AN5: TRUE | AO5: =INT(2&$L5&TEXT(RIGHT($A5,3),"0000")&"01") -> 22015601 | AP5: TRUE | AQ5: =INT(3&$L5&TEXT(RIGHT($A5,3),"0000")&"01") -> 32015601 | AR5: TRUE | AS5: =INT(4&$L5&TEXT(RIGHT($A5,3),"0000")&"01") -> 42015601 | AT5: TRUE
A6: 10000486 | B6: 쿠바바 | C6: 148601 | D6: c486 | E6: ="character_name_"&A6 -> character_name_10000486 | F6: =D6&"_profile" -> c486_profile | G6: None | H6: Normal | I6: 0.95,0.95,0.95 | J6: TRUE | K6: 0,0,0 | L6: 3 | M6: Dark | N6: Attacker | O6: =100+L6 -> 103 | P6: {=_xlfn.IFS($N6="Attacker",6,$N6="Healer",3,$N6="Magician",4,$N6="Defender",3,$N6="Supporter",4)} -> 6 | Q6: {=_xlfn.IFS($N6="Attacker",6,$N6="Healer",3,$N6="Magician",4,$N6="Defender",3,$N6="Supporter",4)} -> 6 | R6: 1 | S6: 0 | T6: 0 | U6: Spd | V6: {=_xlfn.IFS(N6="Attacker",80,N6="Healer",90,N6="Magician",100,N6="Defender",110,N6="Supporter",120)} -> 80 | W6: Hp | X6: 5100 | Y6: Atk | Z6: 420 | AA6: Def | AB6: 120 | AC6: Penetration | AD6: 187 | AE6: Hit | AF6: 100 | AG6: Dodge | AH6: 100 | AI6: CriRatio | AJ6: 5000 | AK6: CriDmgRatio | AL6: 150000 | AM6: =INT(1&L6&TEXT(RIGHT(A6,3),"0000")&"01") -> 13048601 | AN6: TRUE | AO6: =INT(2&$L6&TEXT(RIGHT($A6,3),"0000")&"01") -> 23048601 | AP6: TRUE | AQ6: =INT(3&$L6&TEXT(RIGHT($A6,3),"0000")&"01") -> 33048601 | AR6: TRUE | AS6: =INT(4&$L6&TEXT(RIGHT($A6,3),"0000")&"01") -> 43048601 | AT6: TRUE
A7: 10000532 | B7: 아누비스 | C7: 153201 | D7: c532 | E7: ="character_name_"&A7 -> character_name_10000532 | F7: =D7&"_profile" -> c532_profile | G7: None | H7: Normal | I7: 0.95,0.95,0.95 | J7: TRUE | K7: 0,0,0 | L7: 3 | M7: Dark | N7: Attacker | O7: =100+L7 -> 103 | P7: 6 | Q7: 6 | R7: 1 | S7: 0 | T7: 0 | U7: Spd | V7: {=_xlfn.IFS(N7="Attacker",80,N7="Healer",90,N7="Magician",100,N7="Defender",110,N7="Supporter",120)} -> 80 | W7: Hp | X7: 5100 | Y7: Atk | Z7: 420 | AA7: Def | AB7: 120 | AC7: Penetration | AD7: 120 | AE7: Hit | AF7: 100 | AG7: Dodge | AH7: 100 | AI7: CriRatio | AJ7: 5000 | AK7: CriDmgRatio | AL7: 150000 | AM7: =INT(1&L7&TEXT(RIGHT(A7,3),"0000")&"01") -> 13053201 | AN7: TRUE | AO7: =INT(2&$L7&TEXT(RIGHT($A7,3),"0000")&"01") -> 23053201 | AP7: TRUE | AQ7: =INT(3&$L7&TEXT(RIGHT($A7,3),"0000")&"01") -> 33053201 | AR7: TRUE | AS7: =INT(4&$L7&TEXT(RIGHT($A7,3),"0000")&"01") -> 43053201 | AT7: TRUE
A8: 10000001 | B8: 모나 | C8: 100101 | D8: c001 | E8: ="character_name_"&A8 -> character_name_10000001 | F8: =D8&"_profile" -> c001_profile | G8: None | H8: Normal | I8: 0.95,0.95,0.95 | J8: TRUE | K8: 0,0,0 | L8: 2 | M8: Dark | N8: Defender | O8: =100+L8 -> 102 | P8: 3 | Q8: 3 | R8: 1 | S8: 0 | T8: 0 | U8: Spd | V8: {=_xlfn.IFS(N8="Attacker",80,N8="Healer",90,N8="Magician",100,N8="Defender",110,N8="Supporter",120)} -> 110 | W8: Hp | X8: 6475 | Y8: Atk | Z8: 168 | AA8: Def | AB8: 151 | AC8: Penetration | AD8: 163 | AE8: Hit | AF8: 100 | AG8: Dodge | AH8: 100 | AI8: CriRatio | AJ8: 5000 | AK8: CriDmgRatio | AL8: 150000 | AM8: =INT(1&L8&TEXT(RIGHT(A8,3),"0000")&"01") -> 12000101 | AN8: TRUE | AO8: =INT(2&$L8&TEXT(RIGHT($A8,3),"0000")&"01") -> 22000101 | AP8: TRUE | AQ8: =INT(3&$L8&TEXT(RIGHT($A8,3),"0000")&"01") -> 32000101 | AR8: TRUE | AS8: =INT(4&$L8&TEXT(RIGHT($A8,3),"0000")&"01") -> 42000101 | AT8: TRUE
A9: 10000051 | B9: 프레이 | C9: 105101 | D9: c051 | E9: ="character_name_"&A9 -> character_name_10000051 | F9: =D9&"_profile" -> c051_profile | G9: None | H9: Normal | I9: 0.95,0.95,0.95 | J9: TRUE | K9: 0,0,0 | L9: 3 | M9: Dark | N9: Defender | O9: =100+L9 -> 103 | P9: {=_xlfn.IFS($N9="Attacker",6,$N9="Healer",3,$N9="Magician",4,$N9="Defender",3,$N9="Supporter",4)} -> 3 | Q9: {=_xlfn.IFS($N9="Attacker",6,$N9="Healer",3,$N9="Magician",4,$N9="Defender",3,$N9="Supporter",4)} -> 3 | R9: 1 | S9: 0 | T9: 0 | U9: Spd | V9: {=_xlfn.IFS(N9="Attacker",80,N9="Healer",90,N9="Magician",100,N9="Defender",110,N9="Supporter",120)} -> 110 | W9: Hp | X9: 8650 | Y9: Atk | Z9: 252 | AA9: Def | AB9: 240 | AC9: Penetration | AD9: 234 | AE9: Hit | AF9: 100 | AG9: Dodge | AH9: 100 | AI9: CriRatio | AJ9: 5000 | AK9: CriDmgRatio | AL9: 150000 | AM9: =INT(1&L9&TEXT(RIGHT(A9,3),"0000")&"01") -> 13005101 | AN9: TRUE | AO9: =INT(2&$L9&TEXT(RIGHT($A9,3),"0000")&"01") -> 23005101 | AP9: TRUE | AQ9: =INT(3&$L9&TEXT(RIGHT($A9,3),"0000")&"01") -> 33005101 | AR9: TRUE | AS9: =INT(4&$L9&TEXT(RIGHT($A9,3),"0000")&"01") -> 43005101 | AT9: TRUE
A10: 10000048 | B10: 네반 | C10: 104801 | D10: c048 | E10: character_name_10000048 | F10: =D10&"_profile" -> c048_profile | G10: None | H10: Normal | I10: 0.95,0.95,0.95 | J10: TRUE | K10: 0,0,0 | L10: 1 | M10: Dark | N10: Healer | O10: =100+L10 -> 101 | P10: 3 | Q10: 3 | R10: 1 | S10: 0 | T10: 0 | U10: Spd | V10: 90 | W10: Hp | X10: 6475 | Y10: Atk | Z10: 168 | AA10: Def | AB10: 151 | AC10: Penetration | AD10: 151 | AE10: Hit | AF10: 100 | AG10: Dodge | AH10: 100 | AI10: CriRatio | AJ10: 5000 | AK10: CriDmgRatio | AL10: 150000 | AM10: =INT(1&L10&TEXT(RIGHT(A10,3),"0000")&"01") -> 11004801 | AN10: TRUE | AO10: =INT(2&$L10&TEXT(RIGHT($A10,3),"0000")&"01") -> 21004801 | AP10: TRUE | AQ10: =INT(3&$L10&TEXT(RIGHT($A10,3),"0000")&"01") -> 31004801 | AR10: TRUE | AS10: =INT(4&$L10&TEXT(RIGHT($A10,3),"0000")&"01") -> 41004801 | AT10: TRUE
A11: 10000448 | B11: 미르칼라 | C11: 144801 | D11: c448 | E11: ="character_name_"&A11 -> character_name_10000448 | F11: =D11&"_profile" -> c448_profile | G11: None | H11: Normal | I11: 0.95,0.95,0.95 | J11: TRUE | K11: 0,0,0 | L11: 3 | M11: Dark | N11: Healer | O11: =100+L11 -> 103 | P11: 4 | Q11: 4 | R11: 1 | S11: 0 | T11: 0 | U11: Spd | V11: {=_xlfn.IFS(N11="Attacker",80,N11="Healer",90,N11="Magician",100,N11="Defender",110,N11="Supporter",120)} -> 90 | W11: Hp | X11: 4743 | Y11: Atk | Z11: 341 | AA11: Def | AB11: 108 | AC11: Penetration | AD11: 108 | AE11: Hit | AF11: 100 | AG11: Dodge | AH11: 100 | AI11: CriRatio | AJ11: 5000 | AK11: CriDmgRatio | AL11: 150000 | AM11: =INT(1&L11&TEXT(RIGHT(A11,3),"0000")&"01") -> 13044801 | AN11: TRUE | AO11: =INT(2&$L11&TEXT(RIGHT($A11,3),"0000")&"01") -> 23044801 | AP11: TRUE | AQ11: =INT(3&$L11&TEXT(RIGHT($A11,3),"0000")&"01") -> 33044801 | AR11: TRUE | AS11: =INT(4&$L11&TEXT(RIGHT($A11,3),"0000")&"01") -> 43044801 | AT11: TRUE
A12: 10000514 | B12: 두엣샤 | C12: 151401 | D12: c514 | E12: ="character_name_"&A12 -> character_name_10000514 | F12: =D12&"_profile" -> c514_profile | G12: None | H12: Normal | I12: 0.95,0.95,0.95 | J12: TRUE | K12: 0,0,0 | L12: 2 | M12: Dark | N12: Magician | O12: =100+L12 -> 102 | P12: {=_xlfn.IFS($N12="Attacker",6,$N12="Healer",3,$N12="Magician",4,$N12="Defender",3,$N12="Supporter",4)} -> 4 | Q12: {=_xlfn.IFS($N12="Attacker",6,$N12="Healer",3,$N12="Magician",4,$N12="Defender",3,$N12="Supporter",4)} -> 4 | R12: 1 | S12: 0 | T12: 0 | U12: Spd | V12: {=_xlfn.IFS(N12="Attacker",80,N12="Healer",90,N12="Magician",100,N12="Defender",110,N12="Supporter",120)} -> 100 | W12: Hp | X12: 5100 | Y12: Atk | Z12: 420 | AA12: Def | AB12: 120 | AC12: Penetration | AD12: 156 | AE12: Hit | AF12: 100 | AG12: Dodge | AH12: 100 | AI12: CriRatio | AJ12: 5000 | AK12: CriDmgRatio | AL12: 150000 | AM12: =INT(1&L12&TEXT(RIGHT(A12,3),"0000")&"01") -> 12051401 | AN12: TRUE | AO12: =INT(2&$L12&TEXT(RIGHT($A12,3),"0000")&"01") -> 22051401 | AP12: TRUE | AQ12: =INT(3&$L12&TEXT(RIGHT($A12,3),"0000")&"01") -> 32051401 | AR12: TRUE | AS12: =INT(4&$L12&TEXT(RIGHT($A12,3),"0000")&"01") -> 42051401 | AT12: TRUE
A13: 10000432 | B13: 아르테미스 | C13: 143201 | D13: c432 | E13: ="character_name_"&A13 -> character_name_10000432 | F13: =D13&"_profile" -> c432_profile | G13: None | H13: Normal | I13: 0.95,0.95,0.95 | J13: TRUE | K13: 0,0,0 | L13: 3 | M13: Dark | N13: Magician | O13: =100+L13 -> 103 | P13: {=_xlfn.IFS($N13="Attacker",6,$N13="Healer",3,$N13="Magician",4,$N13="Defender",3,$N13="Supporter",4)} -> 4 | Q13: {=_xlfn.IFS($N13="Attacker",6,$N13="Healer",3,$N13="Magician",4,$N13="Defender",3,$N13="Supporter",4)} -> 4 | R13: 1 | S13: 0 | T13: 0 | U13: Spd | V13: {=_xlfn.IFS(N13="Attacker",80,N13="Healer",90,N13="Magician",100,N13="Defender",110,N13="Supporter",120)} -> 100 | W13: Hp | X13: 5100 | Y13: Atk | Z13: 420 | AA13: Def | AB13: 120 | AC13: Penetration | AD13: 156 | AE13: Hit | AF13: 100 | AG13: Dodge | AH13: 100 | AI13: CriRatio | AJ13: 5000 | AK13: CriDmgRatio | AL13: 150000 | AM13: =INT(1&L13&TEXT(RIGHT(A13,3),"0000")&"01") -> 13043201 | AN13: TRUE | AO13: =INT(2&$L13&TEXT(RIGHT($A13,3),"0000")&"01") -> 23043201 | AP13: TRUE | AQ13: =INT(3&$L13&TEXT(RIGHT($A13,3),"0000")&"01") -> 33043201 | AR13: TRUE | AS13: =INT(4&$L13&TEXT(RIGHT($A13,3),"0000")&"01") -> 43043201 | AT13: TRUE
A14: 10000400 | B14: 반시 | C14: 140001 | D14: c400 | E14: ="character_name_"&A14 -> character_name_10000400 | F14: =D14&"_profile" -> c400_profile | G14: None | H14: Normal | I14: 0.95,0.95,0.95 | J14: TRUE | K14: 0,0,0 | L14: 3 | M14: Dark | N14: Magician | O14: =100+L14 -> 103 | P14: {=_xlfn.IFS($N14="Attacker",6,$N14="Healer",3,$N14="Magician",4,$N14="Defender",3,$N14="Supporter",4)} -> 4 | Q14: {=_xlfn.IFS($N14="Attacker",6,$N14="Healer",3,$N14="Magician",4,$N14="Defender",3,$N14="Supporter",4)} -> 4 | R14: 1 | S14: 0 | T14: 0 | U14: Spd | V14: {=_xlfn.IFS(N14="Attacker",80,N14="Healer",90,N14="Magician",100,N14="Defender",110,N14="Supporter",120)} -> 100 | W14: Hp | X14: 5100 | Y14: Atk | Z14: 420 | AA14: Def | AB14: 120 | AC14: Penetration | AD14: 156 | AE14: Hit | AF14: 100 | AG14: Dodge | AH14: 100 | AI14: CriRatio | AJ14: 5000 | AK14: CriDmgRatio | AL14: 150000 | AM14: =INT(1&L14&TEXT(RIGHT(A14,3),"0000")&"01") -> 13040001 | AN14: TRUE | AO14: =INT(2&$L14&TEXT(RIGHT($A14,3),"0000")&"01") -> 23040001 | AP14: TRUE | AQ14: =INT(3&$L14&TEXT(RIGHT($A14,3),"0000")&"01") -> 33040001 | AR14: TRUE | AS14: =INT(4&$L14&TEXT(RIGHT($A14,3),"0000")&"01") -> 43040001 | AT14: TRUE
A15: 10000035 | B15: 페르세포네 | C15: 103501 | D15: c035 | E15: character_name_10000035 | F15: =D15&"_profile" -> c035_profile | G15: None | H15: Normal | I15: 0.95,0.95,0.95 | J15: TRUE | K15: 0,0,0 | L15: 1 | M15: Dark | N15: Supporter | O15: =100+L15 -> 101 | P15: 4 | Q15: 4 | R15: 1 | S15: 0 | T15: 0 | U15: Spd | V15: 120 | W15: Hp | X15: 5909 | Y15: Atk | Z15: 198 | AA15: Def | AB15: 142 | AC15: Penetration | AD15: 142 | AE15: Hit | AF15: 100 | AG15: Dodge | AH15: 100 | AI15: CriRatio | AJ15: 5000 | AK15: CriDmgRatio | AL15: 150000 | AM15: =INT(1&$L15&TEXT(RIGHT($A15,3),"0000")&"01") -> 11003501 | AN15: TRUE | AO15: =INT(2&$L15&TEXT(RIGHT($A15,3),"0000")&"01") -> 21003501 | AP15: TRUE | AQ15: =INT(3&$L15&TEXT(RIGHT($A15,3),"0000")&"01") -> 31003501 | AR15: TRUE | AS15: =INT(4&$L15&TEXT(RIGHT($A15,3),"0000")&"01") -> 41003501 | AT15: TRUE
A16: 10000294 | B16: 바토리 | C16: 129401 | D16: c294 | E16: ="character_name_"&A16 -> character_name_10000294 | F16: =D16&"_profile" -> c294_profile | G16: None | H16: Normal | I16: 0.95,0.95,0.95 | J16: TRUE | K16: 0,0,0 | L16: 3 | M16: Dark | N16: Supporter | O16: =100+L16 -> 103 | P16: 6 | Q16: 6 | R16: 1 | S16: 0 | T16: 0 | U16: Spd | V16: {=_xlfn.IFS(N16="Attacker",80,N16="Healer",90,N16="Magician",100,N16="Defender",110,N16="Supporter",120)} -> 120 | W16: Hp | X16: 5100 | Y16: Atk | Z16: 420 | AA16: Def | AB16: 120 | AC16: Penetration | AD16: 156 | AE16: Hit | AF16: 100 | AG16: Dodge | AH16: 100 | AI16: CriRatio | AJ16: 5000 | AK16: CriDmgRatio | AL16: 150000 | AM16: =INT(1&L16&TEXT(RIGHT(A16,3),"0000")&"01") -> 13029401 | AN16: TRUE | AO16: =INT(2&$L16&TEXT(RIGHT($A16,3),"0000")&"01") -> 23029401 | AP16: TRUE | AQ16: =INT(3&$L16&TEXT(RIGHT($A16,3),"0000")&"01") -> 33029401 | AR16: TRUE | AS16: =INT(4&$L16&TEXT(RIGHT($A16,3),"0000")&"01") -> 43029401 | AT16: TRUE
A17: 10000485 | B17: 유나 | C17: 148501 | D17: c485 | E17: ="character_name_"&A17 -> character_name_10000485 | F17: =D17&"_profile" -> c485_profile | G17: None | H17: Normal | I17: 0.95,0.95,0.95 | J17: TRUE | K17: 0,0,0 | L17: 3 | M17: Dark | N17: Supporter | O17: =100+L17 -> 103 | P17: 4 | Q17: 4 | R17: 1 | S17: 0 | T17: 0 | U17: Spd | V17: {=_xlfn.IFS(N17="Attacker",80,N17="Healer",90,N17="Magician",100,N17="Defender",110,N17="Supporter",120)} -> 120 | W17: Hp | X17: 5909 | Y17: Atk | Z17: 198 | AA17: Def | AB17: 142 | AC17: Penetration | AD17: 142 | AE17: Hit | AF17: 100 | AG17: Dodge | AH17: 100 | AI17: CriRatio | AJ17: 5000 | AK17: CriDmgRatio | AL17: 150000 | AM17: =INT(1&L17&TEXT(RIGHT(A17,3),"0000")&"01") -> 13048501 | AN17: TRUE | AO17: =INT(2&$L17&TEXT(RIGHT($A17,3),"0000")&"01") -> 23048501 | AP17: TRUE | AQ17: =INT(3&$L17&TEXT(RIGHT($A17,3),"0000")&"01") -> 33048501 | AR17: TRUE | AS17: =INT(4&$L17&TEXT(RIGHT($A17,3),"0000")&"01") -> 43048501 | AT17: TRUE
A18: 10000083 | B18: 네이드 | C18: 108301 | D18: c083 | E18: character_name_10000083 | F18: =D18&"_profile" -> c083_profile | G18: None | H18: Normal | I18: 0.95,0.95,0.95 | J18: TRUE | K18: 0,0,0 | L18: 1 | M18: Fire | N18: Attacker | O18: =100+L18 -> 101 | P18: 6 | Q18: 6 | R18: 1 | S18: 0 | T18: 0 | U18: Spd | V18: 80 | W18: Hp | X18: 5100 | Y18: Atk | Z18: 420 | AA18: Def | AB18: 120 | AC18: Penetration | AD18: 120 | AE18: Hit | AF18: 100 | AG18: Dodge | AH18: 100 | AI18: CriRatio | AJ18: 5000 | AK18: CriDmgRatio | AL18: 150000 | AM18: =INT(1&L18&TEXT(RIGHT(A18,3),"0000")&"01") -> 11008301 | AN18: TRUE | AO18: =INT(2&$L18&TEXT(RIGHT($A18,3),"0000")&"01") -> 21008301 | AP18: TRUE | AQ18: =INT(3&$L18&TEXT(RIGHT($A18,3),"0000")&"01") -> 31008301 | AR18: TRUE | AS18: =INT(4&$L18&TEXT(RIGHT($A18,3),"0000")&"01") -> 41008301 | AT18: TRUE
A19: 10000412 | B19: 카인 | C19: 141201 | D19: c412 | E19: ="character_name_"&A19 -> character_name_10000412 | F19: =D19&"_profile" -> c412_profile | G19: None | H19: Normal | I19: 0.95,0.95,0.95 | J19: TRUE | K19: 0,0,0 | L19: 2 | M19: Fire | N19: Attacker | O19: =100+L19 -> 102 | P19: {=_xlfn.IFS($N19="Attacker",6,$N19="Healer",3,$N19="Magician",4,$N19="Defender",3,$N19="Supporter",4)} -> 6 | Q19: {=_xlfn.IFS($N19="Attacker",6,$N19="Healer",3,$N19="Magician",4,$N19="Defender",3,$N19="Supporter",4)} -> 6 | R19: 1 | S19: 0 | T19: 0 | U19: Spd | V19: {=_xlfn.IFS(N19="Attacker",80,N19="Healer",90,N19="Magician",100,N19="Defender",110,N19="Supporter",120)} -> 80 | W19: Hp | X19: 5100 | Y19: Atk | Z19: 420 | AA19: Def | AB19: 120 | AC19: Penetration | AD19: 130 | AE19: Hit | AF19: 100 | AG19: Dodge | AH19: 100 | AI19: CriRatio | AJ19: 5000 | AK19: CriDmgRatio | AL19: 150000 | AM19: =INT(1&L19&TEXT(RIGHT(A19,3),"0000")&"01") -> 12041201 | AN19: TRUE | AO19: =INT(2&$L19&TEXT(RIGHT($A19,3),"0000")&"01") -> 22041201 | AP19: TRUE | AQ19: =INT(3&$L19&TEXT(RIGHT($A19,3),"0000")&"01") -> 32041201 | AR19: TRUE | AS19: =INT(4&$L19&TEXT(RIGHT($A19,3),"0000")&"01") -> 42041201 | AT19: TRUE
A20: 10000501 | B20: 라가라자 | C20: 150101 | D20: c501 | E20: ="character_name_"&A20 -> character_name_10000501 | F20: =D20&"_profile" -> c501_profile | G20: None | H20: Normal | I20: 0.95,0.95,0.95 | J20: TRUE | K20: 0,0,0 | L20: 3 | M20: Fire | N20: Attacker | O20: =100+L20 -> 103 | P20: {=_xlfn.IFS($N20="Attacker",6,$N20="Healer",3,$N20="Magician",4,$N20="Defender",3,$N20="Supporter",4)} -> 6 | Q20: {=_xlfn.IFS($N20="Attacker",6,$N20="Healer",3,$N20="Magician",4,$N20="Defender",3,$N20="Supporter",4)} -> 6 | R20: 1 | S20: 0 | T20: 0 | U20: Spd | V20: {=_xlfn.IFS(N20="Attacker",80,N20="Healer",90,N20="Magician",100,N20="Defender",110,N20="Supporter",120)} -> 80 | W20: Hp | X20: 8650 | Y20: Atk | Z20: 252 | AA20: Def | AB20: 240 | AC20: Penetration | AD20: 234 | AE20: Hit | AF20: 100 | AG20: Dodge | AH20: 100 | AI20: CriRatio | AJ20: 5000 | AK20: CriDmgRatio | AL20: 150000 | AM20: =INT(1&L20&TEXT(RIGHT(A20,3),"0000")&"01") -> 13050101 | AN20: TRUE | AO20: =INT(2&$L20&TEXT(RIGHT($A20,3),"0000")&"01") -> 23050101 | AP20: TRUE | AQ20: =INT(3&$L20&TEXT(RIGHT($A20,3),"0000")&"01") -> 33050101 | AR20: TRUE | AS20: =INT(4&$L20&TEXT(RIGHT($A20,3),"0000")&"01") -> 43050101 | AT20: TRUE
A21: 10000445 | B21: 카라라트리 | C21: 144501 | D21: c445 | E21: ="character_name_"&A21 -> character_name_10000445 | F21: =D21&"_profile" -> c445_profile | G21: None | H21: Normal | I21: 0.95,0.95,0.95 | J21: TRUE | K21: 0,0,0 | L21: 3 | M21: Fire | N21: Attacker | O21: =100+L21 -> 103 | P21: 4 | Q21: 4 | R21: 1 | S21: 0 | T21: 0 | U21: Spd | V21: {=_xlfn.IFS(N21="Attacker",80,N21="Healer",90,N21="Magician",100,N21="Defender",110,N21="Supporter",120)} -> 80 | W21: Hp | X21: 4743 | Y21: Atk | Z21: 341 | AA21: Def | AB21: 108 | AC21: Penetration | AD21: 156 | AE21: Hit | AF21: 100 | AG21: Dodge | AH21: 100 | AI21: CriRatio | AJ21: 5000 | AK21: CriDmgRatio | AL21: 150000 | AM21: =INT(1&L21&TEXT(RIGHT(A21,3),"0000")&"01") -> 13044501 | AN21: TRUE | AO21: =INT(2&$L21&TEXT(RIGHT($A21,3),"0000")&"01") -> 23044501 | AP21: TRUE | AQ21: =INT(3&$L21&TEXT(RIGHT($A21,3),"0000")&"01") -> 33044501 | AR21: TRUE | AS21: =INT(4&$L21&TEXT(RIGHT($A21,3),"0000")&"01") -> 43044501 | AT21: TRUE
A22: 10000037 | B22: 유다 | C22: 103701 | D22: c037 | E22: character_name_10000037 | F22: =D22&"_profile" -> c037_profile | G22: None | H22: Normal | I22: 0.95,0.95,0.95 | J22: TRUE | K22: 0,0,0 | L22: 1 | M22: Fire | N22: Defender | O22: =100+L22 -> 101 | P22: 3 | Q22: 3 | R22: 1 | S22: 0 | T22: 0 | U22: Spd | V22: 110 | W22: Hp | X22: 8650 | Y22: Atk | Z22: 252 | AA22: Def | AB22: 240 | AC22: Penetration | AD22: 240 | AE22: Hit | AF22: 100 | AG22: Dodge | AH22: 100 | AI22: CriRatio | AJ22: 5000 | AK22: CriDmgRatio | AL22: 150000 | AM22: =INT(1&L22&TEXT(RIGHT(A22,3),"0000")&"01") -> 11003701 | AN22: TRUE | AO22: =INT(2&$L22&TEXT(RIGHT($A22,3),"0000")&"01") -> 21003701 | AP22: TRUE | AQ22: =INT(3&$L22&TEXT(RIGHT($A22,3),"0000")&"01") -> 31003701 | AR22: TRUE | AS22: =INT(4&$L22&TEXT(RIGHT($A22,3),"0000")&"01") -> 41003701 | AT22: TRUE
A23: 10000462 | B23: 데레사 | C23: 146201 | D23: c462 | E23: ="character_name_"&A23 -> character_name_10000462 | F23: =D23&"_profile" -> c462_profile | G23: None | H23: Normal | I23: 0.95,0.95,0.95 | J23: TRUE | K23: 0,0,0 | L23: 3 | M23: Fire | N23: Defender | O23: =100+L23 -> 103 | P23: {=_xlfn.IFS($N23="Attacker",6,$N23="Healer",3,$N23="Magician",4,$N23="Defender",3,$N23="Supporter",4)} -> 3 | Q23: {=_xlfn.IFS($N23="Attacker",6,$N23="Healer",3,$N23="Magician",4,$N23="Defender",3,$N23="Supporter",4)} -> 3 | R23: 1 | S23: 0 | T23: 0 | U23: Spd | V23: {=_xlfn.IFS(N23="Attacker",80,N23="Healer",90,N23="Magician",100,N23="Defender",110,N23="Supporter",120)} -> 110 | W23: Hp | X23: 8650 | Y23: Atk | Z23: 252 | AA23: Def | AB23: 240 | AC23: Penetration | AD23: 156 | AE23: Hit | AF23: 100 | AG23: Dodge | AH23: 100 | AI23: CriRatio | AJ23: 5000 | AK23: CriDmgRatio | AL23: 150000 | AM23: =INT(1&L23&TEXT(RIGHT(A23,3),"0000")&"01") -> 13046201 | AN23: TRUE | AO23: =INT(2&$L23&TEXT(RIGHT($A23,3),"0000")&"01") -> 23046201 | AP23: TRUE | AQ23: =INT(3&$L23&TEXT(RIGHT($A23,3),"0000")&"01") -> 33046201 | AR23: TRUE | AS23: =INT(4&$L23&TEXT(RIGHT($A23,3),"0000")&"01") -> 43046201 | AT23: TRUE
A24: 10000286 | B24: 베르들레 | C24: 128601 | D24: c286 | E24: character_name_10000286 | F24: =D24&"_profile" -> c286_profile | G24: None | H24: Normal | I24: 0.95,0.95,0.95 | J24: TRUE | K24: 0,0,0 | L24: 1 | M24: Fire | N24: Healer | O24: =100+L24 -> 101 | P24: 3 | Q24: 3 | R24: 1 | S24: 0 | T24: 0 | U24: Spd | V24: 90 | W24: Hp | X24: 6475 | Y24: Atk | Z24: 168 | AA24: Def | AB24: 151 | AC24: Penetration | AD24: 151 | AE24: Hit | AF24: 100 | AG24: Dodge | AH24: 100 | AI24: CriRatio | AJ24: 5000 | AK24: CriDmgRatio | AL24: 150000 | AM24: =INT(1&L24&TEXT(RIGHT(A24,3),"0000")&"01") -> 11028601 | AN24: TRUE | AO24: =INT(2&$L24&TEXT(RIGHT($A24,3),"0000")&"01") -> 21028601 | AP24: TRUE | AQ24: =INT(3&$L24&TEXT(RIGHT($A24,3),"0000")&"01") -> 31028601 | AR24: TRUE | AS24: =INT(4&$L24&TEXT(RIGHT($A24,3),"0000")&"01") -> 41028601 | AT24: TRUE
A25: 10000429 | B25: 지바 | C25: 142901 | D25: c429 | E25: ="character_name_"&A25 -> character_name_10000429 | F25: =D25&"_profile" -> c429_profile | G25: None | H25: Normal | I25: 0.95,0.95,0.95 | J25: TRUE | K25: 0,0,0 | L25: 3 | M25: Fire | N25: Healer | O25: =100+L25 -> 103 | P25: 3 | Q25: 3 | R25: 1 | S25: 0 | T25: 0 | U25: Spd | V25: {=_xlfn.IFS(N25="Attacker",80,N25="Healer",90,N25="Magician",100,N25="Defender",110,N25="Supporter",120)} -> 90 | W25: Hp | X25: 6475 | Y25: Atk | Z25: 168 | AA25: Def | AB25: 151 | AC25: Penetration | AD25: 151 | AE25: Hit | AF25: 100 | AG25: Dodge | AH25: 100 | AI25: CriRatio | AJ25: 5000 | AK25: CriDmgRatio | AL25: 150000 | AM25: =INT(1&L25&TEXT(RIGHT(A25,3),"0000")&"01") -> 13042901 | AN25: TRUE | AO25: =INT(2&$L25&TEXT(RIGHT($A25,3),"0000")&"01") -> 23042901 | AP25: TRUE | AQ25: =INT(3&$L25&TEXT(RIGHT($A25,3),"0000")&"01") -> 33042901 | AR25: TRUE | AS25: =INT(4&$L25&TEXT(RIGHT($A25,3),"0000")&"01") -> 43042901 | AT25: TRUE
A26: 10000003 | B26: 다비 | C26: 100301 | D26: c003 | E26: ="character_name_"&A26 -> character_name_10000003 | F26: =D26&"_profile" -> c003_profile | G26: None | H26: Normal | I26: 0.95,0.95,0.95 | J26: TRUE | K26: 0,0,0 | L26: 2 | M26: Fire | N26: Magician | O26: =100+L26 -> 102 | P26: 6 | Q26: 6 | R26: 1 | S26: 0 | T26: 0 | U26: Spd | V26: {=_xlfn.IFS(N26="Attacker",80,N26="Healer",90,N26="Magician",100,N26="Defender",110,N26="Supporter",120)} -> 100 | W26: Hp | X26: 5100 | Y26: Atk | Z26: 420 | AA26: Def | AB26: 120 | AC26: Penetration | AD26: 130 | AE26: Hit | AF26: 100 | AG26: Dodge | AH26: 100 | AI26: CriRatio | AJ26: 5000 | AK26: CriDmgRatio | AL26: 150000 | AM26: =INT(1&L26&TEXT(RIGHT(A26,3),"0000")&"01") -> 12000301 | AN26: TRUE | AO26: =INT(2&$L26&TEXT(RIGHT($A26,3),"0000")&"01") -> 22000301 | AP26: TRUE | AQ26: =INT(3&$L26&TEXT(RIGHT($A26,3),"0000")&"01") -> 32000301 | AR26: TRUE | AS26: =INT(4&$L26&TEXT(RIGHT($A26,3),"0000")&"01") -> 42000301 | AT26: TRUE
A27: 10000417 | B27: 구미호 | C27: 141701 | D27: c417 | E27: ="character_name_"&A27 -> character_name_10000417 | F27: =D27&"_profile" -> c417_profile | G27: None | H27: Normal | I27: 0.95,0.95,0.95 | J27: TRUE | K27: 0,0,0 | L27: 3 | M27: Fire | N27: Magician | O27: =100+L27 -> 103 | P27: 4 | Q27: 4 | R27: 1 | S27: 0 | T27: 0 | U27: Spd | V27: {=_xlfn.IFS(N27="Attacker",80,N27="Healer",90,N27="Magician",100,N27="Defender",110,N27="Supporter",120)} -> 100 | W27: Hp | X27: 4743 | Y27: Atk | Z27: 341 | AA27: Def | AB27: 108 | AC27: Penetration | AD27: 187 | AE27: Hit | AF27: 100 | AG27: Dodge | AH27: 100 | AI27: CriRatio | AJ27: 5000 | AK27: CriDmgRatio | AL27: 150000 | AM27: =INT(1&L27&TEXT(RIGHT(A27,3),"0000")&"01") -> 13041701 | AN27: TRUE | AO27: =INT(2&$L27&TEXT(RIGHT($A27,3),"0000")&"01") -> 23041701 | AP27: TRUE | AQ27: =INT(3&$L27&TEXT(RIGHT($A27,3),"0000")&"01") -> 33041701 | AR27: TRUE | AS27: =INT(4&$L27&TEXT(RIGHT($A27,3),"0000")&"01") -> 43041701 | AT27: TRUE
A28: 10000283 | B28: 모건 | C28: 128301 | D28: c283 | E28: ="character_name_"&A28 -> character_name_10000283 | F28: =D28&"_profile" -> c283_profile | G28: None | H28: Normal | I28: 0.95,0.95,0.95 | J28: TRUE | K28: 0,0,0 | L28: 3 | M28: Fire | N28: Magician | O28: =100+L28 -> 103 | P28: 3 | Q28: 3 | R28: 1 | S28: 0 | T28: 0 | U28: Spd | V28: {=_xlfn.IFS(N28="Attacker",80,N28="Healer",90,N28="Magician",100,N28="Defender",110,N28="Supporter",120)} -> 100 | W28: Hp | X28: 8650 | Y28: Atk | Z28: 252 | AA28: Def | AB28: 240 | AC28: Penetration | AD28: 156 | AE28: Hit | AF28: 100 | AG28: Dodge | AH28: 100 | AI28: CriRatio | AJ28: 5000 | AK28: CriDmgRatio | AL28: 150000 | AM28: =INT(1&L28&TEXT(RIGHT(A28,3),"0000")&"01") -> 13028301 | AN28: TRUE | AO28: =INT(2&$L28&TEXT(RIGHT($A28,3),"0000")&"01") -> 23028301 | AP28: TRUE | AQ28: =INT(3&$L28&TEXT(RIGHT($A28,3),"0000")&"01") -> 33028301 | AR28: TRUE | AS28: =INT(4&$L28&TEXT(RIGHT($A28,3),"0000")&"01") -> 43028301 | AT28: TRUE
A29: 10000339 | B29: 다비 | C29: 133901 | D29: c339 | E29: character_name_10000339 | F29: =D29&"_profile" -> c339_profile | G29: None | H29: Normal | I29: 0.95,0.95,0.95 | J29: TRUE | K29: 0,0,0 | L29: 3 | M29: Fire | N29: Magician | O29: =100+L29 -> 103 | P29: 6 | Q29: 6 | R29: 1 | S29: 0 | T29: 0 | U29: Spd | V29: 100 | W29: Hp | X29: 5500 | Y29: Atk | Z29: 198 | AA29: Def | AB29: 142 | AC29: Penetration | AD29: 142 | AE29: Hit | AF29: 100 | AG29: Dodge | AH29: 100 | AI29: CriRatio | AJ29: 5000 | AK29: CriDmgRatio | AL29: 150000 | AM29: =INT(1&L29&TEXT(RIGHT(A29,3),"0000")&"01") -> 13033901 | AN29: TRUE | AO29: =INT(2&$L29&TEXT(RIGHT($A29,3),"0000")&"01") -> 23033901 | AP29: TRUE | AQ29: =INT(3&$L29&TEXT(RIGHT($A29,3),"0000")&"01") -> 33033901 | AR29: TRUE | AS29: =INT(4&$L29&TEXT(RIGHT($A29,3),"0000")&"01") -> 43033901 | AT29: TRUE
A30: 10000354 | B30: 드미테르 | C30: 135401 | D30: c354 | E30: ="character_name_"&A30 -> character_name_10000354 | F30: =D30&"_profile" -> c354_profile | G30: None | H30: Normal | I30: 0.95,0.95,0.95 | J30: TRUE | K30: 0,0,0 | L30: 2 | M30: Fire | N30: Supporter | O30: =100+L30 -> 102 | P30: {=_xlfn.IFS($N30="Attacker",6,$N30="Healer",3,$N30="Magician",4,$N30="Defender",3,$N30="Supporter",4)} -> 4 | Q30: {=_xlfn.IFS($N30="Attacker",6,$N30="Healer",3,$N30="Magician",4,$N30="Defender",3,$N30="Supporter",4)} -> 4 | R30: 1 | S30: 0 | T30: 0 | U30: Spd | V30: {=_xlfn.IFS(N30="Attacker",80,N30="Healer",90,N30="Magician",100,N30="Defender",110,N30="Supporter",120)} -> 120 | W30: Hp | X30: 5100 | Y30: Atk | Z30: 420 | AA30: Def | AB30: 120 | AC30: Penetration | AD30: 130 | AE30: Hit | AF30: 100 | AG30: Dodge | AH30: 100 | AI30: CriRatio | AJ30: 5000 | AK30: CriDmgRatio | AL30: 150000 | AM30: =INT(1&L30&TEXT(RIGHT(A30,3),"0000")&"01") -> 12035401 | AN30: TRUE | AO30: =INT(2&$L30&TEXT(RIGHT($A30,3),"0000")&"01") -> 22035401 | AP30: TRUE | AQ30: =INT(3&$L30&TEXT(RIGHT($A30,3),"0000")&"01") -> 32035401 | AR30: TRUE | AS30: =INT(4&$L30&TEXT(RIGHT($A30,3),"0000")&"01") -> 42035401 | AT30: TRUE
A31: 10000562 | B31: 살마키스 | C31: 156201 | D31: c562 | E31: ="character_name_"&A31 -> character_name_10000562 | F31: =D31&"_profile" -> c562_profile | G31: None | H31: Normal | I31: 0.95,0.95,0.95 | J31: TRUE | K31: 0,0,0 | L31: 3 | M31: Fire | N31: Supporter | O31: =100+L31 -> 103 | P31: 4 | Q31: 4 | R31: 1 | S31: 0 | T31: 0 | U31: Spd | V31: {=_xlfn.IFS(N31="Attacker",80,N31="Healer",90,N31="Magician",100,N31="Defender",110,N31="Supporter",120)} -> 120 | W31: Hp | X31: 5909 | Y31: Atk | Z31: 198 | AA31: Def | AB31: 142 | AC31: Penetration | AD31: 142 | AE31: Hit | AF31: 100 | AG31: Dodge | AH31: 100 | AI31: CriRatio | AJ31: 5000 | AK31: CriDmgRatio | AL31: 150000 | AM31: =INT(1&L31&TEXT(RIGHT(A31,3),"0000")&"01") -> 13056201 | AN31: TRUE | AO31: =INT(2&$L31&TEXT(RIGHT($A31,3),"0000")&"01") -> 23056201 | AP31: TRUE | AQ31: =INT(3&$L31&TEXT(RIGHT($A31,3),"0000")&"01") -> 33056201 | AR31: TRUE | AS31: =INT(4&$L31&TEXT(RIGHT($A31,3),"0000")&"01") -> 43056201 | AT31: TRUE
A32: 10000062 | B32: 에우로페 | C32: 106201 | D32: c062 | E32: character_name_10000062 | F32: =D32&"_profile" -> c062_profile | G32: None | H32: Normal | I32: 0.95,0.95,0.95 | J32: TRUE | K32: 0,0,0 | L32: 1 | M32: Forest | N32: Attacker | O32: =100+L32 -> 101 | P32: 6 | Q32: 6 | R32: 1 | S32: 0 | T32: 0 | U32: Spd | V32: 80 | W32: Hp | X32: 5100 | Y32: Atk | Z32: 420 | AA32: Def | AB32: 120 | AC32: Penetration | AD32: 120 | AE32: Hit | AF32: 100 | AG32: Dodge | AH32: 100 | AI32: CriRatio | AJ32: 5000 | AK32: CriDmgRatio | AL32: 150000 | AM32: =INT(1&L32&TEXT(RIGHT(A32,3),"0000")&"01") -> 11006201 | AN32: TRUE | AO32: =INT(2&$L32&TEXT(RIGHT($A32,3),"0000")&"01") -> 21006201 | AP32: TRUE | AQ32: =INT(3&$L32&TEXT(RIGHT($A32,3),"0000")&"01") -> 31006201 | AR32: TRUE | AS32: =INT(4&$L32&TEXT(RIGHT($A32,3),"0000")&"01") -> 41006201 | AT32: TRUE
A33: 10000132 | B33: 미다스 | C33: 113201 | D33: c132 | E33: character_name_10000132 | F33: =D33&"_profile" -> c132_profile | G33: None | H33: Normal | I33: 0.95,0.95,0.95 | J33: TRUE | K33: 0,0,0 | L33: 2 | M33: Forest | N33: Attacker | O33: =100+L33 -> 102 | P33: 6 | Q33: 6 | R33: 1 | S33: 0 | T33: 0 | U33: Spd | V33: 80 | W33: Hp | X33: 5100 | Y33: Atk | Z33: 420 | AA33: Def | AB33: 120 | AC33: Penetration | AD33: 120 | AE33: Hit | AF33: 100 | AG33: Dodge | AH33: 100 | AI33: CriRatio | AJ33: 5000 | AK33: CriDmgRatio | AL33: 150000 | AM33: =INT(1&L33&TEXT(RIGHT(A33,3),"0000")&"01") -> 12013201 | AN33: TRUE | AO33: =INT(2&$L33&TEXT(RIGHT($A33,3),"0000")&"01") -> 22013201 | AP33: TRUE | AQ33: =INT(3&$L33&TEXT(RIGHT($A33,3),"0000")&"01") -> 32013201 | AR33: TRUE | AS33: =INT(4&$L33&TEXT(RIGHT($A33,3),"0000")&"01") -> 42013201 | AT33: TRUE
A34: 10000447 | B34: 미리암 | C34: 144701 | D34: c447 | E34: ="character_name_"&A34 -> character_name_10000447 | F34: =D34&"_profile" -> c447_profile | G34: None | H34: Normal | I34: 0.95,0.95,0.95 | J34: TRUE | K34: 0,0,0 | L34: 3 | M34: Forest | N34: Attacker | O34: =100+L34 -> 103 | P34: {=_xlfn.IFS($N34="Attacker",6,$N34="Healer",3,$N34="Magician",4,$N34="Defender",3,$N34="Supporter",4)} -> 6 | Q34: {=_xlfn.IFS($N34="Attacker",6,$N34="Healer",3,$N34="Magician",4,$N34="Defender",3,$N34="Supporter",4)} -> 6 | R34: 1 | S34: 0 | T34: 0 | U34: Spd | V34: {=_xlfn.IFS(N34="Attacker",80,N34="Healer",90,N34="Magician",100,N34="Defender",110,N34="Supporter",120)} -> 80 | W34: Hp | X34: 8650 | Y34: Atk | Z34: 252 | AA34: Def | AB34: 240 | AC34: Penetration | AD34: 156 | AE34: Hit | AF34: 100 | AG34: Dodge | AH34: 100 | AI34: CriRatio | AJ34: 5000 | AK34: CriDmgRatio | AL34: 150000 | AM34: =INT(1&L34&TEXT(RIGHT(A34,3),"0000")&"01") -> 13044701 | AN34: TRUE | AO34: =INT(2&$L34&TEXT(RIGHT($A34,3),"0000")&"01") -> 23044701 | AP34: TRUE | AQ34: =INT(3&$L34&TEXT(RIGHT($A34,3),"0000")&"01") -> 33044701 | AR34: TRUE | AS34: =INT(4&$L34&TEXT(RIGHT($A34,3),"0000")&"01") -> 43044701 | AT34: TRUE
A35: 10000549 | B35: 다누 | C35: 154901 | D35: c549 | E35: ="character_name_"&A35 -> character_name_10000549 | F35: =D35&"_profile" -> c549_profile | G35: None | H35: Normal | I35: 0.95,0.95,0.95 | J35: TRUE | K35: 0,0,0 | L35: 3 | M35: Forest | N35: Attacker | O35: =100+L35 -> 103 | P35: {=_xlfn.IFS($N35="Attacker",6,$N35="Healer",3,$N35="Magician",4,$N35="Defender",3,$N35="Supporter",4)} -> 6 | Q35: {=_xlfn.IFS($N35="Attacker",6,$N35="Healer",3,$N35="Magician",4,$N35="Defender",3,$N35="Supporter",4)} -> 6 | R35: 1 | S35: 0 | T35: 0 | U35: Spd | V35: {=_xlfn.IFS(N35="Attacker",80,N35="Healer",90,N35="Magician",100,N35="Defender",110,N35="Supporter",120)} -> 80 | W35: Hp | X35: 6475 | Y35: Atk | Z35: 168 | AA35: Def | AB35: 151 | AC35: Penetration | AD35: 151 | AE35: Hit | AF35: 100 | AG35: Dodge | AH35: 100 | AI35: CriRatio | AJ35: 5000 | AK35: CriDmgRatio | AL35: 150000 | AM35: =INT(1&L35&TEXT(RIGHT(A35,3),"0000")&"01") -> 13054901 | AN35: TRUE | AO35: =INT(2&$L35&TEXT(RIGHT($A35,3),"0000")&"01") -> 23054901 | AP35: TRUE | AQ35: =INT(3&$L35&TEXT(RIGHT($A35,3),"0000")&"01") -> 33054901 | AR35: TRUE | AS35: =INT(4&$L35&TEXT(RIGHT($A35,3),"0000")&"01") -> 43054901 | AT35: TRUE
A36: 10000180 | B36: 맘몬 | C36: 118001 | D36: c180 | E36: ="character_name_"&A36 -> character_name_10000180 | F36: =D36&"_profile" -> c180_profile | G36: None | H36: Normal | I36: 0.95,0.95,0.95 | J36: TRUE | K36: 0,0,0 | L36: 2 | M36: Forest | N36: Defender | O36: =100+L36 -> 102 | P36: {=_xlfn.IFS($N36="Attacker",6,$N36="Healer",3,$N36="Magician",4,$N36="Defender",3,$N36="Supporter",4)} -> 3 | Q36: {=_xlfn.IFS($N36="Attacker",6,$N36="Healer",3,$N36="Magician",4,$N36="Defender",3,$N36="Supporter",4)} -> 3 | R36: 1 | S36: 0 | T36: 0 | U36: Spd | V36: {=_xlfn.IFS(N36="Attacker",80,N36="Healer",90,N36="Magician",100,N36="Defender",110,N36="Supporter",120)} -> 110 | W36: Hp | X36: 8650 | Y36: Atk | Z36: 252 | AA36: Def | AB36: 240 | AC36: Penetration | AD36: 163 | AE36: Hit | AF36: 100 | AG36: Dodge | AH36: 100 | AI36: CriRatio | AJ36: 5000 | AK36: CriDmgRatio | AL36: 150000 | AM36: =INT(1&L36&TEXT(RIGHT(A36,3),"0000")&"01") -> 12018001 | AN36: TRUE | AO36: =INT(2&$L36&TEXT(RIGHT($A36,3),"0000")&"01") -> 22018001 | AP36: TRUE | AQ36: =INT(3&$L36&TEXT(RIGHT($A36,3),"0000")&"01") -> 32018001 | AR36: TRUE | AS36: =INT(4&$L36&TEXT(RIGHT($A36,3),"0000")&"01") -> 42018001 | AT36: TRUE
A37: 10000468 | B37: 메티스 | C37: 146801 | D37: c468 | E37: ="character_name_"&A37 -> character_name_10000468 | F37: =D37&"_profile" -> c468_profile | G37: None | H37: Normal | I37: 0.95,0.95,0.95 | J37: TRUE | K37: 0,0,0 | L37: 3 | M37: Forest | N37: Defender | O37: =100+L37 -> 103 | P37: {=_xlfn.IFS($N37="Attacker",6,$N37="Healer",3,$N37="Magician",4,$N37="Defender",3,$N37="Supporter",4)} -> 3 | Q37: {=_xlfn.IFS($N37="Attacker",6,$N37="Healer",3,$N37="Magician",4,$N37="Defender",3,$N37="Supporter",4)} -> 3 | R37: 1 | S37: 0 | T37: 0 | U37: Spd | V37: {=_xlfn.IFS(N37="Attacker",80,N37="Healer",90,N37="Magician",100,N37="Defender",110,N37="Supporter",120)} -> 110 | W37: Hp | X37: 5909 | Y37: Atk | Z37: 198 | AA37: Def | AB37: 142 | AC37: Penetration | AD37: 142 | AE37: Hit | AF37: 100 | AG37: Dodge | AH37: 100 | AI37: CriRatio | AJ37: 5000 | AK37: CriDmgRatio | AL37: 150000 | AM37: =INT(1&L37&TEXT(RIGHT(A37,3),"0000")&"01") -> 13046801 | AN37: TRUE | AO37: =INT(2&$L37&TEXT(RIGHT($A37,3),"0000")&"01") -> 23046801 | AP37: TRUE | AQ37: =INT(3&$L37&TEXT(RIGHT($A37,3),"0000")&"01") -> 33046801 | AR37: TRUE | AS37: =INT(4&$L37&TEXT(RIGHT($A37,3),"0000")&"01") -> 43046801 | AT37: TRUE
A38: 10000031 | B38: 프레이야 | C38: 103101 | D38: c031 | E38: character_name_10000031 | F38: =D38&"_profile" -> c031_profile | G38: None | H38: Normal | I38: 0.95,0.95,0.95 | J38: TRUE | K38: 0,0,0 | L38: 1 | M38: Forest | N38: Healer | O38: =100+L38 -> 101 | P38: 3 | Q38: 3 | R38: 1 | S38: 0 | T38: 0 | U38: Spd | V38: 90 | W38: Hp | X38: 6475 | Y38: Atk | Z38: 168 | AA38: Def | AB38: 151 | AC38: Penetration | AD38: 151 | AE38: Hit | AF38: 100 | AG38: Dodge | AH38: 100 | AI38: CriRatio | AJ38: 5000 | AK38: CriDmgRatio | AL38: 150000 | AM38: =INT(1&L38&TEXT(RIGHT(A38,3),"0000")&"01") -> 11003101 | AN38: TRUE | AO38: =INT(2&$L38&TEXT(RIGHT($A38,3),"0000")&"01") -> 21003101 | AP38: TRUE | AQ38: =INT(3&$L38&TEXT(RIGHT($A38,3),"0000")&"01") -> 31003101 | AR38: TRUE | AS38: =INT(4&$L38&TEXT(RIGHT($A38,3),"0000")&"01") -> 41003101 | AT38: TRUE
A39: 10000229 | B39: 브라우니 | C39: 122901 | D39: c229 | E39: ="character_name_"&A39 -> character_name_10000229 | F39: =D39&"_profile" -> c229_profile | G39: None | H39: Normal | I39: 0.95,0.95,0.95 | J39: TRUE | K39: 0,0,0 | L39: 3 | M39: Forest | N39: Healer | O39: =100+L39 -> 103 | P39: 4 | Q39: 4 | R39: 1 | S39: 0 | T39: 0 | U39: Spd | V39: {=_xlfn.IFS(N39="Attacker",80,N39="Healer",90,N39="Magician",100,N39="Defender",110,N39="Supporter",120)} -> 90 | W39: Hp | X39: 5909 | Y39: Atk | Z39: 198 | AA39: Def | AB39: 142 | AC39: Penetration | AD39: 156 | AE39: Hit | AF39: 100 | AG39: Dodge | AH39: 100 | AI39: CriRatio | AJ39: 5000 | AK39: CriDmgRatio | AL39: 150000 | AM39: =INT(1&L39&TEXT(RIGHT(A39,3),"0000")&"01") -> 13022901 | AN39: TRUE | AO39: =INT(2&$L39&TEXT(RIGHT($A39,3),"0000")&"01") -> 23022901 | AP39: TRUE | AQ39: =INT(3&$L39&TEXT(RIGHT($A39,3),"0000")&"01") -> 33022901 | AR39: TRUE | AS39: =INT(4&$L39&TEXT(RIGHT($A39,3),"0000")&"01") -> 43022901 | AT39: TRUE
A40: 10000033 | B40: 다이아나 | C40: 103301 | D40: c033 | E40: character_name_10000033 | F40: =D40&"_profile" -> c033_profile | G40: None | H40: Normal | I40: 0.95,0.95,0.95 | J40: TRUE | K40: 0,0,0 | L40: 1 | M40: Forest | N40: Magician | O40: =100+L40 -> 101 | P40: 4 | Q40: 4 | R40: 1 | S40: 0 | T40: 0 | U40: Spd | V40: 120 | W40: Hp | X40: 5909 | Y40: Atk | Z40: 198 | AA40: Def | AB40: 142 | AC40: Penetration | AD40: 142 | AE40: Hit | AF40: 100 | AG40: Dodge | AH40: 100 | AI40: CriRatio | AJ40: 5000 | AK40: CriDmgRatio | AL40: 150000 | AM40: =INT(1&L40&TEXT(RIGHT(A40,3),"0000")&"01") -> 11003301 | AN40: TRUE | AO40: =INT(2&$L40&TEXT(RIGHT($A40,3),"0000")&"01") -> 21003301 | AP40: TRUE | AQ40: =INT(3&$L40&TEXT(RIGHT($A40,3),"0000")&"01") -> 31003301 | AR40: TRUE | AS40: =INT(4&$L40&TEXT(RIGHT($A40,3),"0000")&"01") -> 41003301 | AT40: TRUE
A41: 10000336 | B41: 판 | C41: 133601 | D41: c336 | E41: ="character_name_"&A41 -> character_name_10000336 | F41: =D41&"_profile" -> c336_profile | G41: None | H41: Normal | I41: 0.95,0.95,0.95 | J41: TRUE | K41: 0,0,0 | L41: 3 | M41: Forest | N41: Magician | O41: =100+L41 -> 103 | P41: 4 | Q41: 4 | R41: 1 | S41: 0 | T41: 0 | U41: Spd | V41: {=_xlfn.IFS(N41="Attacker",80,N41="Healer",90,N41="Magician",100,N41="Defender",110,N41="Supporter",120)} -> 100 | W41: Hp | X41: 4743 | Y41: Atk | Z41: 341 | AA41: Def | AB41: 108 | AC41: Penetration | AD41: 156 | AE41: Hit | AF41: 100 | AG41: Dodge | AH41: 100 | AI41: CriRatio | AJ41: 5000 | AK41: CriDmgRatio | AL41: 150000 | AM41: =INT(1&L41&TEXT(RIGHT(A41,3),"0000")&"01") -> 13033601 | AN41: TRUE | AO41: =INT(2&$L41&TEXT(RIGHT($A41,3),"0000")&"01") -> 23033601 | AP41: TRUE | AQ41: =INT(3&$L41&TEXT(RIGHT($A41,3),"0000")&"01") -> 33033601 | AR41: TRUE | AS41: =INT(4&$L41&TEXT(RIGHT($A41,3),"0000")&"01") -> 43033601 | AT41: TRUE
...

Sheet Detail<Monster>
A1: Id | B1: #이름 | C1: Skin | D1: #DefaultSoul | E1: Name | F1: Profile | G1: MonsterType | H1: Size | I1: #Difficuly | J1: Scale | K1: UseHud | L1: StatusOffset | M1: StarGrade | N1: Element | O1: Role | P1: LevelUpGroup | Q1: MaxSp | R1: UseSp | S1: TurnSp | T1: AtkSp | U1: HitSp | V1: StatParam | W1: StatValue | X1: StatParam | Y1: StatValue | Z1: StatParam | AA1: StatValue | AB1: StatParam | AC1: StatValue | AD1: StatParam | AE1: StatValue | AF1: StatParam | AG1: StatValue | AH1: StatParam | AI1: StatValue | AJ1: StatParam | AK1: StatValue | AL1: StatParam | AM1: StatValue | AN1: SkillId | AO1: DefaultCheck | AP1: SkillId | AQ1: DefaultCheck | AR1: SkillId | AS1: DefaultCheck | AT1: SkillId | AU1: DefaultCheck
G3: 몬스터 타입 | H3: 크기 | I3: 난이도 | M3: 등급 | N3: 속성 | O3: 직업 | AN3: Normal | AP3: Active | AR3: Ultimate | AT3: Passive
A4: 20130101 | B4: 봉제인형 | C4: 201301 | D4: 0 | E4: character_name_20130101 | G4: Normal | H4: Normal | I4: 1 | J4: 1,1,1 | K4: TRUE | L4: 0,0,0 | M4: 2 | N4: Fire | O4: Defender | P4: 200 | Q4: {=_xlfn.IFS($O4="Attacker",6,$O4="Healer",3,$O4="Magician",4,$O4="Defender",3,$O4="Supporter",4)} -> 3 | R4: {=_xlfn.IFS($O4="Attacker",6,$O4="Healer",3,$O4="Magician",4,$O4="Defender",3,$O4="Supporter",4)} -> 3 | S4: 1 | T4: 0 | U4: 0 | V4: Spd | W4: {=_xlfn.IFS(O4="Attacker",80,O4="Healer",90,O4="Magician",100,O4="Defender",110,O4="Supporter",120)} -> 110 | X4: Hp | Y4: 1000 | Z4: Atk | AA4: 500 | AB4: Def | AC4: 20 | AD4: Penetration | AE4: =AC4 -> 20 | AF4: Hit | AG4: 100 | AH4: Dodge | AI4: 80 | AJ4: CriRatio | AK4: 0 | AL4: CriDmgRatio | AM4: 150000 | AN4: 1842051 | AO4: TRUE | AP4: 2842051 | AQ4: TRUE | AR4: 0 | AS4: FALSE | AT4: 0 | AU4: FALSE
A5: 20130201 | B5: 봉제인형 | C5: 201302 | D5: 0 | E5: character_name_20130201 | G5: Normal | H5: Normal | I5: 1 | J5: 1,1,1 | K5: TRUE | L5: 0,0,0 | M5: 2 | N5: Fire | O5: Defender | P5: 200 | Q5: {=_xlfn.IFS($O5="Attacker",6,$O5="Healer",3,$O5="Magician",4,$O5="Defender",3,$O5="Supporter",4)} -> 3 | R5: {=_xlfn.IFS($O5="Attacker",6,$O5="Healer",3,$O5="Magician",4,$O5="Defender",3,$O5="Supporter",4)} -> 3 | S5: 1 | T5: 0 | U5: 0 | V5: Spd | W5: {=_xlfn.IFS(O5="Attacker",80,O5="Healer",90,O5="Magician",100,O5="Defender",110,O5="Supporter",120)} -> 110 | X5: Hp | Y5: 1000 | Z5: Atk | AA5: 500 | AB5: Def | AC5: 20 | AD5: Penetration | AE5: =AC5 -> 20 | AF5: Hit | AG5: 100 | AH5: Dodge | AI5: 80 | AJ5: CriRatio | AK5: 0 | AL5: CriDmgRatio | AM5: 150000 | AN5: 1842051 | AO5: TRUE | AP5: 2842051 | AQ5: TRUE | AR5: 0 | AS5: FALSE | AT5: 0 | AU5: FALSE
A6: 20130102 | B6: 봉제인형 | C6: 201301 | D6: 0 | E6: character_name_20130102 | G6: Normal | H6: Normal | I6: 2 | J6: 1,1,1 | K6: TRUE | L6: 0,0,0 | M6: 2 | N6: Fire | O6: Defender | P6: 200 | Q6: {=_xlfn.IFS($O6="Attacker",6,$O6="Healer",3,$O6="Magician",4,$O6="Defender",3,$O6="Supporter",4)} -> 3 | R6: {=_xlfn.IFS($O6="Attacker",6,$O6="Healer",3,$O6="Magician",4,$O6="Defender",3,$O6="Supporter",4)} -> 3 | S6: 1 | T6: 0 | U6: 0 | V6: Spd | W6: {=_xlfn.IFS(O6="Attacker",80,O6="Healer",90,O6="Magician",100,O6="Defender",110,O6="Supporter",120)} -> 110 | X6: Hp | Y6: 1000 | Z6: Atk | AA6: 500 | AB6: Def | AC6: 20 | AD6: Penetration | AE6: =AC6 -> 20 | AF6: Hit | AG6: 100 | AH6: Dodge | AI6: 80 | AJ6: CriRatio | AK6: 0 | AL6: CriDmgRatio | AM6: 150000 | AN6: 1842051 | AO6: TRUE | AP6: 2842051 | AQ6: TRUE | AR6: 0 | AS6: FALSE | AT6: 0 | AU6: FALSE
A7: 20130202 | B7: 봉제인형 | C7: 201302 | D7: 0 | E7: character_name_20130202 | G7: Normal | H7: Normal | I7: 2 | J7: 1,1,1 | K7: TRUE | L7: 0,0,0 | M7: 2 | N7: Fire | O7: Defender | P7: 200 | Q7: {=_xlfn.IFS($O7="Attacker",6,$O7="Healer",3,$O7="Magician",4,$O7="Defender",3,$O7="Supporter",4)} -> 3 | R7: {=_xlfn.IFS($O7="Attacker",6,$O7="Healer",3,$O7="Magician",4,$O7="Defender",3,$O7="Supporter",4)} -> 3 | S7: 1 | T7: 0 | U7: 0 | V7: Spd | W7: {=_xlfn.IFS(O7="Attacker",80,O7="Healer",90,O7="Magician",100,O7="Defender",110,O7="Supporter",120)} -> 110 | X7: Hp | Y7: 1000 | Z7: Atk | AA7: 500 | AB7: Def | AC7: 20 | AD7: Penetration | AE7: =AC7 -> 20 | AF7: Hit | AG7: 100 | AH7: Dodge | AI7: 80 | AJ7: CriRatio | AK7: 0 | AL7: CriDmgRatio | AM7: 150000 | AN7: 1842051 | AO7: TRUE | AP7: 2842051 | AQ7: TRUE | AR7: 0 | AS7: FALSE | AT7: 0 | AU7: FALSE
A8: 20730101 | B8: 큐브-화 | C8: 207301 | D8: 0 | E8: character_name_20730101 | G8: Normal | H8: Normal | I8: 1 | J8: 1,1,1 | K8: TRUE | L8: 0,0,0 | M8: 2 | N8: Fire | O8: Defender | P8: 200 | Q8: {=_xlfn.IFS($O8="Attacker",6,$O8="Healer",3,$O8="Magician",4,$O8="Defender",3,$O8="Supporter",4)} -> 3 | R8: {=_xlfn.IFS($O8="Attacker",6,$O8="Healer",3,$O8="Magician",4,$O8="Defender",3,$O8="Supporter",4)} -> 3 | S8: 1 | T8: 0 | U8: 0 | V8: Spd | W8: {=_xlfn.IFS(O8="Attacker",80,O8="Healer",90,O8="Magician",100,O8="Defender",110,O8="Supporter",120)} -> 110 | X8: Hp | Y8: 300 | Z8: Atk | AA8: 200 | AB8: Def | AC8: 0 | AD8: Penetration | AE8: 0 | AF8: Hit | AG8: 100 | AH8: Dodge | AI8: 100 | AJ8: CriRatio | AK8: 5000 | AL8: CriDmgRatio | AM8: 150000 | AN8: 1811041 | AO8: TRUE | AP8: 2811041 | AQ8: TRUE | AR8: 0 | AS8: FALSE | AT8: 0 | AU8: FALSE
A9: 20730201 | B9: 큐브-수 | C9: 207302 | D9: 0 | E9: character_name_20730201 | G9: Normal | H9: Normal | I9: 1 | J9: 1,1,1 | K9: TRUE | L9: 0,0,0 | M9: 2 | N9: Water | O9: Defender | P9: 200 | Q9: {=_xlfn.IFS($O9="Attacker",6,$O9="Healer",3,$O9="Magician",4,$O9="Defender",3,$O9="Supporter",4)} -> 3 | R9: {=_xlfn.IFS($O9="Attacker",6,$O9="Healer",3,$O9="Magician",4,$O9="Defender",3,$O9="Supporter",4)} -> 3 | S9: 1 | T9: 0 | U9: 0 | V9: Spd | W9: {=_xlfn.IFS(O9="Attacker",80,O9="Healer",90,O9="Magician",100,O9="Defender",110,O9="Supporter",120)} -> 110 | X9: Hp | Y9: 300 | Z9: Atk | AA9: 200 | AB9: Def | AC9: 0 | AD9: Penetration | AE9: 0 | AF9: Hit | AG9: 120 | AH9: Dodge | AI9: 100 | AJ9: CriRatio | AK9: 5000 | AL9: CriDmgRatio | AM9: 150000 | AN9: 1821041 | AO9: TRUE | AP9: 2821041 | AQ9: TRUE | AR9: 0 | AS9: FALSE | AT9: 0 | AU9: FALSE
A10: 20730301 | B10: 큐브-목 | C10: 207303 | D10: 0 | E10: character_name_20730301 | G10: Normal | H10: Normal | I10: 1 | J10: 1,1,1 | K10: TRUE | L10: 0,0,0 | M10: 2 | N10: Forest | O10: Defender | P10: 200 | Q10: {=_xlfn.IFS($O10="Attacker",6,$O10="Healer",3,$O10="Magician",4,$O10="Defender",3,$O10="Supporter",4)} -> 3 | R10: {=_xlfn.IFS($O10="Attacker",6,$O10="Healer",3,$O10="Magician",4,$O10="Defender",3,$O10="Supporter",4)} -> 3 | S10: 1 | T10: 0 | U10: 0 | V10: Spd | W10: {=_xlfn.IFS(O10="Attacker",80,O10="Healer",90,O10="Magician",100,O10="Defender",110,O10="Supporter",120)} -> 110 | X10: Hp | Y10: 300 | Z10: Atk | AA10: 200 | AB10: Def | AC10: 0 | AD10: Penetration | AE10: 0 | AF10: Hit | AG10: 100 | AH10: Dodge | AI10: 100 | AJ10: CriRatio | AK10: 5000 | AL10: CriDmgRatio | AM10: 150000 | AN10: 1831041 | AO10: TRUE | AP10: 2831041 | AQ10: TRUE | AR10: 0 | AS10: FALSE | AT10: 0 | AU10: FALSE
A11: 20730401 | B11: 큐브-광 | C11: 207304 | D11: 0 | E11: character_name_20730401 | G11: Normal | H11: Normal | I11: 1 | J11: 1,1,1 | K11: TRUE | L11: 0,0,0 | M11: 2 | N11: Light | O11: Defender | P11: 200 | Q11: {=_xlfn.IFS($O11="Attacker",6,$O11="Healer",3,$O11="Magician",4,$O11="Defender",3,$O11="Supporter",4)} -> 3 | R11: {=_xlfn.IFS($O11="Attacker",6,$O11="Healer",3,$O11="Magician",4,$O11="Defender",3,$O11="Supporter",4)} -> 3 | S11: 1 | T11: 0 | U11: 0 | V11: Spd | W11: {=_xlfn.IFS(O11="Attacker",80,O11="Healer",90,O11="Magician",100,O11="Defender",110,O11="Supporter",120)} -> 110 | X11: Hp | Y11: 300 | Z11: Atk | AA11: 200 | AB11: Def | AC11: 0 | AD11: Penetration | AE11: 0 | AF11: Hit | AG11: 100 | AH11: Dodge | AI11: 100 | AJ11: CriRatio | AK11: 5000 | AL11: CriDmgRatio | AM11: 150000 | AN11: 1841041 | AO11: TRUE | AP11: 2841041 | AQ11: TRUE | AR11: 0 | AS11: FALSE | AT11: 0 | AU11: FALSE
A12: 20730501 | B12: 큐브-암 | C12: 207305 | D12: 0 | E12: character_name_20730501 | G12: Normal | H12: Normal | I12: 1 | J12: 1,1,1 | K12: TRUE | L12: 0,0,0 | M12: 2 | N12: Dark | O12: Defender | P12: 200 | Q12: {=_xlfn.IFS($O12="Attacker",6,$O12="Healer",3,$O12="Magician",4,$O12="Defender",3,$O12="Supporter",4)} -> 3 | R12: {=_xlfn.IFS($O12="Attacker",6,$O12="Healer",3,$O12="Magician",4,$O12="Defender",3,$O12="Supporter",4)} -> 3 | S12: 1 | T12: 0 | U12: 0 | V12: Spd | W12: {=_xlfn.IFS(O12="Attacker",80,O12="Healer",90,O12="Magician",100,O12="Defender",110,O12="Supporter",120)} -> 110 | X12: Hp | Y12: 300 | Z12: Atk | AA12: 200 | AB12: Def | AC12: 0 | AD12: Penetration | AE12: 0 | AF12: Hit | AG12: 100 | AH12: Dodge | AI12: 100 | AJ12: CriRatio | AK12: 5000 | AL12: CriDmgRatio | AM12: 150000 | AN12: 1851041 | AO12: TRUE | AP12: 2851041 | AQ12: TRUE | AR12: 0 | AS12: FALSE | AT12: 0 | AU12: FALSE
A13: 20730102 | B13: 큐브-화 | C13: 207301 | D13: 0 | E13: character_name_20730102 | G13: Normal | H13: Normal | I13: 2 | J13: 1,1,1 | K13: TRUE | L13: 0,0,0 | M13: 2 | N13: Fire | O13: Defender | P13: 200 | Q13: {=_xlfn.IFS($O13="Attacker",6,$O13="Healer",3,$O13="Magician",4,$O13="Defender",3,$O13="Supporter",4)} -> 3 | R13: {=_xlfn.IFS($O13="Attacker",6,$O13="Healer",3,$O13="Magician",4,$O13="Defender",3,$O13="Supporter",4)} -> 3 | S13: 1 | T13: 0 | U13: 0 | V13: Spd | W13: {=_xlfn.IFS(O13="Attacker",80,O13="Healer",90,O13="Magician",100,O13="Defender",110,O13="Supporter",120)} -> 110 | X13: Hp | Y13: 300 | Z13: Atk | AA13: 200 | AB13: Def | AC13: 20 | AD13: Penetration | AE13: 0 | AF13: Hit | AG13: 100 | AH13: Dodge | AI13: 100 | AJ13: CriRatio | AK13: 5000 | AL13: CriDmgRatio | AM13: 150000 | AN13: 1811041 | AO13: TRUE | AP13: 2811041 | AQ13: TRUE | AR13: 0 | AS13: FALSE | AT13: 0 | AU13: FALSE
A14: 20730202 | B14: 큐브-수 | C14: 207302 | D14: 0 | E14: character_name_20730202 | G14: Normal | H14: Normal | I14: 2 | J14: 1,1,1 | K14: TRUE | L14: 0,0,0 | M14: 2 | N14: Water | O14: Defender | P14: 200 | Q14: {=_xlfn.IFS($O14="Attacker",6,$O14="Healer",3,$O14="Magician",4,$O14="Defender",3,$O14="Supporter",4)} -> 3 | R14: {=_xlfn.IFS($O14="Attacker",6,$O14="Healer",3,$O14="Magician",4,$O14="Defender",3,$O14="Supporter",4)} -> 3 | S14: 1 | T14: 0 | U14: 0 | V14: Spd | W14: {=_xlfn.IFS(O14="Attacker",80,O14="Healer",90,O14="Magician",100,O14="Defender",110,O14="Supporter",120)} -> 110 | X14: Hp | Y14: 300 | Z14: Atk | AA14: 200 | AB14: Def | AC14: 20 | AD14: Penetration | AE14: 0 | AF14: Hit | AG14: 100 | AH14: Dodge | AI14: 100 | AJ14: CriRatio | AK14: 5000 | AL14: CriDmgRatio | AM14: 150000 | AN14: 1821041 | AO14: TRUE | AP14: 2821041 | AQ14: TRUE | AR14: 0 | AS14: FALSE | AT14: 0 | AU14: FALSE
A15: 20730302 | B15: 큐브-목 | C15: 207303 | D15: 0 | E15: character_name_20730302 | G15: Normal | H15: Normal | I15: 2 | J15: 1,1,1 | K15: TRUE | L15: 0,0,0 | M15: 2 | N15: Forest | O15: Defender | P15: 200 | Q15: {=_xlfn.IFS($O15="Attacker",6,$O15="Healer",3,$O15="Magician",4,$O15="Defender",3,$O15="Supporter",4)} -> 3 | R15: {=_xlfn.IFS($O15="Attacker",6,$O15="Healer",3,$O15="Magician",4,$O15="Defender",3,$O15="Supporter",4)} -> 3 | S15: 1 | T15: 0 | U15: 0 | V15: Spd | W15: {=_xlfn.IFS(O15="Attacker",80,O15="Healer",90,O15="Magician",100,O15="Defender",110,O15="Supporter",120)} -> 110 | X15: Hp | Y15: 300 | Z15: Atk | AA15: 200 | AB15: Def | AC15: 20 | AD15: Penetration | AE15: 0 | AF15: Hit | AG15: 100 | AH15: Dodge | AI15: 100 | AJ15: CriRatio | AK15: 5000 | AL15: CriDmgRatio | AM15: 150000 | AN15: 1831041 | AO15: TRUE | AP15: 2831041 | AQ15: TRUE | AR15: 0 | AS15: FALSE | AT15: 0 | AU15: FALSE
A16: 20730402 | B16: 큐브-광 | C16: 207304 | D16: 0 | E16: character_name_20730402 | G16: Normal | H16: Normal | I16: 2 | J16: 1,1,1 | K16: TRUE | L16: 0,0,0 | M16: 2 | N16: Light | O16: Defender | P16: 200 | Q16: {=_xlfn.IFS($O16="Attacker",6,$O16="Healer",3,$O16="Magician",4,$O16="Defender",3,$O16="Supporter",4)} -> 3 | R16: {=_xlfn.IFS($O16="Attacker",6,$O16="Healer",3,$O16="Magician",4,$O16="Defender",3,$O16="Supporter",4)} -> 3 | S16: 1 | T16: 0 | U16: 0 | V16: Spd | W16: {=_xlfn.IFS(O16="Attacker",80,O16="Healer",90,O16="Magician",100,O16="Defender",110,O16="Supporter",120)} -> 110 | X16: Hp | Y16: 300 | Z16: Atk | AA16: 200 | AB16: Def | AC16: 20 | AD16: Penetration | AE16: 0 | AF16: Hit | AG16: 100 | AH16: Dodge | AI16: 100 | AJ16: CriRatio | AK16: 5000 | AL16: CriDmgRatio | AM16: 150000 | AN16: 1841041 | AO16: TRUE | AP16: 2841041 | AQ16: TRUE | AR16: 0 | AS16: FALSE | AT16: 0 | AU16: FALSE
A17: 20730502 | B17: 큐브-암 | C17: 207305 | D17: 0 | E17: character_name_20730502 | G17: Normal | H17: Normal | I17: 2 | J17: 1,1,1 | K17: TRUE | L17: 0,0,0 | M17: 2 | N17: Dark | O17: Defender | P17: 200 | Q17: {=_xlfn.IFS($O17="Attacker",6,$O17="Healer",3,$O17="Magician",4,$O17="Defender",3,$O17="Supporter",4)} -> 3 | R17: {=_xlfn.IFS($O17="Attacker",6,$O17="Healer",3,$O17="Magician",4,$O17="Defender",3,$O17="Supporter",4)} -> 3 | S17: 1 | T17: 0 | U17: 0 | V17: Spd | W17: {=_xlfn.IFS(O17="Attacker",80,O17="Healer",90,O17="Magician",100,O17="Defender",110,O17="Supporter",120)} -> 110 | X17: Hp | Y17: 300 | Z17: Atk | AA17: 200 | AB17: Def | AC17: 20 | AD17: Penetration | AE17: 0 | AF17: Hit | AG17: 100 | AH17: Dodge | AI17: 100 | AJ17: CriRatio | AK17: 5000 | AL17: CriDmgRatio | AM17: 150000 | AN17: 1851041 | AO17: TRUE | AP17: 2851041 | AQ17: TRUE | AR17: 0 | AS17: FALSE | AT17: 0 | AU17: FALSE
A18: 20730103 | B18: 큐브-화 | C18: 207301 | D18: 0 | E18: character_name_20730103 | G18: Normal | H18: Normal | I18: 3 | J18: 1,1,1 | K18: TRUE | L18: 0,0,0 | M18: 2 | N18: Fire | O18: Defender | P18: 200 | Q18: {=_xlfn.IFS($O18="Attacker",6,$O18="Healer",3,$O18="Magician",4,$O18="Defender",3,$O18="Supporter",4)} -> 3 | R18: {=_xlfn.IFS($O18="Attacker",6,$O18="Healer",3,$O18="Magician",4,$O18="Defender",3,$O18="Supporter",4)} -> 3 | S18: 1 | T18: 0 | U18: 0 | V18: Spd | W18: {=_xlfn.IFS(O18="Attacker",80,O18="Healer",90,O18="Magician",100,O18="Defender",110,O18="Supporter",120)} -> 110 | X18: Hp | Y18: 36000 | Z18: Atk | AA18: 450 | AB18: Def | AC18: 0 | AD18: Penetration | AE18: 0 | AF18: Hit | AG18: 100 | AH18: Dodge | AI18: 80 | AJ18: CriRatio | AK18: 0 | AL18: CriDmgRatio | AM18: 150000 | AN18: 1811041 | AO18: TRUE | AP18: 2811041 | AQ18: TRUE | AR18: 0 | AS18: FALSE | AT18: 0 | AU18: FALSE
A19: 20730203 | B19: 큐브-수 | C19: 207302 | D19: 0 | E19: character_name_20730203 | G19: Normal | H19: Normal | I19: 3 | J19: 1,1,1 | K19: TRUE | L19: 0,0,0 | M19: 2 | N19: Water | O19: Defender | P19: 200 | Q19: {=_xlfn.IFS($O19="Attacker",6,$O19="Healer",3,$O19="Magician",4,$O19="Defender",3,$O19="Supporter",4)} -> 3 | R19: {=_xlfn.IFS($O19="Attacker",6,$O19="Healer",3,$O19="Magician",4,$O19="Defender",3,$O19="Supporter",4)} -> 3 | S19: 1 | T19: 0 | U19: 0 | V19: Spd | W19: {=_xlfn.IFS(O19="Attacker",80,O19="Healer",90,O19="Magician",100,O19="Defender",110,O19="Supporter",120)} -> 110 | X19: Hp | Y19: 36000 | Z19: Atk | AA19: 450 | AB19: Def | AC19: 0 | AD19: Penetration | AE19: 0 | AF19: Hit | AG19: 120 | AH19: Dodge | AI19: 80 | AJ19: CriRatio | AK19: 0 | AL19: CriDmgRatio | AM19: 150000 | AN19: 1821041 | AO19: TRUE | AP19: 2821041 | AQ19: TRUE | AR19: 0 | AS19: FALSE | AT19: 0 | AU19: FALSE
... A141: 11240102 | B141: 이브 | C141: 112411 | D141: 0 | E141: character_name_11240102 | G141: Normal | H141: Normal | I141: 2 | J141: 0.95,0.95,0.95 | K141: TRUE | L141: 0,0,0 | M141: 3 | N141: Water | O141: Attacker | P141: 200 | Q141: {=_xlfn.IFS($O141="Attacker",6,$O141="Healer",3,$O141="Magician",4,$O141="Defender",3,$O141="Supporter",4)} -> 6 | R141: {=_xlfn.IFS($O141="Attacker",6,$O141="Healer",3,$O141="Magician",4,$O141="Defender",3,$O141="Supporter",4)} -> 6 | S141: 1 | T141: 0 | U141: 0 | V141: Spd | W141: {=_xlfn.IFS(O141="Attacker",80,O141="Healer",90,O141="Magician",100,O141="Defender",110,O141="Supporter",120)} -> 80 | X141: Hp | Y141: 2142 | Z141: Atk | AA141: 221 | AB141: Def | AC141: 156 | AD141: Penetration | AE141: 156 | AF141: Hit | AG141: 100 | AH141: Dodge | AI141: 80 | AJ141: CriRatio | AK141: 5000 | AL141: CriDmgRatio | AM141: 150000 | AN141: 1321241 | AO141: TRUE | AP141: 2321241 | AQ141: TRUE | AR141: 3321241 | AS141: TRUE | AT141: 4321241 | AU141: TRUE
A142: 13360102 | B142: 판 | C142: 133611 | D142: 0 | E142: ="character_name_"&A142 -> character_name_13360102 | G142: Normal | H142: Normal | I142: 2 | J142: 0.95,0.95,0.95 | K142: TRUE | L142: 0,0,0 | M142: 3 | N142: Forest | O142: Supporter | P142: =100+M142 -> 103 | Q142: {=_xlfn.IFS($O142="Attacker",6,$O142="Healer",3,$O142="Magician",4,$O142="Defender",3,$O142="Supporter",4)} -> 4 | R142: {=_xlfn.IFS($O142="Attacker",6,$O142="Healer",3,$O142="Magician",4,$O142="Defender",3,$O142="Supporter",4)} -> 4 | S142: 1 | T142: 0 | U142: 0 | V142: Spd | W142: {=_xlfn.IFS(O142="Attacker",80,O142="Healer",90,O142="Magician",100,O142="Defender",110,O142="Supporter",120)} -> 120 | X142: Hp | Y142: =ROUND($Y$16*0.9, 0) -> 270 | Z142: Atk | AA142: 221 | AB142: Def | AC142: 156 | AD142: Penetration | AE142: =AC142 -> 156 | AF142: Hit | AG142: 100 | AH142: Dodge | AI142: 100 | AJ142: CriRatio | AK142: 5000 | AL142: CriDmgRatio | AM142: 150000 | AN142: 1535261 | AO142: TRUE | AP142: 2535261 | AQ142: TRUE | AR142: 3535261 | AS142: TRUE | AT142: 4535261 | AU142: TRUE
A143: 14450102 | B143: 카라라트리 | C143: 144511 | D143: 0 | E143: ="character_name_"&A143 -> character_name_14450102 | G143: Normal | H143: Normal | I143: 2 | J143: 0.95,0.95,0.95 | K143: TRUE | L143: 0,0,0 | M143: 3 | N143: Fire | O143: Attacker | P143: =100+M143 -> 103 | Q143: {=_xlfn.IFS($O143="Attacker",6,$O143="Healer",3,$O143="Magician",4,$O143="Defender",3,$O143="Supporter",4)} -> 6 | R143: {=_xlfn.IFS($O143="Attacker",6,$O143="Healer",3,$O143="Magician",4,$O143="Defender",3,$O143="Supporter",4)} -> 6 | S143: 1 | T143: 0 | U143: 0 | V143: Spd | W143: {=_xlfn.IFS(O143="Attacker",80,O143="Healer",90,O143="Magician",100,O143="Defender",110,O143="Supporter",120)} -> 80 | X143: Hp | Y143: =ROUND($Y$16*0.9, 0) -> 270 | Z143: Atk | AA143: 221 | AB143: Def | AC143: 156 | AD143: Penetration | AE143: =AC143 -> 156 | AF143: Hit | AG143: 100 | AH143: Dodge | AI143: 100 | AJ143: CriRatio | AK143: 5000 | AL143: CriDmgRatio | AM143: 150000 | AN143: 1513271 | AO143: TRUE | AP143: 2513271 | AQ143: TRUE | AR143: 3513271 | AS143: TRUE | AT143: 4513271 | AU143: TRUE
A144: 14610102 | B144: 아우로라 | C144: 146111 | D144: 0 | E144: ="character_name_"&A144 -> character_name_14610102 | G144: Normal | H144: Normal | I144: 2 | J144: 0.95,0.95,0.95 | K144: TRUE | L144: 0,0,0 | M144: 3 | N144: Forest | O144: Supporter | P144: =100+M144 -> 103 | Q144: {=_xlfn.IFS($O144="Attacker",6,$O144="Healer",3,$O144="Magician",4,$O144="Defender",3,$O144="Supporter",4)} -> 4 | R144: {=_xlfn.IFS($O144="Attacker",6,$O144="Healer",3,$O144="Magician",4,$O144="Defender",3,$O144="Supporter",4)} -> 4 | S144: 1 | T144: 0 | U144: 0 | V144: Spd | W144: {=_xlfn.IFS(O144="Attacker",80,O144="Healer",90,O144="Magician",100,O144="Defender",110,O144="Supporter",120)} -> 120 | X144: Hp | Y144: =ROUND($Y$16*0.9, 0) -> 270 | Z144: Atk | AA144: 221 | AB144: Def | AC144: 156 | AD144: Penetration | AE144: =AC144 -> 156 | AF144: Hit | AG144: 100 | AH144: Dodge | AI144: 100 | AJ144: CriRatio | AK144: 5000 | AL144: CriDmgRatio | AM144: 150000 | AN144: 1534281 | AO144: TRUE | AP144: 2534281 | AQ144: TRUE | AR144: 3534281 | AS144: TRUE | AT144: 4534281 | AU144: TRUE
