Workbook

Sheet #summury
A2: Base 테이블
A3: DATA | B3: Type | C3: Desc
A4: Id | B4: int | C4: id
A5: Name | B5: string | C5: 이름
C6: - Localization 테이블의 키 값을 입력한다.
A7: Spine | B7: string | C7: 스파인 리소스 파일명.
C8: - 스파인 리소스는 Front와 Back 2개의 세트로 구성된다.
C9: - 스파인 리소스 파일명 규칙 확정 필요. (ex. Spine_Eve_Front)
A10: Illust | B10: string | C10: 일러스트 리소스 파일명.
A11: Icon | B11: string | C11: 캐릭터 아이콘 파일명
A15: Child 테이블
A16: DATA | B16: Type | C16: Desc
A17: Id | B17: int | C17: id
A18: BaseId | B18: int | C18: 사용할 캐릭터의 Base 테이블의 id를 입력한다.
A19: Name | B19: string | C19: 이름
C20: - Localization 테이블의 키 값을 입력한다.
A21: Grade | B21: Enum.Grade | C21: 캐릭터의 등급을 지정한다.
C22: 0: NONE
C23: 1: 1성
C24: 2: 2성
C25: 3: 3성
A26: Element | B26: Enum.Element | C26: 캐릭터의 속성을 지정한다.
C27: 0: NONE
C28: 1: 수속성
C29: 2: 화속성
C30: 3: 목속성
C31: 4: 광속성
C32: 5: 암속성
A33: Role | B33: Enum.Role | C33: 캐릭터의 직업을 지정한다.
C34: 0: NONE
C35: 1: 공격형
C36: 2: 방어형
C37: 3: 마법형
C38: 4: 보조형
A39: StatParam | B39: Enum.StatParam | C39: 스탯 종류
C40: - 스탯 종류를 설정한다.
A41: StatValue | B41: int | C41: 스탯 초기 값
C42: - 캐릭터의 1레벨의 성장되지 않은 초기 값이다.
C43: - 확장 가능
A44: SkillId | B44: int | C44: 스킬 id
...

Sheet Detail<Child>
A1: Id | B1: #이름 | C1: Skin | D1: #DefaultSoul | E1: Name | F1: Profile | G1: MonsterType | H1: Size | I1: Scale | J1: UseHud | K1: StatusOffset | L1: StarGrade | M1: Element | N1: Role | O1: LevelUpGroup | P1: MaxSp | Q1: UseSp | R1: TurnSp | S1: AtkSp | T1: HitSp | U1: StatParam | V1: StatValue | W1: StatParam | X1: StatValue | Y1: StatParam | Z1: StatValue | AA1: StatParam | AB1: StatValue | AC1: StatParam | AD1: StatValue | AE1: StatParam | AF1: StatValue | AG1: StatParam | AH1: StatValue | AI1: StatParam | AJ1: StatValue | AK1: StatParam | AL1: StatValue | AM1: SkillId | AN1: DefaultCheck | AO1: SkillId | AP1: DefaultCheck | AQ1: SkillId | AR1: DefaultCheck | AS1: SkillId | AT1: DefaultCheck | AU1: #check | AV1: #check | AW1: #check | AX1: #check
G3: 몬스터 타입 | H3: 크기 | L3: 등급 | M3: 속성 | N3: 직업 | AM3: Normal | AO3: Active | AQ3: Ultimate | AS3: Passive
A4: 10000035 | B4: 페르세포네 | C4: 1003501 | D4: c035 | E4: character_name_10000035 | F4: =D4&"_profile" | G4: None | H4: Normal | I4: 0.95,0.95,0.95 | J4: TRUE | K4: 0,0,0 | L4: 1 | M4: Dark | N4: Supporter | O4: =100+L4 | P4: 4 | Q4: 4 | R4: 1 | S4: 0 | T4: 0 | U4: Spd | V4: 120 | W4: Hp | X4: 5909 | Y4: Atk | Z4: 198 | AA4: Def | AB4: 142 | AC4: Penetration | AD4: 142 | AE4: Hit | AF4: 100 | AG4: Dodge | AH4: 100 | AI4: CriRatio | AJ4: 5000 | AK4: CriDmgRatio | AL4: 150000 | AU4: =_xlfn.XLOOKUP(AM4,'[1]Skill<Child>'!$A:$A,'[1]Skill<Child>'!$A:$A) | AV4: =_xlfn.XLOOKUP(AO4,'[1]Skill<Child>'!$A:$A,'[1]Skill<Child>'!$A:$A) | AW4: =_xlfn.XLOOKUP(AQ4,'[1]Skill<Child>'!$A:$A,'[1]Skill<Child>'!$A:$A) | AX4: =_xlfn.XLOOKUP(AS4,'[1]Skill<Child>'!$A:$A,'[1]Skill<Child>'!$A:$A)
A5: 10000048 | B5: 네반 | C5: 1004801 | D5: c048 | E5: character_name_10000048 | F5: =D5&"_profile" | G5: None | H5: Normal | I5: 0.95,0.95,0.95 | J5: TRUE | K5: 0,0,0 | L5: 1 | M5: Dark | N5: Healer | O5: =100+L5 | P5: 3 | Q5: 3 | R5: 1 | S5: 0 | T5: 0 | U5: Spd | V5: 90 | W5: Hp | X5: 6475 | Y5: Atk | Z5: 168 | AA5: Def | AB5: 151 | AC5: Penetration | AD5: 151 | AE5: Hit | AF5: 100 | AG5: Dodge | AH5: 100 | AI5: CriRatio | AJ5: 5000 | AK5: CriDmgRatio | AL5: 150000 | AU5: =_xlfn.XLOOKUP(AM5,'[1]Skill<Child>'!$A:$A,'[1]Skill<Child>'!$A:$A) | AV5: =_xlfn.XLOOKUP(AO5,'[1]Skill<Child>'!$A:$A,'[1]Skill<Child>'!$A:$A) | AW5: =_xlfn.XLOOKUP(AQ5,'[1]Skill<Child>'!$A:$A,'[1]Skill<Child>'!$A:$A) | AX5: =_xlfn.XLOOKUP(AS5,'[1]Skill<Child>'!$A:$A,'[1]Skill<Child>'!$A:$A)
A6: 10000064 | B6: 메두사 | C6: 1006401 | D6: c064 | E6: character_name_10000064 | F6: =D6&"_profile" | G6: None | H6: Normal | I6: 0.95,0.95,0.95 | J6: TRUE | K6: 0,0,0 | L6: 1 | M6: Dark | N6: Attacker | O6: =100+L6 | P6: 6 | Q6: 6 | R6: 1 | S6: 0 | T6: 0 | U6: Spd | V6: 80 | W6: Hp | X6: 5100 | Y6: Atk | Z6: 420 | AA6: Def | AB6: 120 | AC6: Penetration | AD6: 120 | AE6: Hit | AF6: 100 | AG6: Dodge | AH6: 100 | AI6: CriRatio | AJ6: 5000 | AK6: CriDmgRatio | AL6: 150000 | AU6: =_xlfn.XLOOKUP(AM6,'[1]Skill<Child>'!$A:$A,'[1]Skill<Child>'!$A:$A) | AV6: =_xlfn.XLOOKUP(AO6,'[1]Skill<Child>'!$A:$A,'[1]Skill<Child>'!$A:$A) | AW6: =_xlfn.XLOOKUP(AQ6,'[1]Skill<Child>'!$A:$A,'[1]Skill<Child>'!$A:$A) | AX6: =_xlfn.XLOOKUP(AS6,'[1]Skill<Child>'!$A:$A,'[1]Skill<Child>'!$A:$A)
A7: 10000037 | B7: 유다 | C7: 1003701 | D7: c037 | E7: character_name_10000037 | F7: =D7&"_profile" | G7: None | H7: Normal | I7: 0.95,0.95,0.95 | J7: TRUE | K7: 0,0,0 | L7: 1 | M7: Fire | N7: Defender | O7: =100+L7 | P7: 3 | Q7: 3 | R7: 1 | S7: 0 | T7: 0 | U7: Spd | V7: 110 | W7: Hp | X7: 8650 | Y7: Atk | Z7: 252 | AA7: Def | AB7: 240 | AC7: Penetration | AD7: 240 | AE7: Hit | AF7: 100 | AG7: Dodge | AH7: 100 | AI7: CriRatio | AJ7: 5000 | AK7: CriDmgRatio | AL7: 150000 | AU7: =_xlfn.XLOOKUP(AM7,'[1]Skill<Child>'!$A:$A,'[1]Skill<Child>'!$A:$A) | AV7: =_xlfn.XLOOKUP(AO7,'[1]Skill<Child>'!$A:$A,'[1]Skill<Child>'!$A:$A) | AW7: =_xlfn.XLOOKUP(AQ7,'[1]Skill<Child>'!$A:$A,'[1]Skill<Child>'!$A:$A) | AX7: =_xlfn.XLOOKUP(AS7,'[1]Skill<Child>'!$A:$A,'[1]Skill<Child>'!$A:$A)
A8: 10000083 | B8: 네이드 | C8: 1008301 | D8: c083 | E8: character_name_10000083 | F8: =D8&"_profile" | G8: None | H8: Normal | I8: 0.95,0.95,0.95 | J8: TRUE | K8: 0,0,0 | L8: 1 | M8: Fire | N8: Attacker | O8: =100+L8 | P8: 6 | Q8: 6 | R8: 1 | S8: 0 | T8: 0 | U8: Spd | V8: 80 | W8: Hp | X8: 5100 | Y8: Atk | Z8: 420 | AA8: Def | AB8: 120 | AC8: Penetration | AD8: 120 | AE8: Hit | AF8: 100 | AG8: Dodge | AH8: 100 | AI8: CriRatio | AJ8: 5000 | AK8: CriDmgRatio | AL8: 150000 | AU8: =_xlfn.XLOOKUP(AM8,'[1]Skill<Child>'!$A:$A,'[1]Skill<Child>'!$A:$A) | AV8: =_xlfn.XLOOKUP(AO8,'[1]Skill<Child>'!$A:$A,'[1]Skill<Child>'!$A:$A) | AW8: =_xlfn.XLOOKUP(AQ8,'[1]Skill<Child>'!$A:$A,'[1]Skill<Child>'!$A:$A) | AX8: =_xlfn.XLOOKUP(AS8,'[1]Skill<Child>'!$A:$A,'[1]Skill<Child>'!$A:$A)
A9: 10000286 | B9: 베르들레 | C9: 1028601 | D9: c286 | E9: character_name_10000286 | F9: =D9&"_profile" | G9: None | H9: Normal | I9: 0.95,0.95,0.95 | J9: TRUE | K9: 0,0,0 | L9: 1 | M9: Fire | N9: Healer | O9: =100+L9 | P9: 3 | Q9: 3 | R9: 1 | S9: 0 | T9: 0 | U9: Spd | V9: 90 | W9: Hp | X9: 6475 | Y9: Atk | Z9: 168 | AA9: Def | AB9: 151 | AC9: Penetration | AD9: 151 | AE9: Hit | AF9: 100 | AG9: Dodge | AH9: 100 | AI9: CriRatio | AJ9: 5000 | AK9: CriDmgRatio | AL9: 150000 | AU9: =_xlfn.XLOOKUP(AM9,'[1]Skill<Child>'!$A:$A,'[1]Skill<Child>'!$A:$A) | AV9: =_xlfn.XLOOKUP(AO9,'[1]Skill<Child>'!$A:$A,'[1]Skill<Child>'!$A:$A) | AW9: =_xlfn.XLOOKUP(AQ9,'[1]Skill<Child>'!$A:$A,'[1]Skill<Child>'!$A:$A) | AX9: =_xlfn.XLOOKUP(AS9,'[1]Skill<Child>'!$A:$A,'[1]Skill<Child>'!$A:$A)
A10: 10000031 | B10: 프레이야 | C10: 1003101 | D10: c031 | E10: character_name_10000031 | F10: =D10&"_profile" | G10: None | H10: Normal | I10: 0.95,0.95,0.95 | J10: TRUE | K10: 0,0,0 | L10: 1 | M10: Forest | N10: Healer | O10: =100+L10 | P10: 3 | Q10: 3 | R10: 1 | S10: 0 | T10: 0 | U10: Spd | V10: 90 | W10: Hp | X10: 6475 | Y10: Atk | Z10: 168 | AA10: Def | AB10: 151 | AC10: Penetration | AD10: 151 | AE10: Hit | AF10: 100 | AG10: Dodge | AH10: 100 | AI10: CriRatio | AJ10: 5000 | AK10: CriDmgRatio | AL10: 150000 | AU10: =_xlfn.XLOOKUP(AM10,'[1]Skill<Child>'!$A:$A,'[1]Skill<Child>'!$A:$A) | AV10: =_xlfn.XLOOKUP(AO10,'[1]Skill<Child>'!$A:$A,'[1]Skill<Child>'!$A:$A) | AW10: =_xlfn.XLOOKUP(AQ10,'[1]Skill<Child>'!$A:$A,'[1]Skill<Child>'!$A:$A) | AX10: =_xlfn.XLOOKUP(AS10,'[1]Skill<Child>'!$A:$A,'[1]Skill<Child>'!$A:$A)
A11: 10000033 | B11: 다이아나 | C11: 1003301 | D11: c033 | E11: character_name_10000033 | F11: =D11&"_profile" | G11: None | H11: Normal | I11: 0.95,0.95,0.95 | J11: TRUE | K11: 0,0,0 | L11: 1 | M11: Forest | N11: Magician | O11: =100+L11 | P11: 4 | Q11: 4 | R11: 1 | S11: 0 | T11: 0 | U11: Spd | V11: 120 | W11: Hp | X11: 5909 | Y11: Atk | Z11: 198 | AA11: Def | AB11: 142 | AC11: Penetration | AD11: 142 | AE11: Hit | AF11: 100 | AG11: Dodge | AH11: 100 | AI11: CriRatio | AJ11: 5000 | AK11: CriDmgRatio | AL11: 150000 | AU11: =_xlfn.XLOOKUP(AM11,'[1]Skill<Child>'!$A:$A,'[1]Skill<Child>'!$A:$A) | AV11: =_xlfn.XLOOKUP(AO11,'[1]Skill<Child>'!$A:$A,'[1]Skill<Child>'!$A:$A) | AW11: =_xlfn.XLOOKUP(AQ11,'[1]Skill<Child>'!$A:$A,'[1]Skill<Child>'!$A:$A) | AX11: =_xlfn.XLOOKUP(AS11,'[1]Skill<Child>'!$A:$A,'[1]Skill<Child>'!$A:$A)
A12: 10000062 | B12: 에우로페 | C12: 1006201 | D12: c062 | E12: character_name_10000062 | F12: =D12&"_profile" | G12: None | H12: Normal | I12: 0.95,0.95,0.95 | J12: TRUE | K12: 0,0,0 | L12: 1 | M12: Forest | N12: Attacker | O12: =100+L12 | P12: 6 | Q12: 6 | R12: 1 | S12: 0 | T12: 0 | U12: Spd | V12: 80 | W12: Hp | X12: 5100 | Y12: Atk | Z12: 420 | AA12: Def | AB12: 120 | AC12: Penetration | AD12: 120 | AE12: Hit | AF12: 100 | AG12: Dodge | AH12: 100 | AI12: CriRatio | AJ12: 5000 | AK12: CriDmgRatio | AL12: 150000 | AU12: =_xlfn.XLOOKUP(AM12,'[1]Skill<Child>'!$A:$A,'[1]Skill<Child>'!$A:$A) | AV12: =_xlfn.XLOOKUP(AO12,'[1]Skill<Child>'!$A:$A,'[1]Skill<Child>'!$A:$A) | AW12: =_xlfn.XLOOKUP(AQ12,'[1]Skill<Child>'!$A:$A,'[1]Skill<Child>'!$A:$A) | AX12: =_xlfn.XLOOKUP(AS12,'[1]Skill<Child>'!$A:$A,'[1]Skill<Child>'!$A:$A)
A13: 10000028 | B13: 레다 | C13: 1002801 | D13: c028 | E13: character_name_10000028 | F13: =D13&"_profile" | G13: None | H13: Normal | I13: 0.95,0.95,0.95 | J13: TRUE | K13: 0,0,0 | L13: 1 | M13: Light | N13: Supporter | O13: =100+L13 | P13: 4 | Q13: 4 | R13: 1 | S13: 0 | T13: 0 | U13: Spd | V13: 120 | W13: Hp | X13: 5909 | Y13: Atk | Z13: 198 | AA13: Def | AB13: 142 | AC13: Penetration | AD13: 142 | AE13: Hit | AF13: 100 | AG13: Dodge | AH13: 100 | AI13: CriRatio | AJ13: 5000 | AK13: CriDmgRatio | AL13: 150000 | AU13: =_xlfn.XLOOKUP(AM13,'[1]Skill<Child>'!$A:$A,'[1]Skill<Child>'!$A:$A) | AV13: =_xlfn.XLOOKUP(AO13,'[1]Skill<Child>'!$A:$A,'[1]Skill<Child>'!$A:$A) | AW13: =_xlfn.XLOOKUP(AQ13,'[1]Skill<Child>'!$A:$A,'[1]Skill<Child>'!$A:$A) | AX13: =_xlfn.XLOOKUP(AS13,'[1]Skill<Child>'!$A:$A,'[1]Skill<Child>'!$A:$A)
A14: 10000221 | B14: 야나 | C14: 1022101 | D14: c221 | E14: character_name_10000221 | F14: =D14&"_profile" | G14: None | H14: Normal | I14: 0.95,0.95,0.95 | J14: TRUE | K14: 0,0,0 | L14: 1 | M14: Light | N14: Attacker | O14: =100+L14 | P14: 6 | Q14: 6 | R14: 1 | S14: 0 | T14: 0 | U14: Spd | V14: 80 | W14: Hp | X14: 5100 | Y14: Atk | Z14: 420 | AA14: Def | AB14: 120 | AC14: Penetration | AD14: 120 | AE14: Hit | AF14: 100 | AG14: Dodge | AH14: 100 | AI14: CriRatio | AJ14: 5000 | AK14: CriDmgRatio | AL14: 150000 | AU14: =_xlfn.XLOOKUP(AM14,'[1]Skill<Child>'!$A:$A,'[1]Skill<Child>'!$A:$A) | AV14: =_xlfn.XLOOKUP(AO14,'[1]Skill<Child>'!$A:$A,'[1]Skill<Child>'!$A:$A) | AW14: =_xlfn.XLOOKUP(AQ14,'[1]Skill<Child>'!$A:$A,'[1]Skill<Child>'!$A:$A) | AX14: =_xlfn.XLOOKUP(AS14,'[1]Skill<Child>'!$A:$A,'[1]Skill<Child>'!$A:$A)
A15: 10000353 | B15: 샤를 | C15: 135301 | D15: ="c"&MID(C15,2,3) | E15: ="character_name_"&A15 | F15: =D15&"_profile" | G15: None | H15: Normal | I15: 0.95,0.95,0.95 | J15: TRUE | K15: 0,0,0 | L15: 1 | M15: Light | N15: Defender | O15: =100+L15 | P15: {=_xlfn.IFS($N15="Attacker",6,$N15="Healer",3,$N15="Magician",4,$N15="Defender",3,$N15="Supporter",4)} | Q15: {=_xlfn.IFS($N15="Attacker",6,$N15="Healer",3,$N15="Magician",4,$N15="Defender",3,$N15="Supporter",4)} | R15: 1 | S15: 0 | T15: 0 | U15: Spd | V15: {=_xlfn.IFS(N15="Attacker",80,N15="Healer",90,N15="Magician",100,N15="Defender",110,N15="Supporter",120)} | W15: Hp | X15: 8650 | Y15: Atk | Z15: 252 | AA15: Def | AB15: 240 | AC15: Penetration | AD15: 195 | AE15: Hit | AF15: 100 | AG15: Dodge | AH15: 100 | AI15: CriRatio | AJ15: 5000 | AK15: CriDmgRatio | AL15: 150000 | AM15: 1542051 | AN15: TRUE | AO15: 2542051 | AP15: FALSE | AQ15: 3542051 | AR15: TRUE | AS15: 4542051 | AT15: FALSE | AU15: =_xlfn.XLOOKUP(AM15,'[1]Skill<Child>'!$A:$A,'[1]Skill<Child>'!$A:$A) | AV15: =_xlfn.XLOOKUP(AO15,'[1]Skill<Child>'!$A:$A,'[1]Skill<Child>'!$A:$A) | AW15: =_xlfn.XLOOKUP(AQ15,'[1]Skill<Child>'!$A:$A,'[1]Skill<Child>'!$A:$A) | AX15: =_xlfn.XLOOKUP(AS15,'[1]Skill<Child>'!$A:$A,'[1]Skill<Child>'!$A:$A)
A16: 10000022 | B16: 마야우엘 | C16: 1002201 | D16: c022 | E16: character_name_10000022 | F16: =D16&"_profile" | G16: None | H16: Normal | I16: 0.95,0.95,0.95 | J16: TRUE | K16: 0,0,0 | L16: 1 | M16: Water | N16: Magician | O16: =100+L16 | P16: 4 | Q16: 4 | R16: 1 | S16: 0 | T16: 0 | U16: Spd | V16: 120 | W16: Hp | X16: 5909 | Y16: Atk | Z16: 198 | AA16: Def | AB16: 142 | AC16: Penetration | AD16: 142 | AE16: Hit | AF16: 100 | AG16: Dodge | AH16: 100 | AI16: CriRatio | AJ16: 5000 | AK16: CriDmgRatio | AL16: 150000 | AU16: =_xlfn.XLOOKUP(AM16,'[1]Skill<Child>'!$A:$A,'[1]Skill<Child>'!$A:$A) | AV16: =_xlfn.XLOOKUP(AO16,'[1]Skill<Child>'!$A:$A,'[1]Skill<Child>'!$A:$A) | AW16: =_xlfn.XLOOKUP(AQ16,'[1]Skill<Child>'!$A:$A,'[1]Skill<Child>'!$A:$A) | AX16: =_xlfn.XLOOKUP(AS16,'[1]Skill<Child>'!$A:$A,'[1]Skill<Child>'!$A:$A)
A17: 10000362 | B17: 레오 | C17: 1036201 | D17: c362 | E17: character_name_10000362 | F17: =D17&"_profile" | G17: None | H17: Normal | I17: 0.95,0.95,0.95 | J17: TRUE | K17: 0,0,0 | L17: 1 | M17: Water | N17: Supporter | O17: =100+L17 | P17: 4 | Q17: 4 | R17: 1 | S17: 0 | T17: 0 | U17: Spd | V17: 120 | W17: Hp | X17: 5909 | Y17: Atk | Z17: 198 | AA17: Def | AB17: 142 | AC17: Penetration | AD17: 142 | AE17: Hit | AF17: 100 | AG17: Dodge | AH17: 100 | AI17: CriRatio | AJ17: 5000 | AK17: CriDmgRatio | AL17: 150000 | AU17: =_xlfn.XLOOKUP(AM17,'[1]Skill<Child>'!$A:$A,'[1]Skill<Child>'!$A:$A) | AV17: =_xlfn.XLOOKUP(AO17,'[1]Skill<Child>'!$A:$A,'[1]Skill<Child>'!$A:$A) | AW17: =_xlfn.XLOOKUP(AQ17,'[1]Skill<Child>'!$A:$A,'[1]Skill<Child>'!$A:$A) | AX17: =_xlfn.XLOOKUP(AS17,'[1]Skill<Child>'!$A:$A,'[1]Skill<Child>'!$A:$A)
A18: 10000366 | B18: 데이노 | C18: 1036601 | D18: c366 | E18: character_name_10000366 | F18: =D18&"_profile" | G18: None | H18: Normal | I18: 0.95,0.95,0.95 | J18: TRUE | K18: 0,0,0 | L18: 1 | M18: Water | N18: Defender | O18: =100+L18 | P18: 3 | Q18: 3 | R18: 1 | S18: 0 | T18: 0 | U18: Spd | V18: 110 | W18: Hp | X18: 8650 | Y18: Atk | Z18: 252 | AA18: Def | AB18: 240 | AC18: Penetration | AD18: 240 | AE18: Hit | AF18: 100 | AG18: Dodge | AH18: 100 | AI18: CriRatio | AJ18: 5000 | AK18: CriDmgRatio | AL18: 150000 | AU18: =_xlfn.XLOOKUP(AM18,'[1]Skill<Child>'!$A:$A,'[1]Skill<Child>'!$A:$A) | AV18: =_xlfn.XLOOKUP(AO18,'[1]Skill<Child>'!$A:$A,'[1]Skill<Child>'!$A:$A) | AW18: =_xlfn.XLOOKUP(AQ18,'[1]Skill<Child>'!$A:$A,'[1]Skill<Child>'!$A:$A) | AX18: =_xlfn.XLOOKUP(AS18,'[1]Skill<Child>'!$A:$A,'[1]Skill<Child>'!$A:$A)
A19: 10000001 | B19: 모나 | C19: 100101 | D19: ="c"&MID(C19,2,3) | E19: ="character_name_"&A19 | F19: =D19&"_profile" | G19: None | H19: Normal | I19: 0.95,0.95,0.95 | J19: TRUE | K19: 0,0,0 | L19: 2 | M19: Dark | N19: Defender | O19: =100+L19 | P19: 3 | Q19: 3 | R19: 1 | S19: 0 | T19: 0 | U19: Spd | V19: {=_xlfn.IFS(N19="Attacker",80,N19="Healer",90,N19="Magician",100,N19="Defender",110,N19="Supporter",120)} | W19: Hp | X19: 6475 | Y19: Atk | Z19: 168 | AA19: Def | AB19: 151 | AC19: Penetration | AD19: 163 | AE19: Hit | AF19: 100 | AG19: Dodge | AH19: 100 | AI19: CriRatio | AJ19: 5000 | AK19: CriDmgRatio | AL19: 150000 | AM19: 1552111 | AN19: TRUE | AO19: 2552111 | AP19: FALSE | AQ19: 3552111 | AR19: TRUE | AS19: 4552111 | AT19: FALSE | AU19: =_xlfn.XLOOKUP(AM19,'[1]Skill<Child>'!$A:$A,'[1]Skill<Child>'!$A:$A) | AV19: =_xlfn.XLOOKUP(AO19,'[1]Skill<Child>'!$A:$A,'[1]Skill<Child>'!$A:$A) | AW19: =_xlfn.XLOOKUP(AQ19,'[1]Skill<Child>'!$A:$A,'[1]Skill<Child>'!$A:$A) | AX19: =_xlfn.XLOOKUP(AS19,'[1]Skill<Child>'!$A:$A,'[1]Skill<Child>'!$A:$A)
A20: 10000514 | B20: 두엣샤 | C20: 151401 | D20: ="c"&MID(C20,2,3) | E20: ="character_name_"&A20 | F20: =D20&"_profile" | G20: None | H20: Normal | I20: 0.95,0.95,0.95 | J20: TRUE | K20: 0,0,0 | L20: 2 | M20: Dark | N20: Magician | O20: =100+L20 | P20: {=_xlfn.IFS($N20="Attacker",6,$N20="Healer",3,$N20="Magician",4,$N20="Defender",3,$N20="Supporter",4)} | Q20: {=_xlfn.IFS($N20="Attacker",6,$N20="Healer",3,$N20="Magician",4,$N20="Defender",3,$N20="Supporter",4)} | R20: 1 | S20: 0 | T20: 0 | U20: Spd | V20: {=_xlfn.IFS(N20="Attacker",80,N20="Healer",90,N20="Magician",100,N20="Defender",110,N20="Supporter",120)} | W20: Hp | X20: 5100 | Y20: Atk | Z20: 420 | AA20: Def | AB20: 120 | AC20: Penetration | AD20: 156 | AE20: Hit | AF20: 100 | AG20: Dodge | AH20: 100 | AI20: CriRatio | AJ20: 5000 | AK20: CriDmgRatio | AL20: 150000 | AM20: 1451341 | AN20: TRUE | AO20: 2451341 | AP20: TRUE | AQ20: 3451341 | AR20: TRUE | AS20: 4451341 | AT20: FALSE | AU20: =_xlfn.XLOOKUP(AM20,'[1]Skill<Child>'!$A:$A,'[1]Skill<Child>'!$A:$A) | AV20: =_xlfn.XLOOKUP(AO20,'[1]Skill<Child>'!$A:$A,'[1]Skill<Child>'!$A:$A) | AW20: =_xlfn.XLOOKUP(AQ20,'[1]Skill<Child>'!$A:$A,'[1]Skill<Child>'!$A:$A) | AX20: =_xlfn.XLOOKUP(AS20,'[1]Skill<Child>'!$A:$A,'[1]Skill<Child>'!$A:$A)
A21: 10000156 | B21: 에르제베트 | C21: 115601 | D21: ="c"&MID(C21,2,3) | E21: ="character_name_"&A21 | F21: =D21&"_profile" | G21: None | H21: Normal | I21: 0.95,0.95,0.95 | J21: TRUE | K21: 0,0,0 | L21: 2 | M21: Dark | N21: Attacker | O21: =100+L21 | P21: {=_xlfn.IFS($N21="Attacker",6,$N21="Healer",3,$N21="Magician",4,$N21="Defender",3,$N21="Supporter",4)} | Q21: {=_xlfn.IFS($N21="Attacker",6,$N21="Healer",3,$N21="Magician",4,$N21="Defender",3,$N21="Supporter",4)} | R21: 1 | S21: 0 | T21: 0 | U21: Spd | V21: {=_xlfn.IFS(N21="Attacker",80,N21="Healer",90,N21="Magician",100,N21="Defender",110,N21="Supporter",120)} | W21: Hp | X21: 5100 | Y21: Atk | Z21: 420 | AA21: Def | AB21: 120 | AC21: Penetration | AD21: 187 | AE21: Hit | AF21: 100 | AG21: Dodge | AH21: 100 | AI21: CriRatio | AJ21: 5000 | AK21: CriDmgRatio | AL21: 150000 | AM21: 1351191 | AN21: TRUE | AO21: 2351191 | AP21: TRUE | AQ21: 3351191 | AR21: TRUE | AS21: 4351191 | AT21: FALSE | AU21: =_xlfn.XLOOKUP(AM21,'[1]Skill<Child>'!$A:$A,'[1]Skill<Child>'!$A:$A) | AV21: =_xlfn.XLOOKUP(AO21,'[1]Skill<Child>'!$A:$A,'[1]Skill<Child>'!$A:$A) | AW21: =_xlfn.XLOOKUP(AQ21,'[1]Skill<Child>'!$A:$A,'[1]Skill<Child>'!$A:$A) | AX21: =_xlfn.XLOOKUP(AS21,'[1]Skill<Child>'!$A:$A,'[1]Skill<Child>'!$A:$A)
A22: 10000354 | B22: 드미테르 | C22: 135401 | D22: ="c"&MID(C22,2,3) | E22: ="character_name_"&A22 | F22: =D22&"_profile" | G22: None | H22: Normal | I22: 0.95,0.95,0.95 | J22: TRUE | K22: 0,0,0 | L22: 2 | M22: Fire | N22: Supporter | O22: =100+L22 | P22: {=_xlfn.IFS($N22="Attacker",6,$N22="Healer",3,$N22="Magician",4,$N22="Defender",3,$N22="Supporter",4)} | Q22: {=_xlfn.IFS($N22="Attacker",6,$N22="Healer",3,$N22="Magician",4,$N22="Defender",3,$N22="Supporter",4)} | R22: 1 | S22: 0 | T22: 0 | U22: Spd | V22: {=_xlfn.IFS(N22="Attacker",80,N22="Healer",90,N22="Magician",100,N22="Defender",110,N22="Supporter",120)} | W22: Hp | X22: 5100 | Y22: Atk | Z22: 420 | AA22: Def | AB22: 120 | AC22: Penetration | AD22: 130 | AE22: Hit | AF22: 100 | AG22: Dodge | AH22: 100 | AI22: CriRatio | AJ22: 5000 | AK22: CriDmgRatio | AL22: 150000 | AM22: 1513011 | AN22: TRUE | AO22: 2513011 | AP22: FALSE | AQ22: 3513011 | AR22: TRUE | AS22: 4513011 | AT22: FALSE | AU22: =_xlfn.XLOOKUP(AM22,'[1]Skill<Child>'!$A:$A,'[1]Skill<Child>'!$A:$A) | AV22: =_xlfn.XLOOKUP(AO22,'[1]Skill<Child>'!$A:$A,'[1]Skill<Child>'!$A:$A) | AW22: =_xlfn.XLOOKUP(AQ22,'[1]Skill<Child>'!$A:$A,'[1]Skill<Child>'!$A:$A) | AX22: =_xlfn.XLOOKUP(AS22,'[1]Skill<Child>'!$A:$A,'[1]Skill<Child>'!$A:$A)
A23: 10000003 | B23: 다비 | C23: 100301 | D23: ="c"&MID(C23,2,3) | E23: ="character_name_"&A23 | F23: =D23&"_profile" | G23: None | H23: Normal | I23: 0.95,0.95,0.95 | J23: TRUE | K23: 0,0,0 | L23: 2 | M23: Fire | N23: Magician | O23: =100+L23 | P23: 6 | Q23: 6 | R23: 1 | S23: 0 | T23: 0 | U23: Spd | V23: {=_xlfn.IFS(N23="Attacker",80,N23="Healer",90,N23="Magician",100,N23="Defender",110,N23="Supporter",120)} | W23: Hp | X23: 5100 | Y23: Atk | Z23: 420 | AA23: Def | AB23: 120 | AC23: Penetration | AD23: 130 | AE23: Hit | AF23: 100 | AG23: Dodge | AH23: 100 | AI23: CriRatio | AJ23: 5000 | AK23: CriDmgRatio | AL23: 150000 | AM23: 1511031 | AN23: TRUE | AO23: 2511031 | AP23: FALSE | AQ23: 3511031 | AR23: TRUE | AS23: 4511031 | AT23: FALSE | AU23: =_xlfn.XLOOKUP(AM23,'[1]Skill<Child>'!$A:$A,'[1]Skill<Child>'!$A:$A) | AV23: =_xlfn.XLOOKUP(AO23,'[1]Skill<Child>'!$A:$A,'[1]Skill<Child>'!$A:$A) | AW23: =_xlfn.XLOOKUP(AQ23,'[1]Skill<Child>'!$A:$A,'[1]Skill<Child>'!$A:$A) | AX23: =_xlfn.XLOOKUP(AS23,'[1]Skill<Child>'!$A:$A,'[1]Skill<Child>'!$A:$A)
A24: 10000412 | B24: 카인 | C24: 141201 | D24: ="c"&MID(C24,2,3) | E24: ="character_name_"&A24 | F24: =D24&"_profile" | G24: None | H24: Normal | I24: 0.95,0.95,0.95 | J24: TRUE | K24: 0,0,0 | L24: 2 | M24: Fire | N24: Attacker | O24: =100+L24 | P24: {=_xlfn.IFS($N24="Attacker",6,$N24="Healer",3,$N24="Magician",4,$N24="Defender",3,$N24="Supporter",4)} | Q24: {=_xlfn.IFS($N24="Attacker",6,$N24="Healer",3,$N24="Magician",4,$N24="Defender",3,$N24="Supporter",4)} | R24: 1 | S24: 0 | T24: 0 | U24: Spd | V24: {=_xlfn.IFS(N24="Attacker",80,N24="Healer",90,N24="Magician",100,N24="Defender",110,N24="Supporter",120)} | W24: Hp | X24: 5100 | Y24: Atk | Z24: 420 | AA24: Def | AB24: 120 | AC24: Penetration | AD24: 130 | AE24: Hit | AF24: 100 | AG24: Dodge | AH24: 100 | AI24: CriRatio | AJ24: 5000 | AK24: CriDmgRatio | AL24: 150000 | AM24: 1311181 | AN24: TRUE | AO24: 2311181 | AP24: FALSE | AQ24: 3311181 | AR24: TRUE | AS24: 4311181 | AT24: FALSE | AU24: =_xlfn.XLOOKUP(AM24,'[1]Skill<Child>'!$A:$A,'[1]Skill<Child>'!$A:$A) | AV24: =_xlfn.XLOOKUP(AO24,'[1]Skill<Child>'!$A:$A,'[1]Skill<Child>'!$A:$A) | AW24: =_xlfn.XLOOKUP(AQ24,'[1]Skill<Child>'!$A:$A,'[1]Skill<Child>'!$A:$A) | AX24: =_xlfn.XLOOKUP(AS24,'[1]Skill<Child>'!$A:$A,'[1]Skill<Child>'!$A:$A)
A25: 10000180 | B25: 맘몬 | C25: 118001 | D25: ="c"&MID(C25,2,3) | E25: ="character_name_"&A25 | F25: =D25&"_profile" | G25: None | H25: Normal | I25: 0.95,0.95,0.95 | J25: TRUE | K25: 0,0,0 | L25: 2 | M25: Forest | N25: Defender | O25: =100+L25 | P25: {=_xlfn.IFS($N25="Attacker",6,$N25="Healer",3,$N25="Magician",4,$N25="Defender",3,$N25="Supporter",4)} | Q25: {=_xlfn.IFS($N25="Attacker",6,$N25="Healer",3,$N25="Magician",4,$N25="Defender",3,$N25="Supporter",4)} | R25: 1 | S25: 0 | T25: 0 | U25: Spd | V25: {=_xlfn.IFS(N25="Attacker",80,N25="Healer",90,N25="Magician",100,N25="Defender",110,N25="Supporter",120)} | W25: Hp | X25: 8650 | Y25: Atk | Z25: 252 | AA25: Def | AB25: 240 | AC25: Penetration | AD25: 163 | AE25: Hit | AF25: 100 | AG25: Dodge | AH25: 100 | AI25: CriRatio | AJ25: 5000 | AK25: CriDmgRatio | AL25: 150000 | AM25: 1532071 | AN25: TRUE | AO25: 2532071 | AP25: FALSE | AQ25: 3532071 | AR25: TRUE | AS25: 4532071 | AT25: FALSE | AU25: =_xlfn.XLOOKUP(AM25,'[1]Skill<Child>'!$A:$A,'[1]Skill<Child>'!$A:$A) | AV25: =_xlfn.XLOOKUP(AO25,'[1]Skill<Child>'!$A:$A,'[1]Skill<Child>'!$A:$A) | AW25: =_xlfn.XLOOKUP(AQ25,'[1]Skill<Child>'!$A:$A,'[1]Skill<Child>'!$A:$A) | AX25: =_xlfn.XLOOKUP(AS25,'[1]Skill<Child>'!$A:$A,'[1]Skill<Child>'!$A:$A)
A26: 10000132 | B26: 미다스 | C26: 1013201 | D26: c132 | E26: character_name_10000132 | F26: =D26&"_profile" | G26: None | H26: Normal | I26: 0.95,0.95,0.95 | J26: TRUE | K26: 0,0,0 | L26: 2 | M26: Forest | N26: Attacker | O26: =100+L26 | P26: 6 | Q26: 6 | R26: 1 | S26: 0 | T26: 0 | U26: Spd | V26: 80 | W26: Hp | X26: 5100 | Y26: Atk | Z26: 420 | AA26: Def | AB26: 120 | AC26: Penetration | AD26: 120 | AE26: Hit | AF26: 100 | AG26: Dodge | AH26: 100 | AI26: CriRatio | AJ26: 5000 | AK26: CriDmgRatio | AL26: 150000 | AU26: =_xlfn.XLOOKUP(AM26,'[1]Skill<Child>'!$A:$A,'[1]Skill<Child>'!$A:$A) | AV26: =_xlfn.XLOOKUP(AO26,'[1]Skill<Child>'!$A:$A,'[1]Skill<Child>'!$A:$A) | AW26: =_xlfn.XLOOKUP(AQ26,'[1]Skill<Child>'!$A:$A,'[1]Skill<Child>'!$A:$A) | AX26: =_xlfn.XLOOKUP(AS26,'[1]Skill<Child>'!$A:$A,'[1]Skill<Child>'!$A:$A)
A27: 10000398 | B27: 자청비 | C27: 1039801 | D27: c398 | E27: character_name_10000398 | F27: =D27&"_profile" | G27: None | H27: Normal | I27: 0.95,0.95,0.95 | J27: TRUE | K27: 0,0,0 | L27: 2 | M27: Forest | N27: Supporter | O27: =100+L27 | P27: 4 | Q27: 4 | R27: 1 | S27: 0 | T27: 0 | U27: Spd | V27: 120 | W27: Hp | X27: 5909 | Y27: Atk | Z27: 198 | AA27: Def | AB27: 142 | AC27: Penetration | AD27: 142 | AE27: Hit | AF27: 100 | AG27: Dodge | AH27: 100 | AI27: CriRatio | AJ27: 5000 | AK27: CriDmgRatio | AL27: 150000 | AU27: =_xlfn.XLOOKUP(AM27,'[1]Skill<Child>'!$A:$A,'[1]Skill<Child>'!$A:$A) | AV27: =_xlfn.XLOOKUP(AO27,'[1]Skill<Child>'!$A:$A,'[1]Skill<Child>'!$A:$A) | AW27: =_xlfn.XLOOKUP(AQ27,'[1]Skill<Child>'!$A:$A,'[1]Skill<Child>'!$A:$A) | AX27: =_xlfn.XLOOKUP(AS27,'[1]Skill<Child>'!$A:$A,'[1]Skill<Child>'!$A:$A)
A28: 10000227 | B28: 마프데트 | C28: 1022701 | D28: c227 | E28: character_name_10000227 | F28: =D28&"_profile" | G28: None | H28: Normal | I28: 0.95,0.95,0.95 | J28: TRUE | K28: 0,0,0 | L28: 2 | M28: Light | N28: Magician | O28: =100+L28 | P28: 4 | Q28: 4 | R28: 1 | S28: 0 | T28: 0 | U28: Spd | V28: 120 | W28: Hp | X28: 5909 | Y28: Atk | Z28: 198 | AA28: Def | AB28: 142 | AC28: Penetration | AD28: 142 | AE28: Hit | AF28: 100 | AG28: Dodge | AH28: 100 | AI28: CriRatio | AJ28: 5000 | AK28: CriDmgRatio | AL28: 150000 | AU28: =_xlfn.XLOOKUP(AM28,'[1]Skill<Child>'!$A:$A,'[1]Skill<Child>'!$A:$A) | AV28: =_xlfn.XLOOKUP(AO28,'[1]Skill<Child>'!$A:$A,'[1]Skill<Child>'!$A:$A) | AW28: =_xlfn.XLOOKUP(AQ28,'[1]Skill<Child>'!$A:$A,'[1]Skill<Child>'!$A:$A) | AX28: =_xlfn.XLOOKUP(AS28,'[1]Skill<Child>'!$A:$A,'[1]Skill<Child>'!$A:$A)
A29: 10000296 | B29: 힐드 | C29: 129601 | D29: ="c"&MID(C29,2,3) | E29: ="character_name_"&A29 | F29: =D29&"_profile" | G29: None | H29: Normal | I29: 0.95,0.95,0.95 | J29: TRUE | K29: 0,0,0 | L29: 2 | M29: Light | N29: Attacker | O29: =100+L29 | P29: {=_xlfn.IFS($N29="Attacker",6,$N29="Healer",3,$N29="Magician",4,$N29="Defender",3,$N29="Supporter",4)} | Q29: {=_xlfn.IFS($N29="Attacker",6,$N29="Healer",3,$N29="Magician",4,$N29="Defender",3,$N29="Supporter",4)} | R29: 1 | S29: 0 | T29: 0 | U29: Spd | V29: {=_xlfn.IFS(N29="Attacker",80,N29="Healer",90,N29="Magician",100,N29="Defender",110,N29="Supporter",120)} | W29: Hp | X29: 5100 | Y29: Atk | Z29: 420 | AA29: Def | AB29: 120 | AC29: Penetration | AD29: 187 | AE29: Hit | AF29: 100 | AG29: Dodge | AH29: 100 | AI29: CriRatio | AJ29: 5000 | AK29: CriDmgRatio | AL29: 150000 | AM29: 1541021 | AN29: TRUE | AO29: 2541021 | AP29: FALSE | AQ29: 3541021 | AR29: TRUE | AS29: 4541021 | AT29: FALSE | AU29: =_xlfn.XLOOKUP(AM29,'[1]Skill<Child>'!$A:$A,'[1]Skill<Child>'!$A:$A) | AV29: =_xlfn.XLOOKUP(AO29,'[1]Skill<Child>'!$A:$A,'[1]Skill<Child>'!$A:$A) | AW29: =_xlfn.XLOOKUP(AQ29,'[1]Skill<Child>'!$A:$A,'[1]Skill<Child>'!$A:$A) | AX29: =_xlfn.XLOOKUP(AS29,'[1]Skill<Child>'!$A:$A,'[1]Skill<Child>'!$A:$A)
A30: 10000183 | B30: 다나 | C30: 118301 | D30: ="c"&MID(C30,2,3) | E30: ="character_name_"&A30 | F30: =D30&"_profile" | G30: None | H30: Normal | I30: 0.95,0.95,0.95 | J30: TRUE | K30: 0,0,0 | L30: 2 | M30: Light | N30: Healer | O30: =100+L30 | P30: {=_xlfn.IFS($N30="Attacker",6,$N30="Healer",3,$N30="Magician",4,$N30="Defender",3,$N30="Supporter",4)} | Q30: {=_xlfn.IFS($N30="Attacker",6,$N30="Healer",3,$N30="Magician",4,$N30="Defender",3,$N30="Supporter",4)} | R30: 1 | S30: 0 | T30: 0 | U30: Spd | V30: {=_xlfn.IFS(N30="Attacker",80,N30="Healer",90,N30="Magician",100,N30="Defender",110,N30="Supporter",120)} | W30: Hp | X30: 6475 | Y30: Atk | Z30: 168 | AA30: Def | AB30: 151 | AC30: Penetration | AD30: 187 | AE30: Hit | AF30: 100 | AG30: Dodge | AH30: 100 | AI30: CriRatio | AJ30: 5000 | AK30: CriDmgRatio | AL30: 150000 | AM30: 1555081 | AN30: TRUE | AO30: 2555081 | AP30: FALSE | AQ30: 3555081 | AR30: TRUE | AS30: 4555081 | AT30: FALSE | AU30: =_xlfn.XLOOKUP(AM30,'[1]Skill<Child>'!$A:$A,'[1]Skill<Child>'!$A:$A) | AV30: =_xlfn.XLOOKUP(AO30,'[1]Skill<Child>'!$A:$A,'[1]Skill<Child>'!$A:$A) | AW30: =_xlfn.XLOOKUP(AQ30,'[1]Skill<Child>'!$A:$A,'[1]Skill<Child>'!$A:$A) | AX30: =_xlfn.XLOOKUP(AS30,'[1]Skill<Child>'!$A:$A,'[1]Skill<Child>'!$A:$A)
A31: 10000002 | B31: 리자 | C31: 100201 | D31: ="c"&MID(C31,2,3) | E31: ="character_name_"&A31 | F31: =D31&"_profile" | G31: None | H31: Normal | I31: 0.95,0.95,0.95 | J31: TRUE | K31: 0,0,0 | L31: 2 | M31: Water | N31: Attacker | O31: =100+L31 | P31: {=_xlfn.IFS($N31="Attacker",6,$N31="Healer",3,$N31="Magician",4,$N31="Defender",3,$N31="Supporter",4)} | Q31: {=_xlfn.IFS($N31="Attacker",6,$N31="Healer",3,$N31="Magician",4,$N31="Defender",3,$N31="Supporter",4)} | R31: 1 | S31: 0 | T31: 0 | U31: Spd | V31: {=_xlfn.IFS(N31="Attacker",80,N31="Healer",90,N31="Magician",100,N31="Defender",110,N31="Supporter",120)} | W31: Hp | X31: 4743 | Y31: Atk | Z31: 341 | AA31: Def | AB31: 108 | AC31: Penetration | AD31: 130 | AE31: Hit | AF31: 100 | AG31: Dodge | AH31: 100 | AI31: CriRatio | AJ31: 5000 | AK31: CriDmgRatio | AL31: 150000 | AM31: 1325111 | AN31: TRUE | AO31: 2325111 | AP31: FALSE | AQ31: 3325111 | AR31: TRUE | AS31: 4325111 | AT31: FALSE | AU31: =_xlfn.XLOOKUP(AM31,'[1]Skill<Child>'!$A:$A,'[1]Skill<Child>'!$A:$A) | AV31: =_xlfn.XLOOKUP(AO31,'[1]Skill<Child>'!$A:$A,'[1]Skill<Child>'!$A:$A) | AW31: =_xlfn.XLOOKUP(AQ31,'[1]Skill<Child>'!$A:$A,'[1]Skill<Child>'!$A:$A) | AX31: =_xlfn.XLOOKUP(AS31,'[1]Skill<Child>'!$A:$A,'[1]Skill<Child>'!$A:$A)
A32: 10000193 | B32: 비루파 | C32: 1019301 | D32: c193 | E32: character_name_10000193 | F32: =D32&"_profile" | G32: None | H32: Normal | I32: 0.95,0.95,0.95 | J32: TRUE | K32: 0,0,0 | L32: 2 | M32: Water | N32: Attacker | O32: =100+L32 | P32: 6 | Q32: 6 | R32: 1 | S32: 0 | T32: 0 | U32: Spd | V32: 80 | W32: Hp | X32: 5100 | Y32: Atk | Z32: 420 | AA32: Def | AB32: 120 | AC32: Penetration | AD32: 120 | AE32: Hit | AF32: 100 | AG32: Dodge | AH32: 100 | AI32: CriRatio | AJ32: 5000 | AK32: CriDmgRatio | AL32: 150000 | AU32: =_xlfn.XLOOKUP(AM32,'[1]Skill<Child>'!$A:$A,'[1]Skill<Child>'!$A:$A) | AV32: =_xlfn.XLOOKUP(AO32,'[1]Skill<Child>'!$A:$A,'[1]Skill<Child>'!$A:$A) | AW32: =_xlfn.XLOOKUP(AQ32,'[1]Skill<Child>'!$A:$A,'[1]Skill<Child>'!$A:$A) | AX32: =_xlfn.XLOOKUP(AS32,'[1]Skill<Child>'!$A:$A,'[1]Skill<Child>'!$A:$A)
A33: 10000437 | B33: 에우로스 | C33: 1043701 | D33: c437 | E33: character_name_10000437 | F33: =D33&"_profile" | G33: None | H33: Normal | I33: 0.95,0.95,0.95 | J33: TRUE | K33: 0,0,0 | L33: 2 | M33: Water | N33: Healer | O33: =100+L33 | P33: 3 | Q33: 3 | R33: 1 | S33: 0 | T33: 0 | U33: Spd | V33: 90 | W33: Hp | X33: 6475 | Y33: Atk | Z33: 168 | AA33: Def | AB33: 151 | AC33: Penetration | AD33: 151 | AE33: Hit | AF33: 100 | AG33: Dodge | AH33: 100 | AI33: CriRatio | AJ33: 5000 | AK33: CriDmgRatio | AL33: 150000 | AU33: =_xlfn.XLOOKUP(AM33,'[1]Skill<Child>'!$A:$A,'[1]Skill<Child>'!$A:$A) | AV33: =_xlfn.XLOOKUP(AO33,'[1]Skill<Child>'!$A:$A,'[1]Skill<Child>'!$A:$A) | AW33: =_xlfn.XLOOKUP(AQ33,'[1]Skill<Child>'!$A:$A,'[1]Skill<Child>'!$A:$A) | AX33: =_xlfn.XLOOKUP(AS33,'[1]Skill<Child>'!$A:$A,'[1]Skill<Child>'!$A:$A)
A34: 10000432 | B34: 아르테미스 | C34: 143201 | D34: ="c"&MID(C34,2,3) | E34: ="character_name_"&A34 | F34: =D34&"_profile" | G34: None | H34: Normal | I34: 0.95,0.95,0.95 | J34: TRUE | K34: 0,0,0 | L34: 3 | M34: Dark | N34: Magician | O34: =100+L34 | P34: {=_xlfn.IFS($N34="Attacker",6,$N34="Healer",3,$N34="Magician",4,$N34="Defender",3,$N34="Supporter",4)} | Q34: {=_xlfn.IFS($N34="Attacker",6,$N34="Healer",3,$N34="Magician",4,$N34="Defender",3,$N34="Supporter",4)} | R34: 1 | S34: 0 | T34: 0 | U34: Spd | V34: {=_xlfn.IFS(N34="Attacker",80,N34="Healer",90,N34="Magician",100,N34="Defender",110,N34="Supporter",120)} | W34: Hp | X34: 5100 | Y34: Atk | Z34: 420 | AA34: Def | AB34: 120 | AC34: Penetration | AD34: 156 | AE34: Hit | AF34: 100 | AG34: Dodge | AH34: 100 | AI34: CriRatio | AJ34: 5000 | AK34: CriDmgRatio | AL34: 150000 | AM34: 1351161 | AN34: TRUE | AO34: 2351161 | AP34: TRUE | AQ34: 3351161 | AR34: TRUE | AS34: 4351161 | AT34: FALSE | AU34: =_xlfn.XLOOKUP(AM34,'[1]Skill<Child>'!$A:$A,'[1]Skill<Child>'!$A:$A) | AV34: =_xlfn.XLOOKUP(AO34,'[1]Skill<Child>'!$A:$A,'[1]Skill<Child>'!$A:$A) | AW34: =_xlfn.XLOOKUP(AQ34,'[1]Skill<Child>'!$A:$A,'[1]Skill<Child>'!$A:$A) | AX34: =_xlfn.XLOOKUP(AS34,'[1]Skill<Child>'!$A:$A,'[1]Skill<Child>'!$A:$A)
A35: 10000294 | B35: 바토리 | C35: 129401 | D35: ="c"&MID(C35,2,3) | E35: ="character_name_"&A35 | F35: =D35&"_profile" | G35: None | H35: Normal | I35: 0.95,0.95,0.95 | J35: TRUE | K35: 0,0,0 | L35: 3 | M35: Dark | N35: Supporter | O35: =100+L35 | P35: 6 | Q35: 6 | R35: 1 | S35: 0 | T35: 0 | U35: Spd | V35: {=_xlfn.IFS(N35="Attacker",80,N35="Healer",90,N35="Magician",100,N35="Defender",110,N35="Supporter",120)} | W35: Hp | X35: 5100 | Y35: Atk | Z35: 420 | AA35: Def | AB35: 120 | AC35: Penetration | AD35: 156 | AE35: Hit | AF35: 100 | AG35: Dodge | AH35: 100 | AI35: CriRatio | AJ35: 5000 | AK35: CriDmgRatio | AL35: 150000 | AM35: 1333131 | AN35: TRUE | AO35: 2333131 | AP35: TRUE | AQ35: 3333131 | AR35: TRUE | AS35: 4333131 | AT35: FALSE | AU35: =_xlfn.XLOOKUP(AM35,'[1]Skill<Child>'!$A:$A,'[1]Skill<Child>'!$A:$A) | AV35: =_xlfn.XLOOKUP(AO35,'[1]Skill<Child>'!$A:$A,'[1]Skill<Child>'!$A:$A) | AW35: =_xlfn.XLOOKUP(AQ35,'[1]Skill<Child>'!$A:$A,'[1]Skill<Child>'!$A:$A) | AX35: =_xlfn.XLOOKUP(AS35,'[1]Skill<Child>'!$A:$A,'[1]Skill<Child>'!$A:$A)
A36: 10000051 | B36: 프레이 | C36: 105102 | D36: ="c"&MID(C36,2,3) | E36: ="character_name_"&A36 | F36: =D36&"_profile" | G36: None | H36: Normal | I36: 0.95,0.95,0.95 | J36: TRUE | K36: 0,0,0 | L36: 3 | M36: Dark | N36: Defender | O36: =100+L36 | P36: {=_xlfn.IFS($N36="Attacker",6,$N36="Healer",3,$N36="Magician",4,$N36="Defender",3,$N36="Supporter",4)} | Q36: {=_xlfn.IFS($N36="Attacker",6,$N36="Healer",3,$N36="Magician",4,$N36="Defender",3,$N36="Supporter",4)} | R36: 1 | S36: 0 | T36: 0 | U36: Spd | V36: {=_xlfn.IFS(N36="Attacker",80,N36="Healer",90,N36="Magician",100,N36="Defender",110,N36="Supporter",120)} | W36: Hp | X36: 8650 | Y36: Atk | Z36: 252 | AA36: Def | AB36: 240 | AC36: Penetration | AD36: 234 | AE36: Hit | AF36: 100 | AG36: Dodge | AH36: 100 | AI36: CriRatio | AJ36: 5000 | AK36: CriDmgRatio | AL36: 150000 | AM36: 1551091 | AN36: TRUE | AO36: 2551091 | AP36: FALSE | AQ36: 3551091 | AR36: TRUE | AS36: 4551091 | AT36: FALSE | AU36: =_xlfn.XLOOKUP(AM36,'[1]Skill<Child>'!$A:$A,'[1]Skill<Child>'!$A:$A) | AV36: =_xlfn.XLOOKUP(AO36,'[1]Skill<Child>'!$A:$A,'[1]Skill<Child>'!$A:$A) | AW36: =_xlfn.XLOOKUP(AQ36,'[1]Skill<Child>'!$A:$A,'[1]Skill<Child>'!$A:$A) | AX36: =_xlfn.XLOOKUP(AS36,'[1]Skill<Child>'!$A:$A,'[1]Skill<Child>'!$A:$A)
A37: 10000486 | B37: 쿠바바 | C37: 148601 | D37: ="c"&MID(C37,2,3) | E37: ="character_name_"&A37 | F37: =D37&"_profile" | G37: None | H37: Normal | I37: 0.95,0.95,0.95 | J37: TRUE | K37: 0,0,0 | L37: 3 | M37: Dark | N37: Attacker | O37: =100+L37 | P37: {=_xlfn.IFS($N37="Attacker",6,$N37="Healer",3,$N37="Magician",4,$N37="Defender",3,$N37="Supporter",4)} | Q37: {=_xlfn.IFS($N37="Attacker",6,$N37="Healer",3,$N37="Magician",4,$N37="Defender",3,$N37="Supporter",4)} | R37: 1 | S37: 0 | T37: 0 | U37: Spd | V37: {=_xlfn.IFS(N37="Attacker",80,N37="Healer",90,N37="Magician",100,N37="Defender",110,N37="Supporter",120)} | W37: Hp | X37: 5100 | Y37: Atk | Z37: 420 | AA37: Def | AB37: 120 | AC37: Penetration | AD37: 187 | AE37: Hit | AF37: 100 | AG37: Dodge | AH37: 100 | AI37: CriRatio | AJ37: 5000 | AK37: CriDmgRatio | AL37: 150000 | AM37: 1353141 | AN37: TRUE | AO37: 2353141 | AP37: TRUE | AQ37: 3353141 | AR37: TRUE | AS37: 4353141 | AT37: FALSE | AU37: =_xlfn.XLOOKUP(AM37,'[1]Skill<Child>'!$A:$A,'[1]Skill<Child>'!$A:$A) | AV37: =_xlfn.XLOOKUP(AO37,'[1]Skill<Child>'!$A:$A,'[1]Skill<Child>'!$A:$A) | AW37: =_xlfn.XLOOKUP(AQ37,'[1]Skill<Child>'!$A:$A,'[1]Skill<Child>'!$A:$A) | AX37: =_xlfn.XLOOKUP(AS37,'[1]Skill<Child>'!$A:$A,'[1]Skill<Child>'!$A:$A)
A38: 10000400 | B38: 반시 | C38: 140001 | D38: ="c"&MID(C38,2,3) | E38: ="character_name_"&A38 | F38: =D38&"_profile" | G38: None | H38: Normal | I38: 0.95,0.95,0.95 | J38: TRUE | K38: 0,0,0 | L38: 3 | M38: Dark | N38: Magician | O38: =100+L38 | P38: {=_xlfn.IFS($N38="Attacker",6,$N38="Healer",3,$N38="Magician",4,$N38="Defender",3,$N38="Supporter",4)} | Q38: {=_xlfn.IFS($N38="Attacker",6,$N38="Healer",3,$N38="Magician",4,$N38="Defender",3,$N38="Supporter",4)} | R38: 1 | S38: 0 | T38: 0 | U38: Spd | V38: {=_xlfn.IFS(N38="Attacker",80,N38="Healer",90,N38="Magician",100,N38="Defender",110,N38="Supporter",120)} | W38: Hp | X38: 5100 | Y38: Atk | Z38: 420 | AA38: Def | AB38: 120 | AC38: Penetration | AD38: 156 | AE38: Hit | AF38: 100 | AG38: Dodge | AH38: 100 | AI38: CriRatio | AJ38: 5000 | AK38: CriDmgRatio | AL38: 150000 | AM38: 1551301 | AN38: TRUE | AO38: 2551301 | AP38: TRUE | AQ38: 3551301 | AR38: TRUE | AS38: 4551301 | AT38: FALSE
A39: 10000532 | B39: 아누비스 | C39: 153201 | D39: ="c"&MID(C39,2,3) | E39: ="character_name_"&A39 | F39: =D39&"_profile" | G39: None | H39: Normal | I39: 0.95,0.95,0.95 | J39: TRUE | K39: 0,0,0 | L39: 3 | M39: Dark | N39: Attacker | O39: =100+L39 | P39: 6 | Q39: 6 | R39: 1 | S39: 0 | T39: 0 | U39: Spd | V39: {=_xlfn.IFS(N39="Attacker",80,N39="Healer",90,N39="Magician",100,N39="Defender",110,N39="Supporter",120)} | W39: Hp | X39: 5100 | Y39: Atk | Z39: 420 | AA39: Def | AB39: 120 | AC39: Penetration | AD39: 120 | AE39: Hit | AF39: 100 | AG39: Dodge | AH39: 100 | AI39: CriRatio | AJ39: 5000 | AK39: CriDmgRatio | AL39: 150000
A40: 10000448 | B40: 미르칼라 | C40: 144801 | D40: ="c"&MID(C40,2,3) | E40: ="character_name_"&A40 | F40: =D40&"_profile" | G40: None | H40: Normal | I40: 0.95,0.95,0.95 | J40: TRUE | K40: 0,0,0 | L40: 3 | M40: Dark | N40: Healer | O40: =100+L40 | P40: 4 | Q40: 4 | R40: 1 | S40: 0 | T40: 0 | U40: Spd | V40: {=_xlfn.IFS(N40="Attacker",80,N40="Healer",90,N40="Magician",100,N40="Defender",110,N40="Supporter",120)} | W40: Hp | X40: 4743 | Y40: Atk | Z40: 341 | AA40: Def | AB40: 108 | AC40: Penetration | AD40: 108 | AE40: Hit | AF40: 100 | AG40: Dodge | AH40: 100 | AI40: CriRatio | AJ40: 5000 | AK40: CriDmgRatio | AL40: 150000
A41: 10000485 | B41: 유나 | C41: 148501 | D41: ="c"&MID(C41,2,3) | E41: ="character_name_"&A41 | F41: =D41&"_profile" | G41: None | H41: Normal | I41: 0.95,0.95,0.95 | J41: TRUE | K41: 0,0,0 | L41: 3 | M41: Dark | N41: Supporter | O41: =100+L41 | P41: 4 | Q41: 4 | R41: 1 | S41: 0 | T41: 0 | U41: Spd | V41: {=_xlfn.IFS(N41="Attacker",80,N41="Healer",90,N41="Magician",100,N41="Defender",110,N41="Supporter",120)} | W41: Hp | X41: 5909 | Y41: Atk | Z41: 198 | AA41: Def | AB41: 142 | AC41: Penetration | AD41: 142 | AE41: Hit | AF41: 100 | AG41: Dodge | AH41: 100 | AI41: CriRatio | AJ41: 5000 | AK41: CriDmgRatio | AL41: 150000
...

Sheet Detail<Monster>
A1: Id | B1: #이름 | C1: Skin | D1: #DefaultSoul | E1: Name | F1: Profile | G1: MonsterType | H1: Size | I1: #Difficuly | J1: Scale | K1: UseHud | L1: StatusOffset | M1: StarGrade | N1: Element | O1: Role | P1: LevelUpGroup | Q1: MaxSp | R1: UseSp | S1: TurnSp | T1: AtkSp | U1: HitSp | V1: StatParam | W1: StatValue | X1: StatParam | Y1: StatValue | Z1: StatParam | AA1: StatValue | AB1: StatParam | AC1: StatValue | AD1: StatParam | AE1: StatValue | AF1: StatParam | AG1: StatValue | AH1: StatParam | AI1: StatValue | AJ1: StatParam | AK1: StatValue | AL1: StatParam | AM1: StatValue | AN1: SkillId | AO1: DefaultCheck | AP1: SkillId | AQ1: DefaultCheck | AR1: SkillId | AS1: DefaultCheck | AT1: SkillId | AU1: DefaultCheck
G3: 몬스터 타입 | H3: 크기 | I3: 난이도 | M3: 등급 | N3: 속성 | O3: 직업 | AN3: Normal | AP3: Active | AR3: Ultimate | AT3: Passive
A4: 20130101 | B4: 봉제인형 | C4: 201301 | D4: 0 | E4: character_name_20130101 | G4: Normal | H4: Normal | I4: 1 | J4: 1,1,1 | K4: TRUE | L4: 0,0,0 | M4: 2 | N4: Fire | O4: Defender | P4: 200 | Q4: {=_xlfn.IFS($O4="Attacker",6,$O4="Healer",3,$O4="Magician",4,$O4="Defender",3,$O4="Supporter",4)} | R4: {=_xlfn.IFS($O4="Attacker",6,$O4="Healer",3,$O4="Magician",4,$O4="Defender",3,$O4="Supporter",4)} | S4: 1 | T4: 0 | U4: 0 | V4: Spd | W4: {=_xlfn.IFS(O4="Attacker",80,O4="Healer",90,O4="Magician",100,O4="Defender",110,O4="Supporter",120)} | X4: Hp | Y4: 1000 | Z4: Atk | AA4: 500 | AB4: Def | AC4: 20 | AD4: Penetration | AE4: =AC4 | AF4: Hit | AG4: 100 | AH4: Dodge | AI4: 80 | AJ4: CriRatio | AK4: 0 | AL4: CriDmgRatio | AM4: 150000 | AN4: 1842051 | AO4: TRUE | AP4: 2842051 | AQ4: TRUE | AR4: 0 | AS4: FALSE | AT4: 0 | AU4: FALSE
A5: 20130201 | B5: 봉제인형 | C5: 201302 | D5: 0 | E5: character_name_20130201 | G5: Normal | H5: Normal | I5: 1 | J5: 1,1,1 | K5: TRUE | L5: 0,0,0 | M5: 2 | N5: Fire | O5: Defender | P5: 200 | Q5: {=_xlfn.IFS($O5="Attacker",6,$O5="Healer",3,$O5="Magician",4,$O5="Defender",3,$O5="Supporter",4)} | R5: {=_xlfn.IFS($O5="Attacker",6,$O5="Healer",3,$O5="Magician",4,$O5="Defender",3,$O5="Supporter",4)} | S5: 1 | T5: 0 | U5: 0 | V5: Spd | W5: {=_xlfn.IFS(O5="Attacker",80,O5="Healer",90,O5="Magician",100,O5="Defender",110,O5="Supporter",120)} | X5: Hp | Y5: 1000 | Z5: Atk | AA5: 500 | AB5: Def | AC5: 20 | AD5: Penetration | AE5: =AC5 | AF5: Hit | AG5: 100 | AH5: Dodge | AI5: 80 | AJ5: CriRatio | AK5: 0 | AL5: CriDmgRatio | AM5: 150000 | AN5: 1842051 | AO5: TRUE | AP5: 2842051 | AQ5: TRUE | AR5: 0 | AS5: FALSE | AT5: 0 | AU5: FALSE
A6: 20130102 | B6: 봉제인형 | C6: 201301 | D6: 0 | E6: character_name_20130102 | G6: Normal | H6: Normal | I6: 2 | J6: 1,1,1 | K6: TRUE | L6: 0,0,0 | M6: 2 | N6: Fire | O6: Defender | P6: 200 | Q6: {=_xlfn.IFS($O6="Attacker",6,$O6="Healer",3,$O6="Magician",4,$O6="Defender",3,$O6="Supporter",4)} | R6: {=_xlfn.IFS($O6="Attacker",6,$O6="Healer",3,$O6="Magician",4,$O6="Defender",3,$O6="Supporter",4)} | S6: 1 | T6: 0 | U6: 0 | V6: Spd | W6: {=_xlfn.IFS(O6="Attacker",80,O6="Healer",90,O6="Magician",100,O6="Defender",110,O6="Supporter",120)} | X6: Hp | Y6: 1000 | Z6: Atk | AA6: 500 | AB6: Def | AC6: 20 | AD6: Penetration | AE6: =AC6 | AF6: Hit | AG6: 100 | AH6: Dodge | AI6: 80 | AJ6: CriRatio | AK6: 0 | AL6: CriDmgRatio | AM6: 150000 | AN6: 1842051 | AO6: TRUE | AP6: 2842051 | AQ6: TRUE | AR6: 0 | AS6: FALSE | AT6: 0 | AU6: FALSE
A7: 20130202 | B7: 봉제인형 | C7: 201302 | D7: 0 | E7: character_name_20130202 | G7: Normal | H7: Normal | I7: 2 | J7: 1,1,1 | K7: TRUE | L7: 0,0,0 | M7: 2 | N7: Fire | O7: Defender | P7: 200 | Q7: {=_xlfn.IFS($O7="Attacker",6,$O7="Healer",3,$O7="Magician",4,$O7="Defender",3,$O7="Supporter",4)} | R7: {=_xlfn.IFS($O7="Attacker",6,$O7="Healer",3,$O7="Magician",4,$O7="Defender",3,$O7="Supporter",4)} | S7: 1 | T7: 0 | U7: 0 | V7: Spd | W7: {=_xlfn.IFS(O7="Attacker",80,O7="Healer",90,O7="Magician",100,O7="Defender",110,O7="Supporter",120)} | X7: Hp | Y7: 1000 | Z7: Atk | AA7: 500 | AB7: Def | AC7: 20 | AD7: Penetration | AE7: =AC7 | AF7: Hit | AG7: 100 | AH7: Dodge | AI7: 80 | AJ7: CriRatio | AK7: 0 | AL7: CriDmgRatio | AM7: 150000 | AN7: 1842051 | AO7: TRUE | AP7: 2842051 | AQ7: TRUE | AR7: 0 | AS7: FALSE | AT7: 0 | AU7: FALSE
A8: 20730101 | B8: 큐브-화 | C8: 207301 | D8: 0 | E8: character_name_20730101 | G8: Normal | H8: Normal | I8: 1 | J8: 1,1,1 | K8: TRUE | L8: 0,0,0 | M8: 2 | N8: Fire | O8: Defender | P8: 200 | Q8: {=_xlfn.IFS($O8="Attacker",6,$O8="Healer",3,$O8="Magician",4,$O8="Defender",3,$O8="Supporter",4)} | R8: {=_xlfn.IFS($O8="Attacker",6,$O8="Healer",3,$O8="Magician",4,$O8="Defender",3,$O8="Supporter",4)} | S8: 1 | T8: 0 | U8: 0 | V8: Spd | W8: {=_xlfn.IFS(O8="Attacker",80,O8="Healer",90,O8="Magician",100,O8="Defender",110,O8="Supporter",120)} | X8: Hp | Y8: 300 | Z8: Atk | AA8: 200 | AB8: Def | AC8: 0 | AD8: Penetration | AE8: 0 | AF8: Hit | AG8: 100 | AH8: Dodge | AI8: 100 | AJ8: CriRatio | AK8: 5000 | AL8: CriDmgRatio | AM8: 150000 | AN8: 1811041 | AO8: TRUE | AP8: 2811041 | AQ8: TRUE | AR8: 0 | AS8: FALSE | AT8: 0 | AU8: FALSE
A9: 20730201 | B9: 큐브-수 | C9: 207302 | D9: 0 | E9: character_name_20730201 | G9: Normal | H9: Normal | I9: 1 | J9: 1,1,1 | K9: TRUE | L9: 0,0,0 | M9: 2 | N9: Water | O9: Defender | P9: 200 | Q9: {=_xlfn.IFS($O9="Attacker",6,$O9="Healer",3,$O9="Magician",4,$O9="Defender",3,$O9="Supporter",4)} | R9: {=_xlfn.IFS($O9="Attacker",6,$O9="Healer",3,$O9="Magician",4,$O9="Defender",3,$O9="Supporter",4)} | S9: 1 | T9: 0 | U9: 0 | V9: Spd | W9: {=_xlfn.IFS(O9="Attacker",80,O9="Healer",90,O9="Magician",100,O9="Defender",110,O9="Supporter",120)} | X9: Hp | Y9: 300 | Z9: Atk | AA9: 200 | AB9: Def | AC9: 0 | AD9: Penetration | AE9: 0 | AF9: Hit | AG9: 120 | AH9: Dodge | AI9: 100 | AJ9: CriRatio | AK9: 5000 | AL9: CriDmgRatio | AM9: 150000 | AN9: 1821041 | AO9: TRUE | AP9: 2821041 | AQ9: TRUE | AR9: 0 | AS9: FALSE | AT9: 0 | AU9: FALSE
A10: 20730301 | B10: 큐브-목 | C10: 207303 | D10: 0 | E10: character_name_20730301 | G10: Normal | H10: Normal | I10: 1 | J10: 1,1,1 | K10: TRUE | L10: 0,0,0 | M10: 2 | N10: Forest | O10: Defender | P10: 200 | Q10: {=_xlfn.IFS($O10="Attacker",6,$O10="Healer",3,$O10="Magician",4,$O10="Defender",3,$O10="Supporter",4)} | R10: {=_xlfn.IFS($O10="Attacker",6,$O10="Healer",3,$O10="Magician",4,$O10="Defender",3,$O10="Supporter",4)} | S10: 1 | T10: 0 | U10: 0 | V10: Spd | W10: {=_xlfn.IFS(O10="Attacker",80,O10="Healer",90,O10="Magician",100,O10="Defender",110,O10="Supporter",120)} | X10: Hp | Y10: 300 | Z10: Atk | AA10: 200 | AB10: Def | AC10: 0 | AD10: Penetration | AE10: 0 | AF10: Hit | AG10: 100 | AH10: Dodge | AI10: 100 | AJ10: CriRatio | AK10: 5000 | AL10: CriDmgRatio | AM10: 150000 | AN10: 1831041 | AO10: TRUE | AP10: 2831041 | AQ10: TRUE | AR10: 0 | AS10: FALSE | AT10: 0 | AU10: FALSE
A11: 20730401 | B11: 큐브-광 | C11: 207304 | D11: 0 | E11: character_name_20730401 | G11: Normal | H11: Normal | I11: 1 | J11: 1,1,1 | K11: TRUE | L11: 0,0,0 | M11: 2 | N11: Light | O11: Defender | P11: 200 | Q11: {=_xlfn.IFS($O11="Attacker",6,$O11="Healer",3,$O11="Magician",4,$O11="Defender",3,$O11="Supporter",4)} | R11: {=_xlfn.IFS($O11="Attacker",6,$O11="Healer",3,$O11="Magician",4,$O11="Defender",3,$O11="Supporter",4)} | S11: 1 | T11: 0 | U11: 0 | V11: Spd | W11: {=_xlfn.IFS(O11="Attacker",80,O11="Healer",90,O11="Magician",100,O11="Defender",110,O11="Supporter",120)} | X11: Hp | Y11: 300 | Z11: Atk | AA11: 200 | AB11: Def | AC11: 0 | AD11: Penetration | AE11: 0 | AF11: Hit | AG11: 100 | AH11: Dodge | AI11: 100 | AJ11: CriRatio | AK11: 5000 | AL11: CriDmgRatio | AM11: 150000 | AN11: 1841041 | AO11: TRUE | AP11: 2841041 | AQ11: TRUE | AR11: 0 | AS11: FALSE | AT11: 0 | AU11: FALSE
A12: 20730501 | B12: 큐브-암 | C12: 207305 | D12: 0 | E12: character_name_20730501 | G12: Normal | H12: Normal | I12: 1 | J12: 1,1,1 | K12: TRUE | L12: 0,0,0 | M12: 2 | N12: Dark | O12: Defender | P12: 200 | Q12: {=_xlfn.IFS($O12="Attacker",6,$O12="Healer",3,$O12="Magician",4,$O12="Defender",3,$O12="Supporter",4)} | R12: {=_xlfn.IFS($O12="Attacker",6,$O12="Healer",3,$O12="Magician",4,$O12="Defender",3,$O12="Supporter",4)} | S12: 1 | T12: 0 | U12: 0 | V12: Spd | W12: {=_xlfn.IFS(O12="Attacker",80,O12="Healer",90,O12="Magician",100,O12="Defender",110,O12="Supporter",120)} | X12: Hp | Y12: 300 | Z12: Atk | AA12: 200 | AB12: Def | AC12: 0 | AD12: Penetration | AE12: 0 | AF12: Hit | AG12: 100 | AH12: Dodge | AI12: 100 | AJ12: CriRatio | AK12: 5000 | AL12: CriDmgRatio | AM12: 150000 | AN12: 1851041 | AO12: TRUE | AP12: 2851041 | AQ12: TRUE | AR12: 0 | AS12: FALSE | AT12: 0 | AU12: FALSE
A13: 20730102 | B13: 큐브-화 | C13: 207301 | D13: 0 | E13: character_name_20730102 | G13: Normal | H13: Normal | I13: 2 | J13: 1,1,1 | K13: TRUE | L13: 0,0,0 | M13: 2 | N13: Fire | O13: Defender | P13: 200 | Q13: {=_xlfn.IFS($O13="Attacker",6,$O13="Healer",3,$O13="Magician",4,$O13="Defender",3,$O13="Supporter",4)} | R13: {=_xlfn.IFS($O13="Attacker",6,$O13="Healer",3,$O13="Magician",4,$O13="Defender",3,$O13="Supporter",4)} | S13: 1 | T13: 0 | U13: 0 | V13: Spd | W13: {=_xlfn.IFS(O13="Attacker",80,O13="Healer",90,O13="Magician",100,O13="Defender",110,O13="Supporter",120)} | X13: Hp | Y13: 300 | Z13: Atk | AA13: 200 | AB13: Def | AC13: 20 | AD13: Penetration | AE13: 0 | AF13: Hit | AG13: 100 | AH13: Dodge | AI13: 100 | AJ13: CriRatio | AK13: 5000 | AL13: CriDmgRatio | AM13: 150000 | AN13: 1811041 | AO13: TRUE | AP13: 2811041 | AQ13: TRUE | AR13: 0 | AS13: FALSE | AT13: 0 | AU13: FALSE
A14: 20730202 | B14: 큐브-수 | C14: 207302 | D14: 0 | E14: character_name_20730202 | G14: Normal | H14: Normal | I14: 2 | J14: 1,1,1 | K14: TRUE | L14: 0,0,0 | M14: 2 | N14: Water | O14: Defender | P14: 200 | Q14: {=_xlfn.IFS($O14="Attacker",6,$O14="Healer",3,$O14="Magician",4,$O14="Defender",3,$O14="Supporter",4)} | R14: {=_xlfn.IFS($O14="Attacker",6,$O14="Healer",3,$O14="Magician",4,$O14="Defender",3,$O14="Supporter",4)} | S14: 1 | T14: 0 | U14: 0 | V14: Spd | W14: {=_xlfn.IFS(O14="Attacker",80,O14="Healer",90,O14="Magician",100,O14="Defender",110,O14="Supporter",120)} | X14: Hp | Y14: 300 | Z14: Atk | AA14: 200 | AB14: Def | AC14: 20 | AD14: Penetration | AE14: 0 | AF14: Hit | AG14: 100 | AH14: Dodge | AI14: 100 | AJ14: CriRatio | AK14: 5000 | AL14: CriDmgRatio | AM14: 150000 | AN14: 1821041 | AO14: TRUE | AP14: 2821041 | AQ14: TRUE | AR14: 0 | AS14: FALSE | AT14: 0 | AU14: FALSE
A15: 20730302 | B15: 큐브-목 | C15: 207303 | D15: 0 | E15: character_name_20730302 | G15: Normal | H15: Normal | I15: 2 | J15: 1,1,1 | K15: TRUE | L15: 0,0,0 | M15: 2 | N15: Forest | O15: Defender | P15: 200 | Q15: {=_xlfn.IFS($O15="Attacker",6,$O15="Healer",3,$O15="Magician",4,$O15="Defender",3,$O15="Supporter",4)} | R15: {=_xlfn.IFS($O15="Attacker",6,$O15="Healer",3,$O15="Magician",4,$O15="Defender",3,$O15="Supporter",4)} | S15: 1 | T15: 0 | U15: 0 | V15: Spd | W15: {=_xlfn.IFS(O15="Attacker",80,O15="Healer",90,O15="Magician",100,O15="Defender",110,O15="Supporter",120)} | X15: Hp | Y15: 300 | Z15: Atk | AA15: 200 | AB15: Def | AC15: 20 | AD15: Penetration | AE15: 0 | AF15: Hit | AG15: 100 | AH15: Dodge | AI15: 100 | AJ15: CriRatio | AK15: 5000 | AL15: CriDmgRatio | AM15: 150000 | AN15: 1831041 | AO15: TRUE | AP15: 2831041 | AQ15: TRUE | AR15: 0 | AS15: FALSE | AT15: 0 | AU15: FALSE
A16: 20730402 | B16: 큐브-광 | C16: 207304 | D16: 0 | E16: character_name_20730402 | G16: Normal | H16: Normal | I16: 2 | J16: 1,1,1 | K16: TRUE | L16: 0,0,0 | M16: 2 | N16: Light | O16: Defender | P16: 200 | Q16: {=_xlfn.IFS($O16="Attacker",6,$O16="Healer",3,$O16="Magician",4,$O16="Defender",3,$O16="Supporter",4)} | R16: {=_xlfn.IFS($O16="Attacker",6,$O16="Healer",3,$O16="Magician",4,$O16="Defender",3,$O16="Supporter",4)} | S16: 1 | T16: 0 | U16: 0 | V16: Spd | W16: {=_xlfn.IFS(O16="Attacker",80,O16="Healer",90,O16="Magician",100,O16="Defender",110,O16="Supporter",120)} | X16: Hp | Y16: 300 | Z16: Atk | AA16: 200 | AB16: Def | AC16: 20 | AD16: Penetration | AE16: 0 | AF16: Hit | AG16: 100 | AH16: Dodge | AI16: 100 | AJ16: CriRatio | AK16: 5000 | AL16: CriDmgRatio | AM16: 150000 | AN16: 1841041 | AO16: TRUE | AP16: 2841041 | AQ16: TRUE | AR16: 0 | AS16: FALSE | AT16: 0 | AU16: FALSE
A17: 20730502 | B17: 큐브-암 | C17: 207305 | D17: 0 | E17: character_name_20730502 | G17: Normal | H17: Normal | I17: 2 | J17: 1,1,1 | K17: TRUE | L17: 0,0,0 | M17: 2 | N17: Dark | O17: Defender | P17: 200 | Q17: {=_xlfn.IFS($O17="Attacker",6,$O17="Healer",3,$O17="Magician",4,$O17="Defender",3,$O17="Supporter",4)} | R17: {=_xlfn.IFS($O17="Attacker",6,$O17="Healer",3,$O17="Magician",4,$O17="Defender",3,$O17="Supporter",4)} | S17: 1 | T17: 0 | U17: 0 | V17: Spd | W17: {=_xlfn.IFS(O17="Attacker",80,O17="Healer",90,O17="Magician",100,O17="Defender",110,O17="Supporter",120)} | X17: Hp | Y17: 300 | Z17: Atk | AA17: 200 | AB17: Def | AC17: 20 | AD17: Penetration | AE17: 0 | AF17: Hit | AG17: 100 | AH17: Dodge | AI17: 100 | AJ17: CriRatio | AK17: 5000 | AL17: CriDmgRatio | AM17: 150000 | AN17: 1851041 | AO17: TRUE | AP17: 2851041 | AQ17: TRUE | AR17: 0 | AS17: FALSE | AT17: 0 | AU17: FALSE
A18: 20730103 | B18: 큐브-화 | C18: 207301 | D18: 0 | E18: character_name_20730103 | G18: Normal | H18: Normal | I18: 3 | J18: 1,1,1 | K18: TRUE | L18: 0,0,0 | M18: 2 | N18: Fire | O18: Defender | P18: 200 | Q18: {=_xlfn.IFS($O18="Attacker",6,$O18="Healer",3,$O18="Magician",4,$O18="Defender",3,$O18="Supporter",4)} | R18: {=_xlfn.IFS($O18="Attacker",6,$O18="Healer",3,$O18="Magician",4,$O18="Defender",3,$O18="Supporter",4)} | S18: 1 | T18: 0 | U18: 0 | V18: Spd | W18: {=_xlfn.IFS(O18="Attacker",80,O18="Healer",90,O18="Magician",100,O18="Defender",110,O18="Supporter",120)} | X18: Hp | Y18: 36000 | Z18: Atk | AA18: 450 | AB18: Def | AC18: 0 | AD18: Penetration | AE18: 0 | AF18: Hit | AG18: 100 | AH18: Dodge | AI18: 80 | AJ18: CriRatio | AK18: 0 | AL18: CriDmgRatio | AM18: 150000 | AN18: 1811041 | AO18: TRUE | AP18: 2811041 | AQ18: TRUE | AR18: 0 | AS18: FALSE | AT18: 0 | AU18: FALSE
A19: 20730203 | B19: 큐브-수 | C19: 207302 | D19: 0 | E19: character_name_20730203 | G19: Normal | H19: Normal | I19: 3 | J19: 1,1,1 | K19: TRUE | L19: 0,0,0 | M19: 2 | N19: Water | O19: Defender | P19: 200 | Q19: {=_xlfn.IFS($O19="Attacker",6,$O19="Healer",3,$O19="Magician",4,$O19="Defender",3,$O19="Supporter",4)} | R19: {=_xlfn.IFS($O19="Attacker",6,$O19="Healer",3,$O19="Magician",4,$O19="Defender",3,$O19="Supporter",4)} | S19: 1 | T19: 0 | U19: 0 | V19: Spd | W19: {=_xlfn.IFS(O19="Attacker",80,O19="Healer",90,O19="Magician",100,O19="Defender",110,O19="Supporter",120)} | X19: Hp | Y19: 36000 | Z19: Atk | AA19: 450 | AB19: Def | AC19: 0 | AD19: Penetration | AE19: 0 | AF19: Hit | AG19: 120 | AH19: Dodge | AI19: 80 | AJ19: CriRatio | AK19: 0 | AL19: CriDmgRatio | AM19: 150000 | AN19: 1821041 | AO19: TRUE | AP19: 2821041 | AQ19: TRUE | AR19: 0 | AS19: FALSE | AT19: 0 | AU19: FALSE
... A141: 11240102 | B141: 이브 | C141: 112411 | D141: 0 | E141: character_name_11240102 | G141: Normal | H141: Normal | I141: 2 | J141: 0.95,0.95,0.95 | K141: TRUE | L141: 0,0,0 | M141: 3 | N141: Water | O141: Attacker | P141: 200 | Q141: {=_xlfn.IFS($O141="Attacker",6,$O141="Healer",3,$O141="Magician",4,$O141="Defender",3,$O141="Supporter",4)} | R141: {=_xlfn.IFS($O141="Attacker",6,$O141="Healer",3,$O141="Magician",4,$O141="Defender",3,$O141="Supporter",4)} | S141: 1 | T141: 0 | U141: 0 | V141: Spd | W141: {=_xlfn.IFS(O141="Attacker",80,O141="Healer",90,O141="Magician",100,O141="Defender",110,O141="Supporter",120)} | X141: Hp | Y141: 2142 | Z141: Atk | AA141: 221 | AB141: Def | AC141: 156 | AD141: Penetration | AE141: 156 | AF141: Hit | AG141: 100 | AH141: Dodge | AI141: 80 | AJ141: CriRatio | AK141: 5000 | AL141: CriDmgRatio | AM141: 150000 | AN141: 1321241 | AO141: TRUE | AP141: 2321241 | AQ141: TRUE | AR141: 3321241 | AS141: TRUE | AT141: 4321241 | AU141: TRUE
A142: 13360102 | B142: 판 | C142: 133611 | D142: 0 | E142: ="character_name_"&A142 | G142: Normal | H142: Normal | I142: 2 | J142: 0.95,0.95,0.95 | K142: TRUE | L142: 0,0,0 | M142: 3 | N142: Forest | O142: Supporter | P142: =100+M142 | Q142: {=_xlfn.IFS($O142="Attacker",6,$O142="Healer",3,$O142="Magician",4,$O142="Defender",3,$O142="Supporter",4)} | R142: {=_xlfn.IFS($O142="Attacker",6,$O142="Healer",3,$O142="Magician",4,$O142="Defender",3,$O142="Supporter",4)} | S142: 1 | T142: 0 | U142: 0 | V142: Spd | W142: {=_xlfn.IFS(O142="Attacker",80,O142="Healer",90,O142="Magician",100,O142="Defender",110,O142="Supporter",120)} | X142: Hp | Y142: =ROUND($Y$16*0.9, 0) | Z142: Atk | AA142: 221 | AB142: Def | AC142: 156 | AD142: Penetration | AE142: =AC142 | AF142: Hit | AG142: 100 | AH142: Dodge | AI142: 100 | AJ142: CriRatio | AK142: 5000 | AL142: CriDmgRatio | AM142: 150000 | AN142: 1535261 | AO142: TRUE | AP142: 2535261 | AQ142: TRUE | AR142: 3535261 | AS142: TRUE | AT142: 4535261 | AU142: TRUE
A143: 14450102 | B143: 카라라트리 | C143: 144511 | D143: 0 | E143: ="character_name_"&A143 | G143: Normal | H143: Normal | I143: 2 | J143: 0.95,0.95,0.95 | K143: TRUE | L143: 0,0,0 | M143: 3 | N143: Fire | O143: Attacker | P143: =100+M143 | Q143: {=_xlfn.IFS($O143="Attacker",6,$O143="Healer",3,$O143="Magician",4,$O143="Defender",3,$O143="Supporter",4)} | R143: {=_xlfn.IFS($O143="Attacker",6,$O143="Healer",3,$O143="Magician",4,$O143="Defender",3,$O143="Supporter",4)} | S143: 1 | T143: 0 | U143: 0 | V143: Spd | W143: {=_xlfn.IFS(O143="Attacker",80,O143="Healer",90,O143="Magician",100,O143="Defender",110,O143="Supporter",120)} | X143: Hp | Y143: =ROUND($Y$16*0.9, 0) | Z143: Atk | AA143: 221 | AB143: Def | AC143: 156 | AD143: Penetration | AE143: =AC143 | AF143: Hit | AG143: 100 | AH143: Dodge | AI143: 100 | AJ143: CriRatio | AK143: 5000 | AL143: CriDmgRatio | AM143: 150000 | AN143: 1513271 | AO143: TRUE | AP143: 2513271 | AQ143: TRUE | AR143: 3513271 | AS143: TRUE | AT143: 4513271 | AU143: TRUE
A144: 14610102 | B144: 아우로라 | C144: 146111 | D144: 0 | E144: ="character_name_"&A144 | G144: Normal | H144: Normal | I144: 2 | J144: 0.95,0.95,0.95 | K144: TRUE | L144: 0,0,0 | M144: 3 | N144: Forest | O144: Supporter | P144: =100+M144 | Q144: {=_xlfn.IFS($O144="Attacker",6,$O144="Healer",3,$O144="Magician",4,$O144="Defender",3,$O144="Supporter",4)} | R144: {=_xlfn.IFS($O144="Attacker",6,$O144="Healer",3,$O144="Magician",4,$O144="Defender",3,$O144="Supporter",4)} | S144: 1 | T144: 0 | U144: 0 | V144: Spd | W144: {=_xlfn.IFS(O144="Attacker",80,O144="Healer",90,O144="Magician",100,O144="Defender",110,O144="Supporter",120)} | X144: Hp | Y144: =ROUND($Y$16*0.9, 0) | Z144: Atk | AA144: 221 | AB144: Def | AC144: 156 | AD144: Penetration | AE144: =AC144 | AF144: Hit | AG144: 100 | AH144: Dodge | AI144: 100 | AJ144: CriRatio | AK144: 5000 | AL144: CriDmgRatio | AM144: 150000 | AN144: 1534281 | AO144: TRUE | AP144: 2534281 | AQ144: TRUE | AR144: 3534281 | AS144: TRUE | AT144: 4534281 | AU144: TRUE
A145: 12830102 | B145: 모건 | C145: 128311 | D145: 0 | E145: ="character_name_"&A145 | G145: Normal | H145: Normal | I145: 2 | J145: 0.95,0.95,0.95 | K145: TRUE | L145: 0,0,0 | M145: 3 | N145: Forest | O145: Supporter | P145: =100+M145 | Q145: {=_xlfn.IFS($O145="Attacker",6,$O145="Healer",3,$O145="Magician",4,$O145="Defender",3,$O145="Supporter",4)} | R145: {=_xlfn.IFS($O145="Attacker",6,$O145="Healer",3,$O145="Magician",4,$O145="Defender",3,$O145="Supporter",4)} | S145: 1 | T145: 0 | U145: 0 | V145: Spd | W145: {=_xlfn.IFS(O145="Attacker",80,O145="Healer",90,O145="Magician",100,O145="Defender",110,O145="Supporter",120)} | X145: Hp | Y145: =ROUND($Y$16*0.9, 0) | Z145: Atk | AA145: 221 | AB145: Def | AC145: 156 | AD145: Penetration | AE145: =AC145 | AF145: Hit | AG145: 100 | AH145: Dodge | AI145: 100 | AJ145: CriRatio | AK145: 5000 | AL145: CriDmgRatio | AM145: 150000 | AN145: 1534281 | AO145: TRUE | AP145: 2534281 | AQ145: TRUE | AR145: 3534281 | AS145: TRUE | AT145: 4534281 | AU145: TRUE
A146: 14000102 | B146: 반시 | C146: 140011 | D146: 0 | E146: ="character_name_"&A146 | G146: Normal | H146: Normal | I146: 2 | J146: 0.95,0.95,0.95 | K146: TRUE | L146: 0,0,0 | M146: 3 | N146: Forest | O146: Supporter | P146: =100+M146 | Q146: {=_xlfn.IFS($O146="Attacker",6,$O146="Healer",3,$O146="Magician",4,$O146="Defender",3,$O146="Supporter",4)} | R146: {=_xlfn.IFS($O146="Attacker",6,$O146="Healer",3,$O146="Magician",4,$O146="Defender",3,$O146="Supporter",4)} | S146: 1 | T146: 0 | U146: 0 | V146: Spd | W146: {=_xlfn.IFS(O146="Attacker",80,O146="Healer",90,O146="Magician",100,O146="Defender",110,O146="Supporter",120)} | X146: Hp | Y146: =ROUND($Y$16*0.9, 0) | Z146: Atk | AA146: 221 | AB146: Def | AC146: 156 | AD146: Penetration | AE146: =AC146 | AF146: Hit | AG146: 100 | AH146: Dodge | AI146: 100 | AJ146: CriRatio | AK146: 5000 | AL146: CriDmgRatio | AM146: 150000 | AN146: 1534281 | AO146: TRUE | AP146: 2534281 | AQ146: TRUE | AR146: 3534281 | AS146: TRUE | AT146: 4534281 | AU146: TRUE
