Workbook

Sheet Base
A1: Id | B1: ChildId | C1: Name | D1: Atlas | E1: Icon | F1: #이름 | G1: #Element | H1: #Role | I1: #TalentGrade | J1: #ChildGrade | K1: CommonGrade | L1: #TierId | M1: PersonaGrade | N1: DevilStat | O1: Value | P1: ChildStat | Q1: RandomRange | R1: #min | S1: #max | T1: ChildStat | U1: RandomRange | V1: #min | W1: #max | X1: ChildStat | Y1: RandomRange | Z1: #min | AA1: #max | AB1: ContractProb | AC1: #차일드 | AD1: #등급차일드 | AE1: TalentGroup
A4: =INT(1&TEXT(RIGHT(B4,4),"0000")&TEXT(L4,"000")) -> 10354000 | B4: 10000354 | C4: ui_persona | D4: PersonaPortrait | E4: ="Persona_"&_xlfn.XLOOKUP($B4, '#캐릭터'!$A:$A, '#캐릭터'!$C:$C) -> Persona_c354 | G4: =_xlfn.XLOOKUP(_xlfn.XLOOKUP(B4,'[1]Detail<Child>'!$A:$A,'[1]Detail<Child>'!$N:$N),'#참조'!P:P,'#참조'!Q:Q) -> 1 | H4: =_xlfn.XLOOKUP(_xlfn.XLOOKUP(B4,'[1]Detail<Child>'!$A:$A,'[1]Detail<Child>'!$O:$O),'#참조'!R:R,'#참조'!S:S) -> 1 | I4: 0 | J4: 3 | K4: 0 | L4: 0 | M4: Default | N4: DevilSkillDmgRatio | O4: 0 | P4: SoulHp | Q4: =R4&","&S4 -> 1000,1000 | R4: 1000 | S4: =R4 -> 1000 | T4: SoulAtk | U4: =V4&","&W4 -> 100,100 | V4: 100 | W4: =V4 -> 100 | X4: SoulDef | Y4: =Z4&","&AA4 -> 80,80 | Z4: 80 | AA4: =Z4 -> 80 | AB4: 100000 | AE4: =IF(I4=0,0,INT(G4&H4&TEXT(I4,"00"))) -> 0
A5: =INT(1&TEXT(RIGHT(B5,4),"0000")&TEXT(L5,"000")) -> 10354001 | B5: 10000354 | C5: ui_persona | D5: PersonaPortrait | E5: ="Persona_"&_xlfn.XLOOKUP($B5, '#캐릭터'!$A:$A, '#캐릭터'!$C:$C) -> Persona_c354 | G5: =_xlfn.XLOOKUP(_xlfn.XLOOKUP(B5,'[1]Detail<Child>'!$A:$A,'[1]Detail<Child>'!$N:$N),'#참조'!P:P,'#참조'!Q:Q) -> 1 | H5: =_xlfn.XLOOKUP(_xlfn.XLOOKUP(B5,'[1]Detail<Child>'!$A:$A,'[1]Detail<Child>'!$O:$O),'#참조'!R:R,'#참조'!S:S) -> 1 | I5: 0 | J5: 3 | K5: 1 | L5: 1 | M5: Common1 | N5: DevilSkillDmgRatio | O5: 2000 | P5: SoulHp | Q5: =R5&","&S5 -> 1000,1200 | R5: 1000 | S5: =ROUND(R5*1.2, -2) -> 1200 | T5: SoulAtk | U5: =V5&","&W5 -> 100,100 | V5: 100 | W5: =ROUND(V5*1.2, -2) -> 100 | X5: SoulDef | Y5: =Z5&","&AA5 -> 80,100 | Z5: 80 | AA5: =ROUND(Z5*1.2, -2) -> 100 | AB5: 100000 | AC5: =_xlfn.XLOOKUP($B5, '#참조'!$M:$M, '#참조'!$N:$N) -> #N/A | AD5: =M5&"_"&AC5 -> #N/A | AE5: =IF(I5=0,0,INT(G5&H5&TEXT(I5,"00"))) -> 0
A6: =INT(1&TEXT(RIGHT(B6,4),"0000")&TEXT(L6,"000")) -> 10354002 | B6: 10000354 | C6: ui_persona | D6: PersonaPortrait | E6: ="Persona_"&_xlfn.XLOOKUP($B6, '#캐릭터'!$A:$A, '#캐릭터'!$C:$C) -> Persona_c354 | G6: =_xlfn.XLOOKUP(_xlfn.XLOOKUP(B6,'[1]Detail<Child>'!$A:$A,'[1]Detail<Child>'!$N:$N),'#참조'!P:P,'#참조'!Q:Q) -> 1 | H6: =_xlfn.XLOOKUP(_xlfn.XLOOKUP(B6,'[1]Detail<Child>'!$A:$A,'[1]Detail<Child>'!$O:$O),'#참조'!R:R,'#참조'!S:S) -> 1 | I6: 0 | J6: 3 | K6: 1 | L6: 2 | M6: Common2 | N6: DevilSkillDmgRatio | O6: =ROUND(O5*1.1, 0) -> 2200 | P6: SoulHp | Q6: =R6&","&S6 -> 1300,1600 | R6: =ROUND(R5*1.3, 0) -> 1300 | S6: =ROUND(R6*1.2, -2) -> 1600 | T6: SoulAtk | U6: =V6&","&W6 -> 120,100 | V6: =ROUND(V5*1.2, 0) -> 120 | W6: =ROUND(V6*1.2, -2) -> 100 | X6: SoulDef | Y6: =Z6&","&AA6 -> 104,100 | Z6: =ROUND(Z5*1.3, 0) -> 104 | AA6: =ROUND(Z6*1.2, -2) -> 100 | AB6: 100000 | AC6: =_xlfn.XLOOKUP($B6, '#참조'!$M:$M, '#참조'!$N:$N) -> #N/A | AD6: =M6&"_"&AC6 -> #N/A | AE6: =IF(I6=0,0,INT(G6&H6&TEXT(I6,"00"))) -> 0
A7: =INT(1&TEXT(RIGHT(B7,4),"0000")&TEXT(L7,"000")) -> 10354003 | B7: 10000354 | C7: ui_persona | D7: PersonaPortrait | E7: ="Persona_"&_xlfn.XLOOKUP($B7, '#캐릭터'!$A:$A, '#캐릭터'!$C:$C) -> Persona_c354 | G7: =_xlfn.XLOOKUP(_xlfn.XLOOKUP(B7,'[1]Detail<Child>'!$A:$A,'[1]Detail<Child>'!$N:$N),'#참조'!P:P,'#참조'!Q:Q) -> 1 | H7: =_xlfn.XLOOKUP(_xlfn.XLOOKUP(B7,'[1]Detail<Child>'!$A:$A,'[1]Detail<Child>'!$O:$O),'#참조'!R:R,'#참조'!S:S) -> 1 | I7: 0 | J7: 3 | K7: 1 | L7: 3 | M7: Common3 | N7: DevilSkillDmgRatio | O7: =ROUND(O6*1.1, 0) -> 2420 | P7: SoulHp | Q7: =R7&","&S7 -> 1690,2000 | R7: =ROUND(R6*1.3, 0) -> 1690 | S7: =ROUND(R7*1.2, -2) -> 2000 | T7: SoulAtk | U7: =V7&","&W7 -> 144,200 | V7: =ROUND(V6*1.2, 0) -> 144 | W7: =ROUND(V7*1.2, -2) -> 200 | X7: SoulDef | Y7: =Z7&","&AA7 -> 135,200 | Z7: =ROUND(Z6*1.3, 0) -> 135 | AA7: =ROUND(Z7*1.2, -2) -> 200 | AB7: 100000 | AC7: =_xlfn.XLOOKUP($B7, '#참조'!$M:$M, '#참조'!$N:$N) -> #N/A | AD7: =M7&"_"&AC7 -> #N/A | AE7: =IF(I7=0,0,INT(G7&H7&TEXT(I7,"00"))) -> 0
A8: =INT(1&TEXT(RIGHT(B8,4),"0000")&TEXT(L8,"000")) -> 10354004 | B8: 10000354 | C8: ui_persona | D8: PersonaPortrait | E8: ="Persona_"&_xlfn.XLOOKUP($B8, '#캐릭터'!$A:$A, '#캐릭터'!$C:$C) -> Persona_c354 | G8: =_xlfn.XLOOKUP(_xlfn.XLOOKUP(B8,'[1]Detail<Child>'!$A:$A,'[1]Detail<Child>'!$N:$N),'#참조'!P:P,'#참조'!Q:Q) -> 1 | H8: =_xlfn.XLOOKUP(_xlfn.XLOOKUP(B8,'[1]Detail<Child>'!$A:$A,'[1]Detail<Child>'!$O:$O),'#참조'!R:R,'#참조'!S:S) -> 1 | I8: 0 | J8: 3 | K8: 2 | L8: 4 | M8: Uncommon1 | N8: DevilSkillDmgRatio | O8: =ROUND(O7*1.1, 0) -> 2662 | P8: SoulHp | Q8: =R8&","&S8 -> 2197,2600 | R8: =ROUND(R7*1.3, 0) -> 2197 | S8: =ROUND(R8*1.2, -2) -> 2600 | T8: SoulAtk | U8: =V8&","&W8 -> 173,200 | V8: =ROUND(V7*1.2, 0) -> 173 | W8: =ROUND(V8*1.2, -2) -> 200 | X8: SoulDef | Y8: =Z8&","&AA8 -> 176,200 | Z8: =ROUND(Z7*1.3, 0) -> 176 | AA8: =ROUND(Z8*1.2, -2) -> 200 | AB8: 95000 | AC8: =_xlfn.XLOOKUP($B8, '#참조'!$M:$M, '#참조'!$N:$N) -> #N/A | AD8: =M8&"_"&AC8 -> #N/A | AE8: =IF(I8=0,0,INT(G8&H8&TEXT(I8,"00"))) -> 0
A9: =INT(1&TEXT(RIGHT(B9,4),"0000")&TEXT(L9,"000")) -> 10354005 | B9: 10000354 | C9: ui_persona | D9: PersonaPortrait | E9: ="Persona_"&_xlfn.XLOOKUP($B9, '#캐릭터'!$A:$A, '#캐릭터'!$C:$C) -> Persona_c354 | G9: =_xlfn.XLOOKUP(_xlfn.XLOOKUP(B9,'[1]Detail<Child>'!$A:$A,'[1]Detail<Child>'!$N:$N),'#참조'!P:P,'#참조'!Q:Q) -> 1 | H9: =_xlfn.XLOOKUP(_xlfn.XLOOKUP(B9,'[1]Detail<Child>'!$A:$A,'[1]Detail<Child>'!$O:$O),'#참조'!R:R,'#참조'!S:S) -> 1 | I9: 0 | J9: 3 | K9: 2 | L9: 5 | M9: Uncommon2 | N9: DevilSkillDmgRatio | O9: =ROUND(O8*1.1, 0) -> 2928 | P9: SoulHp | Q9: =R9&","&S9 -> 2856,3400 | R9: =ROUND(R8*1.3, 0) -> 2856 | S9: =ROUND(R9*1.2, -2) -> 3400 | T9: SoulAtk | U9: =V9&","&W9 -> 208,200 | V9: =ROUND(V8*1.2, 0) -> 208 | W9: =ROUND(V9*1.2, -2) -> 200 | X9: SoulDef | Y9: =Z9&","&AA9 -> 229,300 | Z9: =ROUND(Z8*1.3, 0) -> 229 | AA9: =ROUND(Z9*1.2, -2) -> 300 | AB9: 95000 | AC9: =_xlfn.XLOOKUP($B9, '#참조'!$M:$M, '#참조'!$N:$N) -> #N/A | AD9: =M9&"_"&AC9 -> #N/A | AE9: =IF(I9=0,0,INT(G9&H9&TEXT(I9,"00"))) -> 0
A10: =INT(1&TEXT(RIGHT(B10,4),"0000")&TEXT(L10,"000")) -> 10354006 | B10: 10000354 | C10: ui_persona | D10: PersonaPortrait | E10: ="Persona_"&_xlfn.XLOOKUP($B10, '#캐릭터'!$A:$A, '#캐릭터'!$C:$C) -> Persona_c354 | G10: =_xlfn.XLOOKUP(_xlfn.XLOOKUP(B10,'[1]Detail<Child>'!$A:$A,'[1]Detail<Child>'!$N:$N),'#참조'!P:P,'#참조'!Q:Q) -> 1 | H10: =_xlfn.XLOOKUP(_xlfn.XLOOKUP(B10,'[1]Detail<Child>'!$A:$A,'[1]Detail<Child>'!$O:$O),'#참조'!R:R,'#참조'!S:S) -> 1 | I10: 0 | J10: 3 | K10: 2 | L10: 6 | M10: Uncommon3 | N10: DevilSkillDmgRatio | O10: =ROUND(O9*1.1, 0) -> 3221 | P10: SoulHp | Q10: =R10&","&S10 -> 3713,4500 | R10: =ROUND(R9*1.3, 0) -> 3713 | S10: =ROUND(R10*1.2, -2) -> 4500 | T10: SoulAtk | U10: =V10&","&W10 -> 250,300 | V10: =ROUND(V9*1.2, 0) -> 250 | W10: =ROUND(V10*1.2, -2) -> 300 | X10: SoulDef | Y10: =Z10&","&AA10 -> 298,400 | Z10: =ROUND(Z9*1.3, 0) -> 298 | AA10: =ROUND(Z10*1.2, -2) -> 400 | AB10: 95000 | AC10: =_xlfn.XLOOKUP($B10, '#참조'!$M:$M, '#참조'!$N:$N) -> #N/A | AD10: =M10&"_"&AC10 -> #N/A | AE10: =IF(I10=0,0,INT(G10&H10&TEXT(I10,"00"))) -> 0
A11: =INT(1&TEXT(RIGHT(B11,4),"0000")&TEXT(L11,"000")) -> 10354007 | B11: 10000354 | C11: ui_persona | D11: PersonaPortrait | E11: ="Persona_"&_xlfn.XLOOKUP($B11, '#캐릭터'!$A:$A, '#캐릭터'!$C:$C) -> Persona_c354 | G11: =_xlfn.XLOOKUP(_xlfn.XLOOKUP(B11,'[1]Detail<Child>'!$A:$A,'[1]Detail<Child>'!$N:$N),'#참조'!P:P,'#참조'!Q:Q) -> 1 | H11: =_xlfn.XLOOKUP(_xlfn.XLOOKUP(B11,'[1]Detail<Child>'!$A:$A,'[1]Detail<Child>'!$O:$O),'#참조'!R:R,'#참조'!S:S) -> 1 | I11: 1 | J11: 3 | K11: 3 | L11: 7 | M11: Rare1 | N11: DevilSkillDmgRatio | O11: =ROUND(O10*1.1, 0) -> 3543 | P11: SoulHp | Q11: =R11&","&S11 -> 4827,5800 | R11: =ROUND(R10*1.3, 0) -> 4827 | S11: =ROUND(R11*1.2, -2) -> 5800 | T11: SoulAtk | U11: =V11&","&W11 -> 300,400 | V11: =ROUND(V10*1.2, 0) -> 300 | W11: =ROUND(V11*1.2, -2) -> 400 | X11: SoulDef | Y11: =Z11&","&AA11 -> 387,500 | Z11: =ROUND(Z10*1.3, 0) -> 387 | AA11: =ROUND(Z11*1.2, -2) -> 500 | AB11: 90000 | AC11: =_xlfn.XLOOKUP($B11, '#참조'!$M:$M, '#참조'!$N:$N) -> #N/A | AD11: =M11&"_"&AC11 -> #N/A | AE11: =IF(I11=0,0,INT(G11&H11&TEXT(I11,"00"))) -> 1101
A12: =INT(1&TEXT(RIGHT(B12,4),"0000")&TEXT(L12,"000")) -> 10354008 | B12: 10000354 | C12: ui_persona | D12: PersonaPortrait | E12: ="Persona_"&_xlfn.XLOOKUP($B12, '#캐릭터'!$A:$A, '#캐릭터'!$C:$C) -> Persona_c354 | G12: =_xlfn.XLOOKUP(_xlfn.XLOOKUP(B12,'[1]Detail<Child>'!$A:$A,'[1]Detail<Child>'!$N:$N),'#참조'!P:P,'#참조'!Q:Q) -> 1 | H12: =_xlfn.XLOOKUP(_xlfn.XLOOKUP(B12,'[1]Detail<Child>'!$A:$A,'[1]Detail<Child>'!$O:$O),'#참조'!R:R,'#참조'!S:S) -> 1 | I12: 1 | J12: 3 | K12: 3 | L12: 8 | M12: Rare2 | N12: DevilSkillDmgRatio | O12: =ROUND(O11*1.1, 0) -> 3897 | P12: SoulHp | Q12: =R12&","&S12 -> 6275,7500 | R12: =ROUND(R11*1.3, 0) -> 6275 | S12: =ROUND(R12*1.2, -2) -> 7500 | T12: SoulAtk | U12: =V12&","&W12 -> 360,400 | V12: =ROUND(V11*1.2, 0) -> 360 | W12: =ROUND(V12*1.2, -2) -> 400 | X12: SoulDef | Y12: =Z12&","&AA12 -> 503,600 | Z12: =ROUND(Z11*1.3, 0) -> 503 | AA12: =ROUND(Z12*1.2, -2) -> 600 | AB12: 90000 | AC12: =_xlfn.XLOOKUP($B12, '#참조'!$M:$M, '#참조'!$N:$N) -> #N/A | AD12: =M12&"_"&AC12 -> #N/A | AE12: =IF(I12=0,0,INT(G12&H12&TEXT(I12,"00"))) -> 1101
A13: =INT(1&TEXT(RIGHT(B13,4),"0000")&TEXT(L13,"000")) -> 10354009 | B13: 10000354 | C13: ui_persona | D13: PersonaPortrait | E13: ="Persona_"&_xlfn.XLOOKUP($B13, '#캐릭터'!$A:$A, '#캐릭터'!$C:$C) -> Persona_c354 | G13: =_xlfn.XLOOKUP(_xlfn.XLOOKUP(B13,'[1]Detail<Child>'!$A:$A,'[1]Detail<Child>'!$N:$N),'#참조'!P:P,'#참조'!Q:Q) -> 1 | H13: =_xlfn.XLOOKUP(_xlfn.XLOOKUP(B13,'[1]Detail<Child>'!$A:$A,'[1]Detail<Child>'!$O:$O),'#참조'!R:R,'#참조'!S:S) -> 1 | I13: 2 | J13: 3 | K13: 3 | L13: 9 | M13: Rare3 | N13: DevilSkillDmgRatio | O13: =ROUND(O12*1.1, 0) -> 4287 | P13: SoulHp | Q13: =R13&","&S13 -> 8158,9800 | R13: =ROUND(R12*1.3, 0) -> 8158 | S13: =ROUND(R13*1.2, -2) -> 9800 | T13: SoulAtk | U13: =V13&","&W13 -> 432,500 | V13: =ROUND(V12*1.2, 0) -> 432 | W13: =ROUND(V13*1.2, -2) -> 500 | X13: SoulDef | Y13: =Z13&","&AA13 -> 654,800 | Z13: =ROUND(Z12*1.3, 0) -> 654 | AA13: =ROUND(Z13*1.2, -2) -> 800 | AB13: 90000 | AC13: =_xlfn.XLOOKUP($B13, '#참조'!$M:$M, '#참조'!$N:$N) -> #N/A | AD13: =M13&"_"&AC13 -> #N/A | AE13: =IF(I13=0,0,INT(G13&H13&TEXT(I13,"00"))) -> 1102
A14: =INT(1&TEXT(RIGHT(B14,4),"0000")&TEXT(L14,"000")) -> 10354010 | B14: 10000354 | C14: ui_persona | D14: PersonaPortrait | E14: ="Persona_"&_xlfn.XLOOKUP($B14, '#캐릭터'!$A:$A, '#캐릭터'!$C:$C) -> Persona_c354 | G14: =_xlfn.XLOOKUP(_xlfn.XLOOKUP(B14,'[1]Detail<Child>'!$A:$A,'[1]Detail<Child>'!$N:$N),'#참조'!P:P,'#참조'!Q:Q) -> 1 | H14: =_xlfn.XLOOKUP(_xlfn.XLOOKUP(B14,'[1]Detail<Child>'!$A:$A,'[1]Detail<Child>'!$O:$O),'#참조'!R:R,'#참조'!S:S) -> 1 | I14: 2 | J14: 3 | K14: 4 | L14: 10 | M14: Unique1 | N14: DevilSkillDmgRatio | O14: =ROUND(O13*1.1, 0) -> 4716 | P14: SoulHp | Q14: =R14&","&S14 -> 10605,12700 | R14: =ROUND(R13*1.3, 0) -> 10605 | S14: =ROUND(R14*1.2, -2) -> 12700 | T14: SoulAtk | U14: =V14&","&W14 -> 518,600 | V14: =ROUND(V13*1.2, 0) -> 518 | W14: =ROUND(V14*1.2, -2) -> 600 | X14: SoulDef | Y14: =Z14&","&AA14 -> 850,1000 | Z14: =ROUND(Z13*1.3, 0) -> 850 | AA14: =ROUND(Z14*1.2, -2) -> 1000 | AB14: 85000 | AC14: =_xlfn.XLOOKUP($B14, '#참조'!$M:$M, '#참조'!$N:$N) -> #N/A | AD14: =M14&"_"&AC14 -> #N/A | AE14: =IF(I14=0,0,INT(G14&H14&TEXT(I14,"00"))) -> 1102
A15: =INT(1&TEXT(RIGHT(B15,4),"0000")&TEXT(L15,"000")) -> 10354011 | B15: 10000354 | C15: ui_persona | D15: PersonaPortrait | E15: ="Persona_"&_xlfn.XLOOKUP($B15, '#캐릭터'!$A:$A, '#캐릭터'!$C:$C) -> Persona_c354 | G15: =_xlfn.XLOOKUP(_xlfn.XLOOKUP(B15,'[1]Detail<Child>'!$A:$A,'[1]Detail<Child>'!$N:$N),'#참조'!P:P,'#참조'!Q:Q) -> 1 | H15: =_xlfn.XLOOKUP(_xlfn.XLOOKUP(B15,'[1]Detail<Child>'!$A:$A,'[1]Detail<Child>'!$O:$O),'#참조'!R:R,'#참조'!S:S) -> 1 | I15: 3 | J15: 3 | K15: 4 | L15: 11 | M15: Unique2 | N15: DevilSkillDmgRatio | O15: =ROUND(O14*1.1, 0) -> 5188 | P15: SoulHp | Q15: =R15&","&S15 -> 13787,16500 | R15: =ROUND(R14*1.3, 0) -> 13787 | S15: =ROUND(R15*1.2, -2) -> 16500 | T15: SoulAtk | U15: =V15&","&W15 -> 622,700 | V15: =ROUND(V14*1.2, 0) -> 622 | W15: =ROUND(V15*1.2, -2) -> 700 | X15: SoulDef | Y15: =Z15&","&AA15 -> 1105,1300 | Z15: =ROUND(Z14*1.3, 0) -> 1105 | AA15: =ROUND(Z15*1.2, -2) -> 1300 | AB15: 85000 | AC15: =_xlfn.XLOOKUP($B15, '#참조'!$M:$M, '#참조'!$N:$N) -> #N/A | AD15: =M15&"_"&AC15 -> #N/A | AE15: =IF(I15=0,0,INT(G15&H15&TEXT(I15,"00"))) -> 1103
A16: =INT(1&TEXT(RIGHT(B16,4),"0000")&TEXT(L16,"000")) -> 10354012 | B16: 10000354 | C16: ui_persona | D16: PersonaPortrait | E16: ="Persona_"&_xlfn.XLOOKUP($B16, '#캐릭터'!$A:$A, '#캐릭터'!$C:$C) -> Persona_c354 | G16: =_xlfn.XLOOKUP(_xlfn.XLOOKUP(B16,'[1]Detail<Child>'!$A:$A,'[1]Detail<Child>'!$N:$N),'#참조'!P:P,'#참조'!Q:Q) -> 1 | H16: =_xlfn.XLOOKUP(_xlfn.XLOOKUP(B16,'[1]Detail<Child>'!$A:$A,'[1]Detail<Child>'!$O:$O),'#참조'!R:R,'#참조'!S:S) -> 1 | I16: 3 | J16: 3 | K16: 4 | L16: 12 | M16: Unique3 | N16: DevilSkillDmgRatio | O16: =ROUND(O15*1.1, 0) -> 5707 | P16: SoulHp | Q16: =R16&","&S16 -> 17923,21500 | R16: =ROUND(R15*1.3, 0) -> 17923 | S16: =ROUND(R16*1.2, -2) -> 21500 | T16: SoulAtk | U16: =V16&","&W16 -> 746,900 | V16: =ROUND(V15*1.2, 0) -> 746 | W16: =ROUND(V16*1.2, -2) -> 900 | X16: SoulDef | Y16: =Z16&","&AA16 -> 1437,1700 | Z16: =ROUND(Z15*1.3, 0) -> 1437 | AA16: =ROUND(Z16*1.2, -2) -> 1700 | AB16: 85000 | AC16: =_xlfn.XLOOKUP($B16, '#참조'!$M:$M, '#참조'!$N:$N) -> #N/A | AD16: =M16&"_"&AC16 -> #N/A | AE16: =IF(I16=0,0,INT(G16&H16&TEXT(I16,"00"))) -> 1103
A17: =INT(1&TEXT(RIGHT(B17,4),"0000")&TEXT(L17,"000")) -> 10354013 | B17: 10000354 | C17: ui_persona | D17: PersonaPortrait | E17: ="Persona_"&_xlfn.XLOOKUP($B17, '#캐릭터'!$A:$A, '#캐릭터'!$C:$C) -> Persona_c354 | G17: =_xlfn.XLOOKUP(_xlfn.XLOOKUP(B17,'[1]Detail<Child>'!$A:$A,'[1]Detail<Child>'!$N:$N),'#참조'!P:P,'#참조'!Q:Q) -> 1 | H17: =_xlfn.XLOOKUP(_xlfn.XLOOKUP(B17,'[1]Detail<Child>'!$A:$A,'[1]Detail<Child>'!$O:$O),'#참조'!R:R,'#참조'!S:S) -> 1 | I17: 4 | J17: 3 | K17: 5 | L17: 13 | M17: Epic1 | N17: DevilSkillDmgRatio | O17: =ROUND(O16*1.1, 0) -> 6278 | P17: SoulHp | Q17: =R17&","&S17 -> 23300,28000 | R17: =ROUND(R16*1.3, 0) -> 23300 | S17: =ROUND(R17*1.2, -2) -> 28000 | T17: SoulAtk | U17: =V17&","&W17 -> 895,1100 | V17: =ROUND(V16*1.2, 0) -> 895 | W17: =ROUND(V17*1.2, -2) -> 1100 | X17: SoulDef | Y17: =Z17&","&AA17 -> 1868,2200 | Z17: =ROUND(Z16*1.3, 0) -> 1868 | AA17: =ROUND(Z17*1.2, -2) -> 2200 | AB17: 80000 | AC17: =_xlfn.XLOOKUP($B17, '#참조'!$M:$M, '#참조'!$N:$N) -> #N/A | AD17: =M17&"_"&AC17 -> #N/A | AE17: =IF(I17=0,0,INT(G17&H17&TEXT(I17,"00"))) -> 1104
... A22: =INT(1&TEXT(RIGHT(B22,4),"0000")&TEXT(L22,"000")) -> 10354018 | B22: 10000354 | C22: ui_persona | D22: PersonaPortrait | E22: ="Persona_"&_xlfn.XLOOKUP($B22, '#캐릭터'!$A:$A, '#캐릭터'!$C:$C) -> Persona_c354 | G22: =_xlfn.XLOOKUP(_xlfn.XLOOKUP(B22,'[1]Detail<Child>'!$A:$A,'[1]Detail<Child>'!$N:$N),'#참조'!P:P,'#참조'!Q:Q) -> 1 | H22: =_xlfn.XLOOKUP(_xlfn.XLOOKUP(B22,'[1]Detail<Child>'!$A:$A,'[1]Detail<Child>'!$O:$O),'#참조'!R:R,'#참조'!S:S) -> 1 | I22: 6 | J22: 3 | K22: 6 | L22: 18 | M22: Legendary3 | N22: DevilSkillDmgRatio | O22: =ROUND(O21*1.1, 0) -> 10112 | P22: SoulHp | Q22: =R22&","&S22 -> 86511,103800 | R22: =ROUND(R21*1.3, 0) -> 86511 | S22: =ROUND(R22*1.2, -2) -> 103800 | T22: SoulAtk | U22: =V22&","&W22 -> 2227,2700 | V22: =ROUND(V21*1.2, 0) -> 2227 | W22: =ROUND(V22*1.2, -2) -> 2700 | X22: SoulDef | Y22: =Z22&","&AA22 -> 6934,8300 | Z22: =ROUND(Z21*1.3, 0) -> 6934 | AA22: =ROUND(Z22*1.2, -2) -> 8300 | AB22: 75000 | AC22: =_xlfn.XLOOKUP($B22, '#참조'!$M:$M, '#참조'!$N:$N) -> #N/A | AD22: =M22&"_"&AC22 -> #N/A | AE22: =IF(I22=0,0,INT(G22&H22&TEXT(I22,"00"))) -> 1106
A23: =INT(1&TEXT(RIGHT(B23,4),"0000")&TEXT(L23,"000")) -> 10296000 | B23: 10000296 | C23: ui_persona | D23: PersonaPortrait | E23: ="Persona_"&_xlfn.XLOOKUP($B23, '#캐릭터'!$A:$A, '#캐릭터'!$C:$C) -> Persona_c296 | G23: =_xlfn.XLOOKUP(_xlfn.XLOOKUP(B23,'[1]Detail<Child>'!$A:$A,'[1]Detail<Child>'!$N:$N),'#참조'!P:P,'#참조'!Q:Q) -> 4 | H23: =_xlfn.XLOOKUP(_xlfn.XLOOKUP(B23,'[1]Detail<Child>'!$A:$A,'[1]Detail<Child>'!$O:$O),'#참조'!R:R,'#참조'!S:S) -> 1 | I23: 0 | J23: 3 | K23: 0 | L23: 0 | M23: Default | N23: DevilSkillDmgRatio | O23: 0 | P23: SoulHp | Q23: =R23&","&S23 -> 1000,1000 | R23: 1000 | S23: =R23 -> 1000 | T23: SoulAtk | U23: =V23&","&W23 -> 100,100 | V23: 100 | W23: =V23 -> 100 | X23: SoulDef | Y23: =Z23&","&AA23 -> 80,80 | Z23: 80 | AA23: =Z23 -> 80 | AB23: 100000 | AE23: =IF(I23=0,0,INT(G23&H23&TEXT(I23,"00"))) -> 0
A24: =INT(1&TEXT(RIGHT(B24,4),"0000")&TEXT(L24,"000")) -> 10296001 | B24: 10000296 | C24: ui_persona | D24: PersonaPortrait | E24: ="Persona_"&_xlfn.XLOOKUP($B24, '#캐릭터'!$A:$A, '#캐릭터'!$C:$C) -> Persona_c296 | G24: =_xlfn.XLOOKUP(_xlfn.XLOOKUP(B24,'[1]Detail<Child>'!$A:$A,'[1]Detail<Child>'!$N:$N),'#참조'!P:P,'#참조'!Q:Q) -> 4 | H24: =_xlfn.XLOOKUP(_xlfn.XLOOKUP(B24,'[1]Detail<Child>'!$A:$A,'[1]Detail<Child>'!$O:$O),'#참조'!R:R,'#참조'!S:S) -> 1 | I24: 0 | J24: 3 | K24: 1 | L24: 1 | M24: Common1 | N24: DevilSkillDmgRatio | O24: 2000 | P24: SoulHp | Q24: =R24&","&S24 -> 1000,1200 | R24: 1000 | S24: =ROUND(R24*1.2, -2) -> 1200 | T24: SoulAtk | U24: =V24&","&W24 -> 100,100 | V24: 100 | W24: =ROUND(V24*1.2, -2) -> 100 | X24: SoulDef | Y24: =Z24&","&AA24 -> 80,100 | Z24: 80 | AA24: =ROUND(Z24*1.2, -2) -> 100 | AB24: 100000 | AC24: =_xlfn.XLOOKUP($B24, '#참조'!$M:$M, '#참조'!$N:$N) -> #N/A | AD24: =M24&"_"&AC24 -> #N/A | AE24: =IF(I24=0,0,INT(G24&H24&TEXT(I24,"00"))) -> 0
A25: =INT(1&TEXT(RIGHT(B25,4),"0000")&TEXT(L25,"000")) -> 10296002 | B25: 10000296 | C25: ui_persona | D25: PersonaPortrait | E25: ="Persona_"&_xlfn.XLOOKUP($B25, '#캐릭터'!$A:$A, '#캐릭터'!$C:$C) -> Persona_c296 | G25: =_xlfn.XLOOKUP(_xlfn.XLOOKUP(B25,'[1]Detail<Child>'!$A:$A,'[1]Detail<Child>'!$N:$N),'#참조'!P:P,'#참조'!Q:Q) -> 4 | H25: =_xlfn.XLOOKUP(_xlfn.XLOOKUP(B25,'[1]Detail<Child>'!$A:$A,'[1]Detail<Child>'!$O:$O),'#참조'!R:R,'#참조'!S:S) -> 1 | I25: 0 | J25: 3 | K25: 1 | L25: 2 | M25: Common2 | N25: DevilSkillDmgRatio | O25: =ROUND(O24*1.1, 0) -> 2200 | P25: SoulHp | Q25: =R25&","&S25 -> 1300,1600 | R25: =ROUND(R24*1.3, 0) -> 1300 | S25: =ROUND(R25*1.2, -2) -> 1600 | T25: SoulAtk | U25: =V25&","&W25 -> 120,100 | V25: =ROUND(V24*1.2, 0) -> 120 | W25: =ROUND(V25*1.2, -2) -> 100 | X25: SoulDef | Y25: =Z25&","&AA25 -> 104,100 | Z25: =ROUND(Z24*1.3, 0) -> 104 | AA25: =ROUND(Z25*1.2, -2) -> 100 | AB25: 100000 | AC25: =_xlfn.XLOOKUP($B25, '#참조'!$M:$M, '#참조'!$N:$N) -> #N/A | AD25: =M25&"_"&AC25 -> #N/A | AE25: =IF(I25=0,0,INT(G25&H25&TEXT(I25,"00"))) -> 0
A26: =INT(1&TEXT(RIGHT(B26,4),"0000")&TEXT(L26,"000")) -> 10296003 | B26: 10000296 | C26: ui_persona | D26: PersonaPortrait | E26: ="Persona_"&_xlfn.XLOOKUP($B26, '#캐릭터'!$A:$A, '#캐릭터'!$C:$C) -> Persona_c296 | G26: =_xlfn.XLOOKUP(_xlfn.XLOOKUP(B26,'[1]Detail<Child>'!$A:$A,'[1]Detail<Child>'!$N:$N),'#참조'!P:P,'#참조'!Q:Q) -> 4 | H26: =_xlfn.XLOOKUP(_xlfn.XLOOKUP(B26,'[1]Detail<Child>'!$A:$A,'[1]Detail<Child>'!$O:$O),'#참조'!R:R,'#참조'!S:S) -> 1 | I26: 0 | J26: 3 | K26: 1 | L26: 3 | M26: Common3 | N26: DevilSkillDmgRatio | O26: =ROUND(O25*1.1, 0) -> 2420 | P26: SoulHp | Q26: =R26&","&S26 -> 1690,2000 | R26: =ROUND(R25*1.3, 0) -> 1690 | S26: =ROUND(R26*1.2, -2) -> 2000 | T26: SoulAtk | U26: =V26&","&W26 -> 144,200 | V26: =ROUND(V25*1.2, 0) -> 144 | W26: =ROUND(V26*1.2, -2) -> 200 | X26: SoulDef | Y26: =Z26&","&AA26 -> 135,200 | Z26: =ROUND(Z25*1.3, 0) -> 135 | AA26: =ROUND(Z26*1.2, -2) -> 200 | AB26: 100000 | AC26: =_xlfn.XLOOKUP($B26, '#참조'!$M:$M, '#참조'!$N:$N) -> #N/A | AD26: =M26&"_"&AC26 -> #N/A | AE26: =IF(I26=0,0,INT(G26&H26&TEXT(I26,"00"))) -> 0
A27: =INT(1&TEXT(RIGHT(B27,4),"0000")&TEXT(L27,"000")) -> 10296004 | B27: 10000296 | C27: ui_persona | D27: PersonaPortrait | E27: ="Persona_"&_xlfn.XLOOKUP($B27, '#캐릭터'!$A:$A, '#캐릭터'!$C:$C) -> Persona_c296 | G27: =_xlfn.XLOOKUP(_xlfn.XLOOKUP(B27,'[1]Detail<Child>'!$A:$A,'[1]Detail<Child>'!$N:$N),'#참조'!P:P,'#참조'!Q:Q) -> 4 | H27: =_xlfn.XLOOKUP(_xlfn.XLOOKUP(B27,'[1]Detail<Child>'!$A:$A,'[1]Detail<Child>'!$O:$O),'#참조'!R:R,'#참조'!S:S) -> 1 | I27: 0 | J27: 3 | K27: 2 | L27: 4 | M27: Uncommon1 | N27: DevilSkillDmgRatio | O27: =ROUND(O26*1.1, 0) -> 2662 | P27: SoulHp | Q27: =R27&","&S27 -> 2197,2600 | R27: =ROUND(R26*1.3, 0) -> 2197 | S27: =ROUND(R27*1.2, -2) -> 2600 | T27: SoulAtk | U27: =V27&","&W27 -> 173,200 | V27: =ROUND(V26*1.2, 0) -> 173 | W27: =ROUND(V27*1.2, -2) -> 200 | X27: SoulDef | Y27: =Z27&","&AA27 -> 176,200 | Z27: =ROUND(Z26*1.3, 0) -> 176 | AA27: =ROUND(Z27*1.2, -2) -> 200 | AB27: 95000 | AC27: =_xlfn.XLOOKUP($B27, '#참조'!$M:$M, '#참조'!$N:$N) -> #N/A | AD27: =M27&"_"&AC27 -> #N/A | AE27: =IF(I27=0,0,INT(G27&H27&TEXT(I27,"00"))) -> 0
A28: =INT(1&TEXT(RIGHT(B28,4),"0000")&TEXT(L28,"000")) -> 10296005 | B28: 10000296 | C28: ui_persona | D28: PersonaPortrait | E28: ="Persona_"&_xlfn.XLOOKUP($B28, '#캐릭터'!$A:$A, '#캐릭터'!$C:$C) -> Persona_c296 | G28: =_xlfn.XLOOKUP(_xlfn.XLOOKUP(B28,'[1]Detail<Child>'!$A:$A,'[1]Detail<Child>'!$N:$N),'#참조'!P:P,'#참조'!Q:Q) -> 4 | H28: =_xlfn.XLOOKUP(_xlfn.XLOOKUP(B28,'[1]Detail<Child>'!$A:$A,'[1]Detail<Child>'!$O:$O),'#참조'!R:R,'#참조'!S:S) -> 1 | I28: 0 | J28: 3 | K28: 2 | L28: 5 | M28: Uncommon2 | N28: DevilSkillDmgRatio | O28: =ROUND(O27*1.1, 0) -> 2928 | P28: SoulHp | Q28: =R28&","&S28 -> 2856,3400 | R28: =ROUND(R27*1.3, 0) -> 2856 | S28: =ROUND(R28*1.2, -2) -> 3400 | T28: SoulAtk | U28: =V28&","&W28 -> 208,200 | V28: =ROUND(V27*1.2, 0) -> 208 | W28: =ROUND(V28*1.2, -2) -> 200 | X28: SoulDef | Y28: =Z28&","&AA28 -> 229,300 | Z28: =ROUND(Z27*1.3, 0) -> 229 | AA28: =ROUND(Z28*1.2, -2) -> 300 | AB28: 95000 | AC28: =_xlfn.XLOOKUP($B28, '#참조'!$M:$M, '#참조'!$N:$N) -> #N/A | AD28: =M28&"_"&AC28 -> #N/A | AE28: =IF(I28=0,0,INT(G28&H28&TEXT(I28,"00"))) -> 0
A29: =INT(1&TEXT(RIGHT(B29,4),"0000")&TEXT(L29,"000")) -> 10296006 | B29: 10000296 | C29: ui_persona | D29: PersonaPortrait | E29: ="Persona_"&_xlfn.XLOOKUP($B29, '#캐릭터'!$A:$A, '#캐릭터'!$C:$C) -> Persona_c296 | G29: =_xlfn.XLOOKUP(_xlfn.XLOOKUP(B29,'[1]Detail<Child>'!$A:$A,'[1]Detail<Child>'!$N:$N),'#참조'!P:P,'#참조'!Q:Q) -> 4 | H29: =_xlfn.XLOOKUP(_xlfn.XLOOKUP(B29,'[1]Detail<Child>'!$A:$A,'[1]Detail<Child>'!$O:$O),'#참조'!R:R,'#참조'!S:S) -> 1 | I29: 0 | J29: 3 | K29: 2 | L29: 6 | M29: Uncommon3 | N29: DevilSkillDmgRatio | O29: =ROUND(O28*1.1, 0) -> 3221 | P29: SoulHp | Q29: =R29&","&S29 -> 3713,4500 | R29: =ROUND(R28*1.3, 0) -> 3713 | S29: =ROUND(R29*1.2, -2) -> 4500 | T29: SoulAtk | U29: =V29&","&W29 -> 250,300 | V29: =ROUND(V28*1.2, 0) -> 250 | W29: =ROUND(V29*1.2, -2) -> 300 | X29: SoulDef | Y29: =Z29&","&AA29 -> 298,400 | Z29: =ROUND(Z28*1.3, 0) -> 298 | AA29: =ROUND(Z29*1.2, -2) -> 400 | AB29: 95000 | AC29: =_xlfn.XLOOKUP($B29, '#참조'!$M:$M, '#참조'!$N:$N) -> #N/A | AD29: =M29&"_"&AC29 -> #N/A | AE29: =IF(I29=0,0,INT(G29&H29&TEXT(I29,"00"))) -> 0
A30: =INT(1&TEXT(RIGHT(B30,4),"0000")&TEXT(L30,"000")) -> 10296007 | B30: 10000296 | C30: ui_persona | D30: PersonaPortrait | E30: ="Persona_"&_xlfn.XLOOKUP($B30, '#캐릭터'!$A:$A, '#캐릭터'!$C:$C) -> Persona_c296 | G30: =_xlfn.XLOOKUP(_xlfn.XLOOKUP(B30,'[1]Detail<Child>'!$A:$A,'[1]Detail<Child>'!$N:$N),'#참조'!P:P,'#참조'!Q:Q) -> 4 | H30: =_xlfn.XLOOKUP(_xlfn.XLOOKUP(B30,'[1]Detail<Child>'!$A:$A,'[1]Detail<Child>'!$O:$O),'#참조'!R:R,'#참조'!S:S) -> 1 | I30: 1 | J30: 3 | K30: 3 | L30: 7 | M30: Rare1 | N30: DevilSkillDmgRatio | O30: =ROUND(O29*1.1, 0) -> 3543 | P30: SoulHp | Q30: =R30&","&S30 -> 4827,5800 | R30: =ROUND(R29*1.3, 0) -> 4827 | S30: =ROUND(R30*1.2, -2) -> 5800 | T30: SoulAtk | U30: =V30&","&W30 -> 300,400 | V30: =ROUND(V29*1.2, 0) -> 300 | W30: =ROUND(V30*1.2, -2) -> 400 | X30: SoulDef | Y30: =Z30&","&AA30 -> 387,500 | Z30: =ROUND(Z29*1.3, 0) -> 387 | AA30: =ROUND(Z30*1.2, -2) -> 500 | AB30: 90000 | AC30: =_xlfn.XLOOKUP($B30, '#참조'!$M:$M, '#참조'!$N:$N) -> #N/A | AD30: =M30&"_"&AC30 -> #N/A | AE30: =IF(I30=0,0,INT(G30&H30&TEXT(I30,"00"))) -> 4101
A31: =INT(1&TEXT(RIGHT(B31,4),"0000")&TEXT(L31,"000")) -> 10296008 | B31: 10000296 | C31: ui_persona | D31: PersonaPortrait | E31: ="Persona_"&_xlfn.XLOOKUP($B31, '#캐릭터'!$A:$A, '#캐릭터'!$C:$C) -> Persona_c296 | G31: =_xlfn.XLOOKUP(_xlfn.XLOOKUP(B31,'[1]Detail<Child>'!$A:$A,'[1]Detail<Child>'!$N:$N),'#참조'!P:P,'#참조'!Q:Q) -> 4 | H31: =_xlfn.XLOOKUP(_xlfn.XLOOKUP(B31,'[1]Detail<Child>'!$A:$A,'[1]Detail<Child>'!$O:$O),'#참조'!R:R,'#참조'!S:S) -> 1 | I31: 1 | J31: 3 | K31: 3 | L31: 8 | M31: Rare2 | N31: DevilSkillDmgRatio | O31: =ROUND(O30*1.1, 0) -> 3897 | P31: SoulHp | Q31: =R31&","&S31 -> 6275,7500 | R31: =ROUND(R30*1.3, 0) -> 6275 | S31: =ROUND(R31*1.2, -2) -> 7500 | T31: SoulAtk | U31: =V31&","&W31 -> 360,400 | V31: =ROUND(V30*1.2, 0) -> 360 | W31: =ROUND(V31*1.2, -2) -> 400 | X31: SoulDef | Y31: =Z31&","&AA31 -> 503,600 | Z31: =ROUND(Z30*1.3, 0) -> 503 | AA31: =ROUND(Z31*1.2, -2) -> 600 | AB31: 90000 | AC31: =_xlfn.XLOOKUP($B31, '#참조'!$M:$M, '#참조'!$N:$N) -> #N/A | AD31: =M31&"_"&AC31 -> #N/A | AE31: =IF(I31=0,0,INT(G31&H31&TEXT(I31,"00"))) -> 4101
A32: =INT(1&TEXT(RIGHT(B32,4),"0000")&TEXT(L32,"000")) -> 10296009 | B32: 10000296 | C32: ui_persona | D32: PersonaPortrait | E32: ="Persona_"&_xlfn.XLOOKUP($B32, '#캐릭터'!$A:$A, '#캐릭터'!$C:$C) -> Persona_c296 | G32: =_xlfn.XLOOKUP(_xlfn.XLOOKUP(B32,'[1]Detail<Child>'!$A:$A,'[1]Detail<Child>'!$N:$N),'#참조'!P:P,'#참조'!Q:Q) -> 4 | H32: =_xlfn.XLOOKUP(_xlfn.XLOOKUP(B32,'[1]Detail<Child>'!$A:$A,'[1]Detail<Child>'!$O:$O),'#참조'!R:R,'#참조'!S:S) -> 1 | I32: 2 | J32: 3 | K32: 3 | L32: 9 | M32: Rare3 | N32: DevilSkillDmgRatio | O32: =ROUND(O31*1.1, 0) -> 4287 | P32: SoulHp | Q32: =R32&","&S32 -> 8158,9800 | R32: =ROUND(R31*1.3, 0) -> 8158 | S32: =ROUND(R32*1.2, -2) -> 9800 | T32: SoulAtk | U32: =V32&","&W32 -> 432,500 | V32: =ROUND(V31*1.2, 0) -> 432 | W32: =ROUND(V32*1.2, -2) -> 500 | X32: SoulDef | Y32: =Z32&","&AA32 -> 654,800 | Z32: =ROUND(Z31*1.3, 0) -> 654 | AA32: =ROUND(Z32*1.2, -2) -> 800 | AB32: 90000 | AC32: =_xlfn.XLOOKUP($B32, '#참조'!$M:$M, '#참조'!$N:$N) -> #N/A | AD32: =M32&"_"&AC32 -> #N/A | AE32: =IF(I32=0,0,INT(G32&H32&TEXT(I32,"00"))) -> 4102
A33: =INT(1&TEXT(RIGHT(B33,4),"0000")&TEXT(L33,"000")) -> 10296010 | B33: 10000296 | C33: ui_persona | D33: PersonaPortrait | E33: ="Persona_"&_xlfn.XLOOKUP($B33, '#캐릭터'!$A:$A, '#캐릭터'!$C:$C) -> Persona_c296 | G33: =_xlfn.XLOOKUP(_xlfn.XLOOKUP(B33,'[1]Detail<Child>'!$A:$A,'[1]Detail<Child>'!$N:$N),'#참조'!P:P,'#참조'!Q:Q) -> 4 | H33: =_xlfn.XLOOKUP(_xlfn.XLOOKUP(B33,'[1]Detail<Child>'!$A:$A,'[1]Detail<Child>'!$O:$O),'#참조'!R:R,'#참조'!S:S) -> 1 | I33: 2 | J33: 3 | K33: 4 | L33: 10 | M33: Unique1 | N33: DevilSkillDmgRatio | O33: =ROUND(O32*1.1, 0) -> 4716 | P33: SoulHp | Q33: =R33&","&S33 -> 10605,12700 | R33: =ROUND(R32*1.3, 0) -> 10605 | S33: =ROUND(R33*1.2, -2) -> 12700 | T33: SoulAtk | U33: =V33&","&W33 -> 518,600 | V33: =ROUND(V32*1.2, 0) -> 518 | W33: =ROUND(V33*1.2, -2) -> 600 | X33: SoulDef | Y33: =Z33&","&AA33 -> 850,1000 | Z33: =ROUND(Z32*1.3, 0) -> 850 | AA33: =ROUND(Z33*1.2, -2) -> 1000 | AB33: 85000 | AC33: =_xlfn.XLOOKUP($B33, '#참조'!$M:$M, '#참조'!$N:$N) -> #N/A | AD33: =M33&"_"&AC33 -> #N/A | AE33: =IF(I33=0,0,INT(G33&H33&TEXT(I33,"00"))) -> 4102
A34: =INT(1&TEXT(RIGHT(B34,4),"0000")&TEXT(L34,"000")) -> 10296011 | B34: 10000296 | C34: ui_persona | D34: PersonaPortrait | E34: ="Persona_"&_xlfn.XLOOKUP($B34, '#캐릭터'!$A:$A, '#캐릭터'!$C:$C) -> Persona_c296 | G34: =_xlfn.XLOOKUP(_xlfn.XLOOKUP(B34,'[1]Detail<Child>'!$A:$A,'[1]Detail<Child>'!$N:$N),'#참조'!P:P,'#참조'!Q:Q) -> 4 | H34: =_xlfn.XLOOKUP(_xlfn.XLOOKUP(B34,'[1]Detail<Child>'!$A:$A,'[1]Detail<Child>'!$O:$O),'#참조'!R:R,'#참조'!S:S) -> 1 | I34: 3 | J34: 3 | K34: 4 | L34: 11 | M34: Unique2 | N34: DevilSkillDmgRatio | O34: =ROUND(O33*1.1, 0) -> 5188 | P34: SoulHp | Q34: =R34&","&S34 -> 13787,16500 | R34: =ROUND(R33*1.3, 0) -> 13787 | S34: =ROUND(R34*1.2, -2) -> 16500 | T34: SoulAtk | U34: =V34&","&W34 -> 622,700 | V34: =ROUND(V33*1.2, 0) -> 622 | W34: =ROUND(V34*1.2, -2) -> 700 | X34: SoulDef | Y34: =Z34&","&AA34 -> 1105,1300 | Z34: =ROUND(Z33*1.3, 0) -> 1105 | AA34: =ROUND(Z34*1.2, -2) -> 1300 | AB34: 85000 | AC34: =_xlfn.XLOOKUP($B34, '#참조'!$M:$M, '#참조'!$N:$N) -> #N/A | AD34: =M34&"_"&AC34 -> #N/A | AE34: =IF(I34=0,0,INT(G34&H34&TEXT(I34,"00"))) -> 4103
A35: =INT(1&TEXT(RIGHT(B35,4),"0000")&TEXT(L35,"000")) -> 10296012 | B35: 10000296 | C35: ui_persona | D35: PersonaPortrait | E35: ="Persona_"&_xlfn.XLOOKUP($B35, '#캐릭터'!$A:$A, '#캐릭터'!$C:$C) -> Persona_c296 | G35: =_xlfn.XLOOKUP(_xlfn.XLOOKUP(B35,'[1]Detail<Child>'!$A:$A,'[1]Detail<Child>'!$N:$N),'#참조'!P:P,'#참조'!Q:Q) -> 4 | H35: =_xlfn.XLOOKUP(_xlfn.XLOOKUP(B35,'[1]Detail<Child>'!$A:$A,'[1]Detail<Child>'!$O:$O),'#참조'!R:R,'#참조'!S:S) -> 1 | I35: 3 | J35: 3 | K35: 4 | L35: 12 | M35: Unique3 | N35: DevilSkillDmgRatio | O35: =ROUND(O34*1.1, 0) -> 5707 | P35: SoulHp | Q35: =R35&","&S35 -> 17923,21500 | R35: =ROUND(R34*1.3, 0) -> 17923 | S35: =ROUND(R35*1.2, -2) -> 21500 | T35: SoulAtk | U35: =V35&","&W35 -> 746,900 | V35: =ROUND(V34*1.2, 0) -> 746 | W35: =ROUND(V35*1.2, -2) -> 900 | X35: SoulDef | Y35: =Z35&","&AA35 -> 1437,1700 | Z35: =ROUND(Z34*1.3, 0) -> 1437 | AA35: =ROUND(Z35*1.2, -2) -> 1700 | AB35: 85000 | AC35: =_xlfn.XLOOKUP($B35, '#참조'!$M:$M, '#참조'!$N:$N) -> #N/A | AD35: =M35&"_"&AC35 -> #N/A | AE35: =IF(I35=0,0,INT(G35&H35&TEXT(I35,"00"))) -> 4103
A36: =INT(1&TEXT(RIGHT(B36,4),"0000")&TEXT(L36,"000")) -> 10296013 | B36: 10000296 | C36: ui_persona | D36: PersonaPortrait | E36: ="Persona_"&_xlfn.XLOOKUP($B36, '#캐릭터'!$A:$A, '#캐릭터'!$C:$C) -> Persona_c296 | G36: =_xlfn.XLOOKUP(_xlfn.XLOOKUP(B36,'[1]Detail<Child>'!$A:$A,'[1]Detail<Child>'!$N:$N),'#참조'!P:P,'#참조'!Q:Q) -> 4 | H36: =_xlfn.XLOOKUP(_xlfn.XLOOKUP(B36,'[1]Detail<Child>'!$A:$A,'[1]Detail<Child>'!$O:$O),'#참조'!R:R,'#참조'!S:S) -> 1 | I36: 4 | J36: 3 | K36: 5 | L36: 13 | M36: Epic1 | N36: DevilSkillDmgRatio | O36: =ROUND(O35*1.1, 0) -> 6278 | P36: SoulHp | Q36: =R36&","&S36 -> 23300,28000 | R36: =ROUND(R35*1.3, 0) -> 23300 | S36: =ROUND(R36*1.2, -2) -> 28000 | T36: SoulAtk | U36: =V36&","&W36 -> 895,1100 | V36: =ROUND(V35*1.2, 0) -> 895 | W36: =ROUND(V36*1.2, -2) -> 1100 | X36: SoulDef | Y36: =Z36&","&AA36 -> 1868,2200 | Z36: =ROUND(Z35*1.3, 0) -> 1868 | AA36: =ROUND(Z36*1.2, -2) -> 2200 | AB36: 80000 | AC36: =_xlfn.XLOOKUP($B36, '#참조'!$M:$M, '#참조'!$N:$N) -> #N/A | AD36: =M36&"_"&AC36 -> #N/A | AE36: =IF(I36=0,0,INT(G36&H36&TEXT(I36,"00"))) -> 4104
... A41: =INT(1&TEXT(RIGHT(B41,4),"0000")&TEXT(L41,"000")) -> 10296018 | B41: 10000296 | C41: ui_persona | D41: PersonaPortrait | E41: ="Persona_"&_xlfn.XLOOKUP($B41, '#캐릭터'!$A:$A, '#캐릭터'!$C:$C) -> Persona_c296 | G41: =_xlfn.XLOOKUP(_xlfn.XLOOKUP(B41,'[1]Detail<Child>'!$A:$A,'[1]Detail<Child>'!$N:$N),'#참조'!P:P,'#참조'!Q:Q) -> 4 | H41: =_xlfn.XLOOKUP(_xlfn.XLOOKUP(B41,'[1]Detail<Child>'!$A:$A,'[1]Detail<Child>'!$O:$O),'#참조'!R:R,'#참조'!S:S) -> 1 | I41: 6 | J41: 3 | K41: 6 | L41: 18 | M41: Legendary3 | N41: DevilSkillDmgRatio | O41: =ROUND(O40*1.1, 0) -> 10112 | P41: SoulHp | Q41: =R41&","&S41 -> 86511,103800 | R41: =ROUND(R40*1.3, 0) -> 86511 | S41: =ROUND(R41*1.2, -2) -> 103800 | T41: SoulAtk | U41: =V41&","&W41 -> 2227,2700 | V41: =ROUND(V40*1.2, 0) -> 2227 | W41: =ROUND(V41*1.2, -2) -> 2700 | X41: SoulDef | Y41: =Z41&","&AA41 -> 6934,8300 | Z41: =ROUND(Z40*1.3, 0) -> 6934 | AA41: =ROUND(Z41*1.2, -2) -> 8300 | AB41: 75000 | AC41: =_xlfn.XLOOKUP($B41, '#참조'!$M:$M, '#참조'!$N:$N) -> #N/A | AD41: =M41&"_"&AC41 -> #N/A | AE41: =IF(I41=0,0,INT(G41&H41&TEXT(I41,"00"))) -> 4106
A42: =INT(1&TEXT(RIGHT(B42,4),"0000")&TEXT(L42,"000")) -> 10003000 | B42: 10000003 | C42: ui_persona | D42: PersonaPortrait | E42: ="Persona_"&_xlfn.XLOOKUP($B42, '#캐릭터'!$A:$A, '#캐릭터'!$C:$C) -> Persona_c003 | G42: =_xlfn.XLOOKUP(_xlfn.XLOOKUP(B42,'[1]Detail<Child>'!$A:$A,'[1]Detail<Child>'!$N:$N),'#참조'!P:P,'#참조'!Q:Q) -> 1 | H42: =_xlfn.XLOOKUP(_xlfn.XLOOKUP(B42,'[1]Detail<Child>'!$A:$A,'[1]Detail<Child>'!$O:$O),'#참조'!R:R,'#참조'!S:S) -> 4 | I42: 0 | J42: 3 | K42: 0 | L42: 0 | M42: Default | N42: DevilSkillDmgRatio | O42: 0 | P42: SoulHp | Q42: =R42&","&S42 -> 1000,1000 | R42: 1000 | S42: =R42 -> 1000 | T42: SoulAtk | U42: =V42&","&W42 -> 100,100 | V42: 100 | W42: =V42 -> 100 | X42: SoulDef | Y42: =Z42&","&AA42 -> 80,80 | Z42: 80 | AA42: =Z42 -> 80 | AB42: 100000 | AE42: =IF(I42=0,0,INT(G42&H42&TEXT(I42,"00"))) -> 0
A43: =INT(1&TEXT(RIGHT(B43,4),"0000")&TEXT(L43,"000")) -> 10003001 | B43: 10000003 | C43: ui_persona | D43: PersonaPortrait | E43: ="Persona_"&_xlfn.XLOOKUP($B43, '#캐릭터'!$A:$A, '#캐릭터'!$C:$C) -> Persona_c003 | G43: =_xlfn.XLOOKUP(_xlfn.XLOOKUP(B43,'[1]Detail<Child>'!$A:$A,'[1]Detail<Child>'!$N:$N),'#참조'!P:P,'#참조'!Q:Q) -> 1 | H43: =_xlfn.XLOOKUP(_xlfn.XLOOKUP(B43,'[1]Detail<Child>'!$A:$A,'[1]Detail<Child>'!$O:$O),'#참조'!R:R,'#참조'!S:S) -> 4 | I43: 0 | J43: 1 | K43: 1 | L43: 1 | M43: Common1 | N43: DevilSkillDmgRatio | O43: 2000 | P43: SoulHp | Q43: =R43&","&S43 -> 1000,1200 | R43: 1000 | S43: =ROUND(R43*1.2, -2) -> 1200 | T43: SoulAtk | U43: =V43&","&W43 -> 100,100 | V43: 100 | W43: =ROUND(V43*1.2, -2) -> 100 | X43: SoulDef | Y43: =Z43&","&AA43 -> 80,100 | Z43: 80 | AA43: =ROUND(Z43*1.2, -2) -> 100 | AB43: 100000 | AC43: =_xlfn.XLOOKUP($B43, '#참조'!$M:$M, '#참조'!$N:$N) -> 다비 | AD43: =M43&"_"&AC43 -> Common1_다비 | AE43: =IF(I43=0,0,INT(G43&H43&TEXT(I43,"00"))) -> 0
A44: =INT(1&TEXT(RIGHT(B44,4),"0000")&TEXT(L44,"000")) -> 10003002 | B44: 10000003 | C44: ui_persona | D44: PersonaPortrait | E44: ="Persona_"&_xlfn.XLOOKUP($B44, '#캐릭터'!$A:$A, '#캐릭터'!$C:$C) -> Persona_c003 | G44: =_xlfn.XLOOKUP(_xlfn.XLOOKUP(B44,'[1]Detail<Child>'!$A:$A,'[1]Detail<Child>'!$N:$N),'#참조'!P:P,'#참조'!Q:Q) -> 1 | H44: =_xlfn.XLOOKUP(_xlfn.XLOOKUP(B44,'[1]Detail<Child>'!$A:$A,'[1]Detail<Child>'!$O:$O),'#참조'!R:R,'#참조'!S:S) -> 4 | I44: 0 | J44: 1 | K44: 1 | L44: 2 | M44: Common2 | N44: DevilSkillDmgRatio | O44: =ROUND(O43*1.1, 0) -> 2200 | P44: SoulHp | Q44: =R44&","&S44 -> 1300,1600 | R44: =ROUND(R43*1.3, 0) -> 1300 | S44: =ROUND(R44*1.2, -2) -> 1600 | T44: SoulAtk | U44: =V44&","&W44 -> 120,100 | V44: =ROUND(V43*1.2, 0) -> 120 | W44: =ROUND(V44*1.2, -2) -> 100 | X44: SoulDef | Y44: =Z44&","&AA44 -> 104,100 | Z44: =ROUND(Z43*1.3, 0) -> 104 | AA44: =ROUND(Z44*1.2, -2) -> 100 | AB44: 100000 | AC44: =_xlfn.XLOOKUP($B44, '#참조'!$M:$M, '#참조'!$N:$N) -> 다비 | AD44: =M44&"_"&AC44 -> Common2_다비 | AE44: =IF(I44=0,0,INT(G44&H44&TEXT(I44,"00"))) -> 0
A45: =INT(1&TEXT(RIGHT(B45,4),"0000")&TEXT(L45,"000")) -> 10003003 | B45: 10000003 | C45: ui_persona | D45: PersonaPortrait | E45: ="Persona_"&_xlfn.XLOOKUP($B45, '#캐릭터'!$A:$A, '#캐릭터'!$C:$C) -> Persona_c003 | G45: =_xlfn.XLOOKUP(_xlfn.XLOOKUP(B45,'[1]Detail<Child>'!$A:$A,'[1]Detail<Child>'!$N:$N),'#참조'!P:P,'#참조'!Q:Q) -> 1 | H45: =_xlfn.XLOOKUP(_xlfn.XLOOKUP(B45,'[1]Detail<Child>'!$A:$A,'[1]Detail<Child>'!$O:$O),'#참조'!R:R,'#참조'!S:S) -> 4 | I45: 0 | J45: 1 | K45: 1 | L45: 3 | M45: Common3 | N45: DevilSkillDmgRatio | O45: =ROUND(O44*1.1, 0) -> 2420 | P45: SoulHp | Q45: =R45&","&S45 -> 1690,2000 | R45: =ROUND(R44*1.3, 0) -> 1690 | S45: =ROUND(R45*1.2, -2) -> 2000 | T45: SoulAtk | U45: =V45&","&W45 -> 144,200 | V45: =ROUND(V44*1.2, 0) -> 144 | W45: =ROUND(V45*1.2, -2) -> 200 | X45: SoulDef | Y45: =Z45&","&AA45 -> 135,200 | Z45: =ROUND(Z44*1.3, 0) -> 135 | AA45: =ROUND(Z45*1.2, -2) -> 200 | AB45: 100000 | AC45: =_xlfn.XLOOKUP($B45, '#참조'!$M:$M, '#참조'!$N:$N) -> 다비 | AD45: =M45&"_"&AC45 -> Common3_다비 | AE45: =IF(I45=0,0,INT(G45&H45&TEXT(I45,"00"))) -> 0
A46: =INT(1&TEXT(RIGHT(B46,4),"0000")&TEXT(L46,"000")) -> 10003004 | B46: 10000003 | C46: ui_persona | D46: PersonaPortrait | E46: ="Persona_"&_xlfn.XLOOKUP($B46, '#캐릭터'!$A:$A, '#캐릭터'!$C:$C) -> Persona_c003 | G46: =_xlfn.XLOOKUP(_xlfn.XLOOKUP(B46,'[1]Detail<Child>'!$A:$A,'[1]Detail<Child>'!$N:$N),'#참조'!P:P,'#참조'!Q:Q) -> 1 | H46: =_xlfn.XLOOKUP(_xlfn.XLOOKUP(B46,'[1]Detail<Child>'!$A:$A,'[1]Detail<Child>'!$O:$O),'#참조'!R:R,'#참조'!S:S) -> 4 | I46: 0 | J46: 1 | K46: 2 | L46: 4 | M46: Uncommon1 | N46: DevilSkillDmgRatio | O46: =ROUND(O45*1.1, 0) -> 2662 | P46: SoulHp | Q46: =R46&","&S46 -> 2197,2600 | R46: =ROUND(R45*1.3, 0) -> 2197 | S46: =ROUND(R46*1.2, -2) -> 2600 | T46: SoulAtk | U46: =V46&","&W46 -> 173,200 | V46: =ROUND(V45*1.2, 0) -> 173 | W46: =ROUND(V46*1.2, -2) -> 200 | X46: SoulDef | Y46: =Z46&","&AA46 -> 176,200 | Z46: =ROUND(Z45*1.3, 0) -> 176 | AA46: =ROUND(Z46*1.2, -2) -> 200 | AB46: 95000 | AC46: =_xlfn.XLOOKUP($B46, '#참조'!$M:$M, '#참조'!$N:$N) -> 다비 | AD46: =M46&"_"&AC46 -> Uncommon1_다비 | AE46: =IF(I46=0,0,INT(G46&H46&TEXT(I46,"00"))) -> 0
A47: =INT(1&TEXT(RIGHT(B47,4),"0000")&TEXT(L47,"000")) -> 10003005 | B47: 10000003 | C47: ui_persona | D47: PersonaPortrait | E47: ="Persona_"&_xlfn.XLOOKUP($B47, '#캐릭터'!$A:$A, '#캐릭터'!$C:$C) -> Persona_c003 | G47: =_xlfn.XLOOKUP(_xlfn.XLOOKUP(B47,'[1]Detail<Child>'!$A:$A,'[1]Detail<Child>'!$N:$N),'#참조'!P:P,'#참조'!Q:Q) -> 1 | H47: =_xlfn.XLOOKUP(_xlfn.XLOOKUP(B47,'[1]Detail<Child>'!$A:$A,'[1]Detail<Child>'!$O:$O),'#참조'!R:R,'#참조'!S:S) -> 4 | I47: 0 | J47: 1 | K47: 2 | L47: 5 | M47: Uncommon2 | N47: DevilSkillDmgRatio | O47: =ROUND(O46*1.1, 0) -> 2928 | P47: SoulHp | Q47: =R47&","&S47 -> 2856,3400 | R47: =ROUND(R46*1.3, 0) -> 2856 | S47: =ROUND(R47*1.2, -2) -> 3400 | T47: SoulAtk | U47: =V47&","&W47 -> 208,200 | V47: =ROUND(V46*1.2, 0) -> 208 | W47: =ROUND(V47*1.2, -2) -> 200 | X47: SoulDef | Y47: =Z47&","&AA47 -> 229,300 | Z47: =ROUND(Z46*1.3, 0) -> 229 | AA47: =ROUND(Z47*1.2, -2) -> 300 | AB47: 95000 | AC47: =_xlfn.XLOOKUP($B47, '#참조'!$M:$M, '#참조'!$N:$N) -> 다비 | AD47: =M47&"_"&AC47 -> Uncommon2_다비 | AE47: =IF(I47=0,0,INT(G47&H47&TEXT(I47,"00"))) -> 0
A48: =INT(1&TEXT(RIGHT(B48,4),"0000")&TEXT(L48,"000")) -> 10003006 | B48: 10000003 | C48: ui_persona | D48: PersonaPortrait | E48: ="Persona_"&_xlfn.XLOOKUP($B48, '#캐릭터'!$A:$A, '#캐릭터'!$C:$C) -> Persona_c003 | G48: =_xlfn.XLOOKUP(_xlfn.XLOOKUP(B48,'[1]Detail<Child>'!$A:$A,'[1]Detail<Child>'!$N:$N),'#참조'!P:P,'#참조'!Q:Q) -> 1 | H48: =_xlfn.XLOOKUP(_xlfn.XLOOKUP(B48,'[1]Detail<Child>'!$A:$A,'[1]Detail<Child>'!$O:$O),'#참조'!R:R,'#참조'!S:S) -> 4 | I48: 0 | J48: 1 | K48: 2 | L48: 6 | M48: Uncommon3 | N48: DevilSkillDmgRatio | O48: =ROUND(O47*1.1, 0) -> 3221 | P48: SoulHp | Q48: =R48&","&S48 -> 3713,4500 | R48: =ROUND(R47*1.3, 0) -> 3713 | S48: =ROUND(R48*1.2, -2) -> 4500 | T48: SoulAtk | U48: =V48&","&W48 -> 250,300 | V48: =ROUND(V47*1.2, 0) -> 250 | W48: =ROUND(V48*1.2, -2) -> 300 | X48: SoulDef | Y48: =Z48&","&AA48 -> 298,400 | Z48: =ROUND(Z47*1.3, 0) -> 298 | AA48: =ROUND(Z48*1.2, -2) -> 400 | AB48: 95000 | AC48: =_xlfn.XLOOKUP($B48, '#참조'!$M:$M, '#참조'!$N:$N) -> 다비 | AD48: =M48&"_"&AC48 -> Uncommon3_다비 | AE48: =IF(I48=0,0,INT(G48&H48&TEXT(I48,"00"))) -> 0
A49: =INT(1&TEXT(RIGHT(B49,4),"0000")&TEXT(L49,"000")) -> 10003007 | B49: 10000003 | C49: ui_persona | D49: PersonaPortrait | E49: ="Persona_"&_xlfn.XLOOKUP($B49, '#캐릭터'!$A:$A, '#캐릭터'!$C:$C) -> Persona_c003 | G49: =_xlfn.XLOOKUP(_xlfn.XLOOKUP(B49,'[1]Detail<Child>'!$A:$A,'[1]Detail<Child>'!$N:$N),'#참조'!P:P,'#참조'!Q:Q) -> 1 | H49: =_xlfn.XLOOKUP(_xlfn.XLOOKUP(B49,'[1]Detail<Child>'!$A:$A,'[1]Detail<Child>'!$O:$O),'#참조'!R:R,'#참조'!S:S) -> 4 | I49: 1 | J49: 1 | K49: 3 | L49: 7 | M49: Rare1 | N49: DevilSkillDmgRatio | O49: =ROUND(O48*1.1, 0) -> 3543 | P49: SoulHp | Q49: =R49&","&S49 -> 4827,5800 | R49: =ROUND(R48*1.3, 0) -> 4827 | S49: =ROUND(R49*1.2, -2) -> 5800 | T49: SoulAtk | U49: =V49&","&W49 -> 300,400 | V49: =ROUND(V48*1.2, 0) -> 300 | W49: =ROUND(V49*1.2, -2) -> 400 | X49: SoulDef | Y49: =Z49&","&AA49 -> 387,500 | Z49: =ROUND(Z48*1.3, 0) -> 387 | AA49: =ROUND(Z49*1.2, -2) -> 500 | AB49: 90000 | AC49: =_xlfn.XLOOKUP($B49, '#참조'!$M:$M, '#참조'!$N:$N) -> 다비 | AD49: =M49&"_"&AC49 -> Rare1_다비 | AE49: =IF(I49=0,0,INT(G49&H49&TEXT(I49,"00"))) -> 1401
A50: =INT(1&TEXT(RIGHT(B50,4),"0000")&TEXT(L50,"000")) -> 10003008 | B50: 10000003 | C50: ui_persona | D50: PersonaPortrait | E50: ="Persona_"&_xlfn.XLOOKUP($B50, '#캐릭터'!$A:$A, '#캐릭터'!$C:$C) -> Persona_c003 | G50: =_xlfn.XLOOKUP(_xlfn.XLOOKUP(B50,'[1]Detail<Child>'!$A:$A,'[1]Detail<Child>'!$N:$N),'#참조'!P:P,'#참조'!Q:Q) -> 1 | H50: =_xlfn.XLOOKUP(_xlfn.XLOOKUP(B50,'[1]Detail<Child>'!$A:$A,'[1]Detail<Child>'!$O:$O),'#참조'!R:R,'#참조'!S:S) -> 4 | I50: 1 | J50: 1 | K50: 3 | L50: 8 | M50: Rare2 | N50: DevilSkillDmgRatio | O50: =ROUND(O49*1.1, 0) -> 3897 | P50: SoulHp | Q50: =R50&","&S50 -> 6275,7500 | R50: =ROUND(R49*1.3, 0) -> 6275 | S50: =ROUND(R50*1.2, -2) -> 7500 | T50: SoulAtk | U50: =V50&","&W50 -> 360,400 | V50: =ROUND(V49*1.2, 0) -> 360 | W50: =ROUND(V50*1.2, -2) -> 400 | X50: SoulDef | Y50: =Z50&","&AA50 -> 503,600 | Z50: =ROUND(Z49*1.3, 0) -> 503 | AA50: =ROUND(Z50*1.2, -2) -> 600 | AB50: 90000 | AC50: =_xlfn.XLOOKUP($B50, '#참조'!$M:$M, '#참조'!$N:$N) -> 다비 | AD50: =M50&"_"&AC50 -> Rare2_다비 | AE50: =IF(I50=0,0,INT(G50&H50&TEXT(I50,"00"))) -> 1401
...

Sheet Desire
A1: Id | B1: #이름 | C1: DesireType | D1: Atlas | E1: Icon | F1: Name | G1: Desc | H1: ChildStat | I1: Value | J1: ChildStat | K1: Value | L1: ChildStat | M1: Value
A4: 101 | B4: 오만 | C4: Superbia | D4: CommonIcon | E4: ="Icon_Persona_Desire_"&C4 -> Icon_Persona_Desire_Superbia | F4: =LOWER("persona_desire_"&$C4&"_"&F$1) -> persona_desire_superbia_name | G4: =LOWER("persona_desire_"&$C4&"_"&G$1) -> persona_desire_superbia_desc | H4: AtkRatio | I4: 20000 | J4: Dodge | K4: -10 | L4: None | M4: 0
A5: 102 | B5: 인색 | C5: Avaritia | D5: CommonIcon | E5: ="Icon_Persona_Desire_"&C5 -> Icon_Persona_Desire_Avaritia | F5: =LOWER("persona_desire_"&$C5&"_"&F$1) -> persona_desire_avaritia_name | G5: =LOWER("persona_desire_"&$C5&"_"&G$1) -> persona_desire_avaritia_desc | H5: DefRatio | I5: 20000 | J5: Spd | K5: -5 | L5: None | M5: 0
A6: 103 | B6: 질투 | C6: Invidia | D6: CommonIcon | E6: ="Icon_Persona_Desire_"&C6 -> Icon_Persona_Desire_Invidia | F6: =LOWER("persona_desire_"&$C6&"_"&F$1) -> persona_desire_invidia_name | G6: =LOWER("persona_desire_"&$C6&"_"&G$1) -> persona_desire_invidia_desc | H6: AtkRatio | I6: 20000 | J6: Hit | K6: -10 | L6: None | M6: 0
A7: 104 | B7: 분노 | C7: Ira | D7: CommonIcon | E7: ="Icon_Persona_Desire_"&C7 -> Icon_Persona_Desire_Ira | F7: =LOWER("persona_desire_"&$C7&"_"&F$1) -> persona_desire_ira_name | G7: =LOWER("persona_desire_"&$C7&"_"&G$1) -> persona_desire_ira_desc | H7: AtkRatio | I7: 20000 | J7: DefRatio | K7: -20000 | L7: None | M7: 0
A8: 105 | B8: 색욕 | C8: Luxuria | D8: CommonIcon | E8: ="Icon_Persona_Desire_"&C8 -> Icon_Persona_Desire_Luxuria | F8: =LOWER("persona_desire_"&$C8&"_"&F$1) -> persona_desire_luxuria_name | G8: =LOWER("persona_desire_"&$C8&"_"&G$1) -> persona_desire_luxuria_desc | H8: Spd | I8: 5 | J8: HpRatio | K8: -20000 | L8: None | M8: 0
A9: 106 | B9: 탐욕 | C9: Gula | D9: CommonIcon | E9: ="Icon_Persona_Desire_"&C9 -> Icon_Persona_Desire_Gula | F9: =LOWER("persona_desire_"&$C9&"_"&F$1) -> persona_desire_gula_name | G9: =LOWER("persona_desire_"&$C9&"_"&G$1) -> persona_desire_gula_desc | H9: Spd | I9: 5 | J9: Hit | K9: -10 | L9: None | M9: 0
A10: 107 | B10: 나태 | C10: Pigritia | D10: CommonIcon | E10: ="Icon_Persona_Desire_"&C10 -> Icon_Persona_Desire_Pigritia | F10: =LOWER("persona_desire_"&$C10&"_"&F$1) -> persona_desire_pigritia_name | G10: =LOWER("persona_desire_"&$C10&"_"&G$1) -> persona_desire_pigritia_desc | H10: HpRatio | I10: 20000 | J10: Spd | K10: -5 | L10: None | M10: 0
A11: 108 | B11: 집착 | C11: Obsession | D11: CommonIcon | E11: ="Icon_Persona_Desire_"&C11 -> Icon_Persona_Desire_Obsession | F11: =LOWER("persona_desire_"&$C11&"_"&F$1) -> persona_desire_obsession_name | G11: =LOWER("persona_desire_"&$C11&"_"&G$1) -> persona_desire_obsession_desc | H11: Hit | I11: 10 | J11: DefRatio | K11: -20000 | L11: None | M11: 0
A12: 109 | B12: 겸손 | C12: Humilitas | D12: CommonIcon | E12: ="Icon_Persona_Desire_"&C12 -> Icon_Persona_Desire_Humilitas | F12: =LOWER("persona_desire_"&$C12&"_"&F$1) -> persona_desire_humilitas_name | G12: =LOWER("persona_desire_"&$C12&"_"&G$1) -> persona_desire_humilitas_desc | H12: DefRatio | I12: 20000 | J12: AtkRatio | K12: -20000 | L12: None | M12: 0
A13: 110 | B13: 자선 | C13: Caritas | D13: CommonIcon | E13: ="Icon_Persona_Desire_"&C13 -> Icon_Persona_Desire_Caritas | F13: =LOWER("persona_desire_"&$C13&"_"&F$1) -> persona_desire_caritas_name | G13: =LOWER("persona_desire_"&$C13&"_"&G$1) -> persona_desire_caritas_desc | H13: HpRatio | I13: 20000 | J13: AtkRatio | K13: -20000 | L13: None | M13: 0
A14: 111 | B14: 친절 | C14: Benevolentia | D14: CommonIcon | E14: ="Icon_Persona_Desire_"&C14 -> Icon_Persona_Desire_Benevolentia | F14: =LOWER("persona_desire_"&$C14&"_"&F$1) -> persona_desire_benevolentia_name | G14: =LOWER("persona_desire_"&$C14&"_"&G$1) -> persona_desire_benevolentia_desc | H14: HpRatio | I14: 0 | J14: AtkRatio | K14: 0 | L14: None | M14: 0
A15: 112 | B15: 인내 | C15: Patientia | D15: CommonIcon | E15: ="Icon_Persona_Desire_"&C15 -> Icon_Persona_Desire_Patientia | F15: =LOWER("persona_desire_"&$C15&"_"&F$1) -> persona_desire_patientia_name | G15: =LOWER("persona_desire_"&$C15&"_"&G$1) -> persona_desire_patientia_desc | H15: DefRatio | I15: 20000 | J15: Dodge | K15: -10 | L15: None | M15: 0
... A19: 116 | B19: 초연 | C19: Definitio | D19: CommonIcon | E19: ="Icon_Persona_Desire_"&C19 -> Icon_Persona_Desire_Definitio | F19: =LOWER("persona_desire_"&$C19&"_"&F$1) -> persona_desire_definitio_name | G19: =LOWER("persona_desire_"&$C19&"_"&G$1) -> persona_desire_definitio_desc | H19: Dodge | I19: 10 | J19: HpRatio | K19: -20000 | L19: None | M19: 0

Sheet Talent
A1: Id | B1: #idx | C1: #이름 | D1: #Element | E1: #role | F1: #Grade | G1: CommonGrade | H1: Group | I1: Skill | J1: Weight | K1: #ref | L1: #ref | M1: #ref | N1: #ref | O1: #ref | P1: #ref | Q1: #ref | R1: #ref | S1: #ref | T1: #ref
K3: 1 | L3: 2 | M3: 3 | N3: 4 | O3: 5 | P3: 6
A4: =INT(H4&TEXT(B4,"000")) -> 1101001 | B4: 1 | C4: 투쟁심 | D4: 1 | E4: 1 | F4: 1 | G4: Common | H4: =INT(D4&E4&TEXT(F4,"00")) -> 1101 | I4: 7000101 | J4: 20000 | K4: =J4/SUM(J4:J13) -> 0.17761989 | L4: =K14 -> 0.1722488 | M4: =K24 -> 0.1659751 | N4: =K34 -> 0.1585504 | O4: =K44 -> 0.14962594 | P4: =K54 -> 0.13869626 | Q4: 7000101 | R4: =_xlfn.XLOOKUP(Q4,I:I,C:C) -> 투쟁심 | S4: =_xlfn.XLOOKUP(Q4,I:I,A:A) -> 1101001 | T4: =_xlfn.XLOOKUP(Q4,'[2]Skill<Talent>'!$A:$A,'[2]Skill<Talent>'!$C:$C) -> 매 턴 시작시 공격력이 <color=#87cefa>5%</color> 증가
A5: =INT(H5&TEXT(B5,"000")) -> 1101002 | B5: 2 | C5: 원칙주의자 | D5: 1 | E5: 1 | F5: 1 | G5: Common | H5: =INT(D5&E5&TEXT(F5,"00")) -> 1101 | I5: 7000106 | J5: 20000 | K5: =J5/SUM(J4:J13) -> 0.17761989 | L5: =K15 -> 0.1722488 | M5: =K25 -> 0.1659751 | N5: =K35 -> 0.1585504 | O5: =K45 -> 0.14962594 | P5: =K55 -> 0.13869626 | Q5: 7000102 | R5: =_xlfn.XLOOKUP(Q5,I:I,C:C) -> 인내심 | S5: =_xlfn.XLOOKUP(Q5,I:I,A:A) -> 1201001 | T5: =_xlfn.XLOOKUP(Q5,'[2]Skill<Talent>'!$A:$A,'[2]Skill<Talent>'!$C:$C) -> 매 턴 시작시 방어력이 <color=#87cefa>5%</color> 증가
A6: =INT(H6&TEXT(B6,"000")) -> 1101003 | B6: 3 | C6: 기교꾼 | D6: 1 | E6: 1 | F6: 1 | G6: Common | H6: =INT(D6&E6&TEXT(F6,"00")) -> 1101 | I6: 7000107 | J6: 20000 | K6: =J6/SUM(J4:J13) -> 0.17761989 | L6: =K16 -> 0.1722488 | M6: =K26 -> 0.1659751 | N6: =K36 -> 0.1585504 | O6: =K46 -> 0.14962594 | P6: =K56 -> 0.13869626 | Q6: 7000103 | R6: =_xlfn.XLOOKUP(Q6,I:I,C:C) -> 생존본능 | S6: =_xlfn.XLOOKUP(Q6,I:I,A:A) -> 1501001 | T6: =_xlfn.XLOOKUP(Q6,'[2]Skill<Talent>'!$A:$A,'[2]Skill<Talent>'!$C:$C) -> 매 턴 시작시 최대 체력의 <color=#87cefa>7%</color> 회복
A7: =INT(H7&TEXT(B7,"000")) -> 1101004 | B7: 4 | C7: 극의 해방 | D7: 1 | E7: 1 | F7: 1 | G7: Uncommon | H7: =INT(D7&E7&TEXT(F7,"00")) -> 1101 | I7: 7000108 | J7: 15000 | K7: =J7/SUM(J4:J13) -> 0.13321492 | L7: =K17 -> 0.13875598 | M7: =K27 -> 0.14522822 | N7: =K37 -> 0.15288788 | O7: =K47 -> 0.16209476 | P7: =K57 -> 0.17337032 | Q7: 7000104 | R7: =_xlfn.XLOOKUP(Q7,I:I,C:C) -> 집중 | S7: =_xlfn.XLOOKUP(Q7,I:I,A:A) -> 1401001 | T7: =_xlfn.XLOOKUP(Q7,'[2]Skill<Talent>'!$A:$A,'[2]Skill<Talent>'!$C:$C) -> 매 턴 시작시 Sp를 <color=#87cefa>20</color> 충전
A8: =INT(H8&TEXT(B8,"000")) -> 1101005 | B8: 5 | C8: 격노 | D8: 1 | E8: 1 | F8: 1 | G8: Uncommon | H8: =INT(D8&E8&TEXT(F8,"00")) -> 1101 | I8: 7000126 | J8: 15000 | K8: =J8/SUM(J4:J13) -> 0.13321492 | L8: =K18 -> 0.13875598 | M8: =K28 -> 0.14522822 | N8: =K38 -> 0.15288788 | O8: =K48 -> 0.16209476 | P8: =K58 -> 0.17337032 | Q8: 7000105 | R8: =_xlfn.XLOOKUP(Q8,I:I,C:C) -> 자기 합리화 | S8: =_xlfn.XLOOKUP(Q8,I:I,A:A) -> 1301001 | T8: =_xlfn.XLOOKUP(Q8,'[2]Skill<Talent>'!$A:$A,'[2]Skill<Talent>'!$C:$C) -> 매 턴 시작시 디버프 1개 해제
A9: =INT(H9&TEXT(B9,"000")) -> 1101006 | B9: 6 | C9: 광분 | D9: 1 | E9: 1 | F9: 1 | G9: Rare | H9: =INT(D9&E9&TEXT(F9,"00")) -> 1101 | I9: 7000127 | J9: 10000 | K9: =J9/SUM(J4:J13) -> 0.088809947 | L9: =K19 -> 0.090909091 | M9: =K29 -> 0.093360996 | N9: =K39 -> 0.096262741 | O9: =K49 -> 0.099750623 | P9: =K59 -> 0.10402219 | Q9: 7000106 | R9: =_xlfn.XLOOKUP(Q9,I:I,C:C) -> 원칙주의자 | S9: =_xlfn.XLOOKUP(Q9,I:I,A:A) -> 1101002 | T9: =_xlfn.XLOOKUP(Q9,'[2]Skill<Talent>'!$A:$A,'[2]Skill<Talent>'!$C:$C) -> 노멀 대미지 <color=#87cefa>{buff:main}_{value:1}%</color> 증가
A10: =INT(H10&TEXT(B10,"000")) -> 1101007 | B10: 7 | C10: 다혈질 | D10: 1 | E10: 1 | F10: 1 | G10: Rare | H10: =INT(D10&E10&TEXT(F10,"00")) -> 1101 | I10: 7000129 | J10: 10000 | K10: =J10/SUM(J4:J13) -> 0.088809947 | L10: =K20 -> 0.090909091 | M10: =K30 -> 0.093360996 | N10: =K40 -> 0.096262741 | O10: =K50 -> 0.099750623 | P10: =K60 -> 0.10402219 | Q10: 7000107 | R10: =_xlfn.XLOOKUP(Q10,I:I,C:C) -> 기교꾼 | S10: =_xlfn.XLOOKUP(Q10,I:I,A:A) -> 1101003 | T10: =_xlfn.XLOOKUP(Q10,'[2]Skill<Talent>'!$A:$A,'[2]Skill<Talent>'!$C:$C) -> 액티브 대미지 <color=#87cefa>{buff:main}_{value:1}%</color> 증가
A11: =INT(H11&TEXT(B11,"000")) -> 1101008 | B11: 8 | C11: 광폭화 | D11: 1 | E11: 1 | F11: 1 | G11: Unique | H11: =INT(D11&E11&TEXT(F11,"00")) -> 1101 | I11: 7000130 | J11: 2000 | K11: =J11/SUM(J4:J13) -> 0.017761989 | L11: =K21 -> 0.018181818 | M11: =K31 -> 0.018672199 | N11: =K41 -> 0.019252548 | O11: =K51 -> 0.019950125 | P11: =K61 -> 0.020804438 | Q11: 7000108 | R11: =_xlfn.XLOOKUP(Q11,I:I,C:C) -> 극의 해방 | S11: =_xlfn.XLOOKUP(Q11,I:I,A:A) -> 1101004 | T11: =_xlfn.XLOOKUP(Q11,'[2]Skill<Talent>'!$A:$A,'[2]Skill<Talent>'!$C:$C) -> 얼티밋 대미지 <color=#87cefa>{buff:main}_{value:1}%</color> 증가
A12: =INT(H12&TEXT(B12,"000")) -> 1101009 | B12: 9 | C12: 독기 | D12: 1 | E12: 1 | F12: 1 | G12: Epic | H12: =INT(D12&E12&TEXT(F12,"00")) -> 1101 | I12: 7000163 | J12: 500 | K12: =J12/SUM(J4:J13) -> 0.0044404973 | L12: =K22 -> 0.004784689 | M12: =K32 -> 0.005186722 | N12: =K42 -> 0.0056625142 | O12: =K52 -> 0.006234414 | P12: =K62 -> 0.0069348128 | Q12: 7000109 | R12: =_xlfn.XLOOKUP(Q12,I:I,C:C) -> 예리 | S12: =_xlfn.XLOOKUP(Q12,I:I,A:A) -> 2101003 | T12: =_xlfn.XLOOKUP(Q12,'[2]Skill<Talent>'!$A:$A,'[2]Skill<Talent>'!$C:$C) -> 약점 대미지 <color=#87cefa>{buff:main}_{value:1}%</color> 증가
A13: =INT(H13&TEXT(B13,"000")) -> 1101010 | B13: 10 | C13: 자기연소 | D13: 1 | E13: 1 | F13: 1 | G13: Legendary | H13: =INT(D13&E13&TEXT(F13,"00")) -> 1101 | I13: 7000174 | J13: 100 | K13: =J13/SUM(J4:J13) -> 0.00088809947 | L13: =K23 -> 0.0009569378 | M13: =K33 -> 0.0010373444 | N13: =K43 -> 0.0011325028 | O13: =K53 -> 0.0012468828 | P13: =K63 -> 0.0013869626 | Q13: 7000110 | R13: =_xlfn.XLOOKUP(Q13,I:I,C:C) -> 복수심 | S13: =_xlfn.XLOOKUP(Q13,I:I,A:A) -> 1201002 | T13: =_xlfn.XLOOKUP(Q13,'[2]Skill<Talent>'!$A:$A,'[2]Skill<Talent>'!$C:$C) -> 배틀 시작시 1턴 동안 반격 확률 50% 증가
A14: =INT(H14&TEXT(B14,"000")) -> 1102001 | B14: 1 | C14: =C4 -> 투쟁심 | D14: 1 | E14: 1 | F14: 2 | G14: Common | H14: =INT(D14&E14&TEXT(F14,"00")) -> 1102 | I14: 7000101 | J14: 18000 | K14: =J14/SUM(J14:J23) -> 0.1722488 | Q14: 7000111 | R14: =_xlfn.XLOOKUP(Q14,I:I,C:C) -> 결벽증 | S14: =_xlfn.XLOOKUP(Q14,I:I,A:A) -> 2201002 | T14: =_xlfn.XLOOKUP(Q14,'[2]Skill<Talent>'!$A:$A,'[2]Skill<Talent>'!$C:$C) -> 배틀 시작시 1턴 동안 면역 부여
A15: =INT(H15&TEXT(B15,"000")) -> 1102002 | B15: 2 | C15: =C5 -> 원칙주의자 | D15: 1 | E15: 1 | F15: 2 | G15: Common | H15: =INT(D15&E15&TEXT(F15,"00")) -> 1102 | I15: 7000106 | J15: 18000 | K15: =J15/SUM(J14:J23) -> 0.1722488 | Q15: 7000112 | R15: =_xlfn.XLOOKUP(Q15,I:I,C:C) -> 허영심 | S15: =_xlfn.XLOOKUP(Q15,I:I,A:A) -> 2201009 | T15: =_xlfn.XLOOKUP(Q15,'[2]Skill<Talent>'!$A:$A,'[2]Skill<Talent>'!$C:$C) -> 배틀 시작시 가까운 적 1명에게 1턴 동안 도발 부여
A16: =INT(H16&TEXT(B16,"000")) -> 1102003 | B16: 3 | C16: =C6 -> 기교꾼 | D16: 1 | E16: 1 | F16: 2 | G16: Common | H16: =INT(D16&E16&TEXT(F16,"00")) -> 1102 | I16: 7000107 | J16: 18000 | K16: =J16/SUM(J14:J23) -> 0.1722488 | Q16: 7000113 | R16: =_xlfn.XLOOKUP(Q16,I:I,C:C) -> 완벽주의자 | S16: =_xlfn.XLOOKUP(Q16,I:I,A:A) -> 2201003 | T16: =_xlfn.XLOOKUP(Q16,'[2]Skill<Talent>'!$A:$A,'[2]Skill<Talent>'!$C:$C) -> 배틀 시작시 1턴 동안 무적 부여
A17: =INT(H17&TEXT(B17,"000")) -> 1102004 | B17: 4 | C17: =C7 -> 극의 해방 | D17: 1 | E17: 1 | F17: 2 | G17: Uncommon | H17: =INT(D17&E17&TEXT(F17,"00")) -> 1102 | I17: 7000108 | J17: 14500 | K17: =J17/SUM(J14:J23) -> 0.13875598 | Q17: 7000114 | R17: =_xlfn.XLOOKUP(Q17,I:I,C:C) -> 성급 | S17: =_xlfn.XLOOKUP(Q17,I:I,A:A) -> 1201003 | T17: =_xlfn.XLOOKUP(Q17,'[2]Skill<Talent>'!$A:$A,'[2]Skill<Talent>'!$C:$C) -> 배틀 시작시 액티브 쿨타임 2턴 감소
A18: =INT(H18&TEXT(B18,"000")) -> 1102005 | B18: 5 | C18: =C8 -> 격노 | D18: 1 | E18: 1 | F18: 2 | G18: Uncommon | H18: =INT(D18&E18&TEXT(F18,"00")) -> 1102 | I18: 7000126 | J18: 14500 | K18: =J18/SUM(J14:J23) -> 0.13875598 | Q18: 7000115 | R18: =_xlfn.XLOOKUP(Q18,I:I,C:C) -> 만전태세 | S18: =_xlfn.XLOOKUP(Q18,I:I,A:A) -> 1401002 | T18: =_xlfn.XLOOKUP(Q18,'[2]Skill<Talent>'!$A:$A,'[2]Skill<Talent>'!$C:$C) -> 배틀 시작시 Sp <color=#87cefa>150</color> 충전
A19: =INT(H19&TEXT(B19,"000")) -> 1102006 | B19: 6 | C19: =C9 -> 광분 | D19: 1 | E19: 1 | F19: 2 | G19: Rare | H19: =INT(D19&E19&TEXT(F19,"00")) -> 1102 | I19: 7000127 | J19: 9500 | K19: =J19/SUM(J14:J23) -> 0.090909091 | Q19: 7000116 | R19: =_xlfn.XLOOKUP(Q19,I:I,C:C) -> 투지 | S19: =_xlfn.XLOOKUP(Q19,I:I,A:A) -> 1201004 | T19: =_xlfn.XLOOKUP(Q19,'[2]Skill<Talent>'!$A:$A,'[2]Skill<Talent>'!$C:$C) -> 회복 중 공격력 <color=#87cefa>{buff:main}_{value:1}%</color> 증가
A20: =INT(H20&TEXT(B20,"000")) -> 1102007 | B20: 7 | C20: =C10 -> 다혈질 | D20: 1 | E20: 1 | F20: 2 | G20: Rare | H20: =INT(D20&E20&TEXT(F20,"00")) -> 1102 | I20: 7000129 | J20: 9500 | K20: =J20/SUM(J14:J23) -> 0.090909091 | Q20: 7000117 | R20: =_xlfn.XLOOKUP(Q20,I:I,C:C) -> 방어기제 | S20: =_xlfn.XLOOKUP(Q20,I:I,A:A) -> 1501003 | T20: =_xlfn.XLOOKUP(Q20,'[2]Skill<Talent>'!$A:$A,'[2]Skill<Talent>'!$C:$C) -> 회복 중 방어력 <color=#87cefa>{buff:main}_{value:1}%</color> 증가
A21: =INT(H21&TEXT(B21,"000")) -> 1102008 | B21: 8 | C21: =C11 -> 광폭화 | D21: 1 | E21: 1 | F21: 2 | G21: Unique | H21: =INT(D21&E21&TEXT(F21,"00")) -> 1102 | I21: 7000130 | J21: 1900 | K21: =J21/SUM(J14:J23) -> 0.018181818 | Q21: 7000118 | R21: =_xlfn.XLOOKUP(Q21,I:I,C:C) -> 경계심 | S21: =_xlfn.XLOOKUP(Q21,I:I,A:A) -> 2201005 | T21: =_xlfn.XLOOKUP(Q21,'[2]Skill<Talent>'!$A:$A,'[2]Skill<Talent>'!$C:$C) -> 회복 중 속도 <color=#87cefa>20</color> 증가
A22: =INT(H22&TEXT(B22,"000")) -> 1102009 | B22: 9 | C22: =C12 -> 독기 | D22: 1 | E22: 1 | F22: 2 | G22: Epic | H22: =INT(D22&E22&TEXT(F22,"00")) -> 1102 | I22: 7000163 | J22: 500 | K22: =J22/SUM(J14:J23) -> 0.004784689 | Q22: 7000119 | R22: =_xlfn.XLOOKUP(Q22,I:I,C:C) -> 다재다능 | S22: =_xlfn.XLOOKUP(Q22,I:I,A:A) -> 1401010 | T22: =_xlfn.XLOOKUP(Q22,'[2]Skill<Talent>'!$A:$A,'[2]Skill<Talent>'!$C:$C) -> 보호막 중 공격력 <color=#87cefa>{buff:main}_{value:1}%</color> 증가
A23: =INT(H23&TEXT(B23,"000")) -> 1102010 | B23: 10 | C23: =C13 -> 자기연소 | D23: 1 | E23: 1 | F23: 2 | G23: Legendary | H23: =INT(D23&E23&TEXT(F23,"00")) -> 1102 | I23: 7000174 | J23: 100 | K23: =J23/SUM(J14:J23) -> 0.0009569378 | Q23: 7000120 | R23: =_xlfn.XLOOKUP(Q23,I:I,C:C) -> 철벽 | S23: =_xlfn.XLOOKUP(Q23,I:I,A:A) -> 1201005 | T23: =_xlfn.XLOOKUP(Q23,'[2]Skill<Talent>'!$A:$A,'[2]Skill<Talent>'!$C:$C) -> 보호막 중 방어력 <color=#87cefa>{buff:main}_{value:1}%</color> 증가
A24: =INT(H24&TEXT(B24,"000")) -> 1103001 | B24: 1 | C24: =C14 -> 투쟁심 | D24: 1 | E24: 1 | F24: 3 | G24: Common | H24: =INT(D24&E24&TEXT(F24,"00")) -> 1103 | I24: 7000101 | J24: 16000 | K24: =J24/SUM(J24:J33) -> 0.1659751 | Q24: 7000121 | R24: =_xlfn.XLOOKUP(Q24,I:I,C:C) -> 겁쟁이 | S24: =_xlfn.XLOOKUP(Q24,I:I,A:A) -> 4201003 | T24: =_xlfn.XLOOKUP(Q24,'[2]Skill<Talent>'!$A:$A,'[2]Skill<Talent>'!$C:$C) -> 보호막 중 속도 <color=#87cefa>20</color> 증가
A25: =INT(H25&TEXT(B25,"000")) -> 1103002 | B25: 2 | C25: =C15 -> 원칙주의자 | D25: 1 | E25: 1 | F25: 3 | G25: Common | H25: =INT(D25&E25&TEXT(F25,"00")) -> 1103 | I25: 7000106 | J25: 16000 | K25: =J25/SUM(J24:J33) -> 0.1659751 | Q25: 7000122 | R25: =_xlfn.XLOOKUP(Q25,I:I,C:C) -> 기회주의자 | S25: =_xlfn.XLOOKUP(Q25,I:I,A:A) -> 1501009 | T25: =_xlfn.XLOOKUP(Q25,'[2]Skill<Talent>'!$A:$A,'[2]Skill<Talent>'!$C:$C) -> 노멀 공격시 35% 확률로 Sp <color=#87cefa>10</color> 획득
A26: =INT(H26&TEXT(B26,"000")) -> 1103003 | B26: 3 | C26: =C16 -> 기교꾼 | D26: 1 | E26: 1 | F26: 3 | G26: Common | H26: =INT(D26&E26&TEXT(F26,"00")) -> 1103 | I26: 7000107 | J26: 16000 | K26: =J26/SUM(J24:J33) -> 0.1659751 | Q26: 7000123 | R26: =_xlfn.XLOOKUP(Q26,I:I,C:C) -> 책략가 | S26: =_xlfn.XLOOKUP(Q26,I:I,A:A) -> 2101005 | T26: =_xlfn.XLOOKUP(Q26,'[2]Skill<Talent>'!$A:$A,'[2]Skill<Talent>'!$C:$C) -> 액티브 공격시 35% 확률로 Sp <color=#87cefa>10</color> 획득
A27: =INT(H27&TEXT(B27,"000")) -> 1103004 | B27: 4 | C27: =C17 -> 극의 해방 | D27: 1 | E27: 1 | F27: 3 | G27: Uncommon | H27: =INT(D27&E27&TEXT(F27,"00")) -> 1103 | I27: 7000108 | J27: 14000 | K27: =J27/SUM(J24:J33) -> 0.14522822 | Q27: 7000124 | R27: =_xlfn.XLOOKUP(Q27,I:I,C:C) -> 착취 | S27: =_xlfn.XLOOKUP(Q27,I:I,A:A) -> 2101004 | T27: =_xlfn.XLOOKUP(Q27,'[2]Skill<Talent>'!$A:$A,'[2]Skill<Talent>'!$C:$C) -> 얼티밋 공격시 20% 확률로 Sp <color=#87cefa>5</color> 획득
A28: =INT(H28&TEXT(B28,"000")) -> 1103005 | B28: 5 | C28: =C18 -> 격노 | D28: 1 | E28: 1 | F28: 3 | G28: Uncommon | H28: =INT(D28&E28&TEXT(F28,"00")) -> 1103 | I28: 7000126 | J28: 14000 | K28: =J28/SUM(J24:J33) -> 0.14522822 | Q28: 7000125 | R28: =_xlfn.XLOOKUP(Q28,I:I,C:C) -> 증오 | S28: =_xlfn.XLOOKUP(Q28,I:I,A:A) -> 3101003 | T28: =_xlfn.XLOOKUP(Q28,'[2]Skill<Talent>'!$A:$A,'[2]Skill<Talent>'!$C:$C) -> 체력이 50% 이하일 때 노멀 대미지 <color=#87cefa>{buff:main}_{value:1}%</color> 증가
A29: =INT(H29&TEXT(B29,"000")) -> 1103006 | B29: 6 | C29: =C19 -> 광분 | D29: 1 | E29: 1 | F29: 3 | G29: Rare | H29: =INT(D29&E29&TEXT(F29,"00")) -> 1103 | I29: 7000127 | J29: 9000 | K29: =J29/SUM(J24:J33) -> 0.093360996 | Q29: 7000126 | R29: =_xlfn.XLOOKUP(Q29,I:I,C:C) -> 격노 | S29: =_xlfn.XLOOKUP(Q29,I:I,A:A) -> 1101005 | T29: =_xlfn.XLOOKUP(Q29,'[2]Skill<Talent>'!$A:$A,'[2]Skill<Talent>'!$C:$C) -> 체력이 50% 이하일 때 액티브 대미지 <color=#87cefa>{buff:main}_{value:1}%</color> 증가
A30: =INT(H30&TEXT(B30,"000")) -> 1103007 | B30: 7 | C30: =C20 -> 다혈질 | D30: 1 | E30: 1 | F30: 3 | G30: Rare | H30: =INT(D30&E30&TEXT(F30,"00")) -> 1103 | I30: 7000129 | J30: 9000 | K30: =J30/SUM(J24:J33) -> 0.093360996 | Q30: 7000127 | R30: =_xlfn.XLOOKUP(Q30,I:I,C:C) -> 광분 | S30: =_xlfn.XLOOKUP(Q30,I:I,A:A) -> 1101006 | T30: =_xlfn.XLOOKUP(Q30,'[2]Skill<Talent>'!$A:$A,'[2]Skill<Talent>'!$C:$C) -> 체력이 50% 이하일 때 얼티밋 대미지 <color=#87cefa>{buff:main}_{value:1}%</color> 증가
A31: =INT(H31&TEXT(B31,"000")) -> 1103008 | B31: 8 | C31: =C21 -> 광폭화 | D31: 1 | E31: 1 | F31: 3 | G31: Unique | H31: =INT(D31&E31&TEXT(F31,"00")) -> 1103 | I31: 7000130 | J31: 1800 | K31: =J31/SUM(J24:J33) -> 0.018672199 | Q31: 7000128 | R31: =_xlfn.XLOOKUP(Q31,I:I,C:C) -> 근성 | S31: =_xlfn.XLOOKUP(Q31,I:I,A:A) -> 3101004 | T31: =_xlfn.XLOOKUP(Q31,'[2]Skill<Talent>'!$A:$A,'[2]Skill<Talent>'!$C:$C) -> 체력이 50% 이하일 때 방어력 <color=#87cefa>{buff:main}_{value:1}%</color> 증가
A32: =INT(H32&TEXT(B32,"000")) -> 1103009 | B32: 9 | C32: =C22 -> 독기 | D32: 1 | E32: 1 | F32: 3 | G32: Epic | H32: =INT(D32&E32&TEXT(F32,"00")) -> 1103 | I32: 7000163 | J32: 500 | K32: =J32/SUM(J24:J33) -> 0.005186722 | Q32: 7000129 | R32: =_xlfn.XLOOKUP(Q32,I:I,C:C) -> 다혈질 | S32: =_xlfn.XLOOKUP(Q32,I:I,A:A) -> 1101007 | T32: =_xlfn.XLOOKUP(Q32,'[2]Skill<Talent>'!$A:$A,'[2]Skill<Talent>'!$C:$C) -> 체력이 50% 이하일 때 치명타 확률 <color=#87cefa>{buff:main}_{value:1}%</color> 증가
